Workbook

Sheet Acra Point
A1: Windham Blackead Range Wilderness
A2: Acra Point | X2: R25
B3: 1990 | C3: 1991 | D3: 1992 | E3: 1993 | F3: 1994 | G3: 1995 | H3: 1996 | I3: 1997 | J3: 1998 | K3: 1999 | L3: 2000 | M3: 2001 | N3: 2002 | O3: 2003 | P3: 2004 | Q3: 2005 | R3: 2006 | S3: 2007 | T3: 2008 | U3: 2009 | V3: 2010 | W3: 2011 | X3: 2012 | Y3: 2013 | Z3: 2014 | AA3: 2015 | AB3: 2016 | AC3: 2017 | AD3: 2018 | AE3: 2019 | AF3: 2020 | AG3: 2021 | AH3: 2022 | AI3: 2023 | AJ3: 2024 | AK3: 2025
A5: January | H5: 5 | I5: 18 | J5: 31 | K5: 11 | L5: 47 | Q5: 21 | R5: 48 | S5: 31 | T5: 22 | U5: 21 | V5: 38 | W5: 25 | X5: 40 | Y5: * | Z5: 25 | AA5: 38 | AB5: 59 | AC5: 67 | AD5: 21 | AE5: 22 | AF5: 84 | AG5: 140 | AH5: * | AI5: 58 | AJ5: 39 | AK5: 67
A6: February | H6: 18 | I6: 36 | J6: 119 | K6: 39 | L6: 35 | P6: 22 | Q6: 16 | R6: 26 | S6: 18 | T6: 22 | U6: 20 | V6: 33 | W6: 28 | X6: 24 | Y6: * | Z6: 15 | AA6: 8 | AB6: 62 | AC6: 56 | AD6: 32 | AE6: 39 | AF6: 68 | AG6: 21 | AH6: 35 | AI6: 63 | AJ6: 33 | AK6: 41
A7: March | H7: 44 | I7: 26 | J7: 108 | K7: 39 | L7: 26 | P7: 3 | Q7: 43 | R7: 34 | S7: 35 | T7: 29 | U7: 36 | V7: 7 | W7: 53 | X7: 83 | Y7: * | Z7: 28 | AA7: 27 | AB7: 74 | AC7: 35 | AD7: 48 | AE7: 45 | AF7: 83 | AG7: 106 | AH7: 67 | AI7: 49 | AJ7: 62 | AK7: 81
A8: April | H8: 85 | I8: 57 | J8: 65 | K8: 78 | L8: 78 | Q8: 46 | R8: 71 | S8: 37 | T8: 68 | U8: 74 | V8: 38 | W8: 54 | X8: 81 | Y8: 46 | Z8: 38 | AA8: 47 | AB8: 46 | AC8: 125 | AD8: 54 | AE8: 77 | AF8: 120 | AG8: 92 | AH8: 314 | AI8: 92 | AJ8: 93 | AK8: 79
A9: May | H9: 100 | I9: 99 | J9: 104 | K9: 116 | L9: 78 | P9: 65 | Q9: 76 | R9: 64 | S9: 61 | T9: 72 | U9: 86 | V9: 163 | W9: 120 | X9: 138 | Y9: 118 | Z9: 143 | AA9: 115 | AB9: 94 | AC9: 115 | AD9: 118 | AE9: 176 | AF9: 220 | AG9: 218 | AH9: 139 | AI9: 25 | AJ9: 161 | AK9: 133
A10: June | H10: 172 | I10: 174 | J10: 80 | K10: 120 | L10: 94 | P10: 120 | Q10: 67 | R10: 2 | S10: 30 | T10: 63 | U10: 46 | V10: 79 | W10: 86 | X10: =SUM('Acra Point'!X11) -> 82 | Y10: 92 | Z10: 65 | AA10: 71 | AB10: 103 | AC10: 104 | AD10: 83 | AE10: 206 | AF10: 169 | AG10: 164 | AH10: 168 | AI10: * | AJ10: 93 | AK10: 97
A11: July | H11: 130 | I11: 174 | J11: 244 | K11: 124 | L11: 189 | P11: 126 | Q11: 128 | R11: 149 | T11: 112 | U11: 168 | V11: 131 | W11: 132 | X11: 82 | Y11: 62 | Z11: 81 | AA11: 97 | AB11: 195 | AC11: 233 | AD11: 104 | AE11: 139 | AF11: 234 | AG11: 236 | AH11: 95 | AI11: * | AJ11: 134 | AK11: 157
A12: August | H12: 128 | I12: 171 | J12: 161 | K12: 134 | L12: 113 | P12: 95 | Q12: 113 | R12: 98 | T12: 125 | U12: 160 | V12: 135 | W12: 147 | X12: 141 | Y12: 151 | Z12: 103 | AA12: 110 | AB12: 126 | AC12: 124 | AD12: 97 | AE12: 300 | AF12: 262 | AG12: 205 | AH12: 131 | AI12: * | AJ12: 180 | AK12: 180
A13: September | I13: 0 | J13: 151 | K13: 207 | L13: 113 | P13: 139 | Q13: 101 | R13: 140 | T13: 91 | U13: 141 | V13: 154 | W13: 5 | X13: 3 | Y13: 140 | Z13: 71 | AA13: 104 | AB13: 132 | AC13: 156 | AD13: 105 | AE13: 213 | AF13: 226 | AG13: 213 | AH13: 159 | AI13: * | AJ13: 143 | AK13: 173
A14: October | I14: 280 | J14: 149 | K14: 170 | L14: 248 | P14: 92 | Q14: 91 | R14: 147 | T14: 136 | U14: 96 | V14: 140 | W14: 110 | X14: * | Y14: 152 | Z14: 105 | AA14: 130 | AB14: 168 | AC14: 200 | AD14: 207 | AE14: 276 | AF14: 292 | AG14: 392 | AH14: 291 | AI14: 153 | AJ14: 255 | AK14: 174
A15: November | I15: 23 | J15: 72 | K15: 103 | L15: 66 | P15: 13 | Q15: 65 | R15: 29 | T15: 20 | U15: 59 | V15: 87 | W15: 58 | X15: * | Y15: 98 | Z15: 34 | AA15: 72 | AB15: 116 | AC15: 87 | AD15: 63 | AE15: 95 | AF15: 210 | AG15: 155 | AH15: 90 | AI15: 94 | AJ15: 84 | AK15: 61
A16: December | I16: 44 | K16: 29 | L16: 19 | Q16: 7 | R16: 52 | T16: 39 | U16: 18 | V16: 22 | W16: 69 | X16: * | Y16: 29 | Z16: 35 | AA16: 48 | AB16: 32 | AC16: 26 | AD16: 94 | AE16: 29 | AF16: 89 | AG16: 115 | AH16: 44 | AI16: 67 | AJ16: 64 | AL16: *Registers missing
A18: Yearly Totals | B18: 718 | C18: 772 | D18: 715 | E18: 901 | F18: 1078 | G18: 1223 | H18: =SUM(H5:H17) -> 682 | I18: =SUM(I5:I17) -> 1102 | J18: =SUM(J5:J17) -> 1284 | K18: =SUM(K5:K17) -> 1170 | L18: =SUM(L5:L17) -> 1106 | M18: 904 | N18: 868 | O18: 770 | P18: 807 | Q18: 774 | R18: =SUM(R5:R16) -> 860 | S18: =SUM(S5:S16) -> 212 | T18: =SUM(T5:T16) -> 799 | U18: =SUM(U5:U16) -> 925 | V18: =SUM(V5:V16) -> 1027 | W18: =SUM(W5:W16) -> 887 | X18: =SUM(X5:X16) -> 674 | Y18: =SUM(Y5:Y16) -> 888 | ... AF18: =SUM(AF5:AF16) -> 2057 | AG18: =SUM(AG5:AG17) -> 2057 | AH18: =SUM(AH5:AH16) -> 1533 | AI18: =SUM(AI5:AI16) -> 601 | AJ18: =SUM(AJ5:AJ16) -> 1341 | AK18: =SUM(AK5:AK16) -> 1243
J19: 1317

Sheet Barnum Road
A1: Windham Blackhead Range Wilderness
A2: Barnum Road | X2: R24
B3: 1990 | C3: 1991 | D3: 1992 | E3: 1993 | F3: 1994 | G3: 1995 | H3: 1996 | I3: 1997 | J3: 1998 | K3: 1999 | L3: 2000 | M3: 2001 | N3: 2002 | O3: 2003 | P3: 2004 | Q3: 2005 | R3: 2006 | S3: 2007 | T3: 2008 | U3: 2009 | V3: 2010 | W3: 2011 | X3: 2012 | Y3: 2013 | Z3: 2014 | AA3: 2015 | AB3: 2016 | AC3: 2017 | AD3: 2018 | AE3: 2019 | AF3: 2020 | AG3: 2021 | AH3: 2022 | AI3: 2023 | AJ3: 2024 | AK3: 2025
A5: January | H5: 19 | I5: 8 | J5: 61 | K5: 21 | L5: 34 | P5: 11 | Q5: 114 | R5: 67 | S5: 47 | T5: 49 | U5: 50 | V5: 33 | W5: 36 | X5: 55 | Y5: * | Z5: 27 | AA5: 49 | AB5: 458 | AC5: 14 | AD5: 75 | AE5: 39 | AF5: 88 | AG5: 152 | AH5: 53 | AI5: 50 | AJ5: 32 | AK5: 10
A6: February | H6: 14 | I6: 27 | J6: 40 | K6: 46 | L6: 42 | Q6: 52 | R6: 66 | S6: 45 | T6: 37 | U6: 44 | V6: 17 | W6: 50 | X6: 68 | Y6: * | Z6: 40 | AA6: 27 | AB6: 82 | AC6: X | AD6: 64 | AE6: 38 | AF6: 88 | AG6: 51 | AH6: 67 | AI6: 85 | AJ6: 57 | AK6: 20
A7: March | H7: 49 | I7: 46 | J7: 57 | K7: 30 | L7: 78 | Q7: 29 | R7: 63 | S7: 52 | T7: 46 | U7: 27 | V7: 42 | W7: 35 | X7: 70 | Y7: * | Z7: 36 | AA7: 35 | AB7: 144 | AC7: X | AD7: 75 | AE7: 48 | AF7: 98 | AG7: 79 | AH7: 61 | AI7: 19 | AJ7: 60 | AK7: 57
A8: April | H8: 63 | I8: 24 | J8: 75 | K8: 113 | L8: 67 | Q8: 37 | R8: 89 | S8: 56 | T8: 81 | U8: 54 | V8: 50 | W8: 54 | X8: 78 | Y8: 86 | Z8: 57 | AA8: 53 | AB8: 104 | AC8: 23 | AD8: 53 | AE8: 67 | AF8: 101 | AG8: 19 | AH8: 68 | AI8: 80 | AJ8: 79 | AK8: 75
A9: May | H9: 172 | I9: 111 | J9: 193 | K9: 198 | L9: 150 | P9: 146 | Q9: 148 | R9: 179 | S9: 85 | T9: 140 | U9: 83 | V9: 105 | W9: 143 | X9: 141 | Y9: 81 | Z9: 84 | AA9: 134 | AB9: 156 | AC9: 150 | AD9: 119 | AE9: 105 | AF9: 219 | AG9: 124 | AH9: 130 | AI9: 146 | AJ9: 123 | AK9: 94
A10: June | I10: 129 | J10: 95 | K10: 123 | L10: 102 | P10: 134 | Q10: 105 | R10: 61 | S10: 34 | T10: 113 | U10: 142 | V10: 86 | W10: 81 | X10: 74 | Y10: 52 | Z10: 108 | AA10: 113 | AB10: 95 | AC10: 132 | AD10: 128 | AE10: 125 | AF10: 177 | AG10: 189 | AH10: 142 | AI10: 113 | AJ10: 106 | AK10: 122
A11: July | I11: 120 | J11: 133 | K11: 100 | L11: 120 | P11: 117 | Q11: 164 | R11: 166 | T11: 99 | U11: 108 | V11: 127 | W11: 144 | X11: * | Y11: 62 | Z11: 106 | AA11: 105 | AB11: 85 | AC11: 202 | AD11: 149 | AE11: 113 | AF11: 165 | AG11: 154 | AH11: 147 | AI11: 167 | AJ11: 123 | AK11: 88
A12: August | I12: 222 | J12: 134 | K12: 175 | L12: 180 | P12: 134 | Q12: 119 | R12: 100 | T12: 192 | U12: 100 | V12: 126 | W12: 115 | X12: * | Y12: 129 | Z12: 205 | AA12: 168 | AB12: 121 | AC12: 142 | AD12: 142 | AE12: 154 | AF12: 203 | AG12: 105 | AH12: 94 | AI12: 136 | AJ12: 106
A13: September | I13: 111 | J13: 159 | K13: 123 | L13: 78 | P13: 144 | Q13: 125 | R13: 88 | T13: 86 | U13: 115 | V13: 142 | W13: 90 | X13: * | Y13: 117 | Z13: 101 | AA13: 102 | AB13: 128 | AC13: 152 | AD13: 134 | AE13: 177 | AF13: 237 | AG13: 115 | AH13: 88 | AI13: 76 | AJ13: 81
A14: October | I14: 204 | J14: 143 | K14: 153 | L14: 246 | P14: 199 | Q14: 92 | R14: 214 | T14: 278 | U14: 193 | V14: 208 | W14: 98 | X14: * | Y14: 104 | Z14: 121 | AA14: 139 | AB14: 138 | AC14: 146 | AD14: 156 | AE14: 183 | AF14: 188 | AG14: 128 | AH14: 125 | AI14: 111 | AJ14: 128
A15: November | I15: 53 | J15: 101 | K15: 97 | L15: 68 | P15: 100 | Q15: 102 | R15: 116 | T15: 45 | U15: 67 | V15: 126 | W15: 100 | X15: * | Y15: 98 | Z15: 52 | AA15: 129 | AB15: 85 | AC15: 76 | AD15: 77 | AE15: 103 | AF15: 129 | AG15: 185 | AH15: 60 | AI15: 77 | AJ15: 86
A16: December | I16: 33 | J16: 45 | K16: 26 | L16: 25 | P16: 29 | Q16: 56 | R16: 54 | T16: 41 | U16: 17 | V16: 35 | W16: 67 | X16: * | Y16: 34 | Z16: 32 | AA16: 80 | AB16: 48 | AC16: 58 | AD16: 53 | AE16: 57 | AF16: 95 | AG16: 6 | AH16: 42 | AI16: 62 | AJ16: 18 | AL16: *Registers missing
A18: Yearly Totals | B18: 770 | C18: 787 | D18: 1702 | E18: 1190 | F18: 1186 | G18: 1284 | H18: =SUM(H5:H17) -> 317 | I18: =SUM(I5:I17) -> 1088 | J18: =SUM(J5:J17) -> 1236 | K18: =SUM(K5:K17) -> 1205 | L18: =SUM(L5:L17) -> 1190 | M18: 1674 | N18: 1235 | O18: 1044 | P18: 1028 | Q18: =SUM(Q5:Q16) -> 1143 | R18: =SUM(R5:R16) -> 1263 | S18: =SUM(S5:S16) -> 319 | T18: =SUM(T5:T16) -> 1207 | U18: =SUM(U5:U16) -> 1000 | V18: =SUM(V5:V16) -> 1097 | W18: =SUM(W5:W16) -> 1013 | X18: =SUM(X5:X16) -> 486 | ... AD18: =SUM(AD5:AD16) -> 1225 | AE18: =SUM(AE5:AE17) -> 1209 | AF18: =SUM(AF5:AF17) -> 1788 | AG18: =SUM(AG5:AG17) -> 1307 | AH18: =SUM(AH5:AH17) -> 1077 | AI18: =SUM(AI5:AI17) -> 1122 | AJ18: =SUM(AJ5:AJ17) -> 999 | AK18: =SUM(AK5:AK17) -> 466
I19: 1224
AF23: all estimated

Sheet Batavia Kill
A1: Windham Blackhead Range Wilderness
A2: Batavia Kill | X2: R26
B3: 1990 | C3: 1991 | D3: 1992 | E3: 1993 | F3: 1994 | G3: 1995 | H3: 1996 | I3: 1997 | J3: 1998 | K3: 1999 | L3: 2000 | M3: 2001 | N3: 2002 | O3: 2003 | P3: 2004 | Q3: 2005 | R3: 2006 | S3: 2007 | T3: 2008 | U3: 2009 | V3: 2010 | W3: 2011 | X3: 2012 | Y3: 2013 | Z3: 2014 | AA3: 2015 | AB3: 2016 | AC3: 2017 | AD3: 2018 | AE3: 2019 | AF3: 2020 | AG3: 2021 | AH3: 2022 | AI3: 2023 | AJ3: 2024 | AK3: 2025
A5: January | H5: 64 | I5: 35 | J5: 165 | K5: 90 | L5: 111 | P5: 116 | Q5: 36 | R5: 151 | S5: 118 | T5: 117 | U5: 102 | V5: 157 | W5: 127 | X5: 216 | Y5: * | Z5: 122 | AA5: 184 | AB5: 166 | AC5: 173 | AD5: 149 | AE5: 252 | AF5: 269 | AG5: 186 | AH5: 240 | AI5: 352 | AJ5: * | AK5: 174
A6: February | H6: 73 | I6: 101 | J6: 102 | K6: 119 | L6: 110 | P6: 111 | Q6: 87 | R6: 93 | S6: 70 | T6: 88 | U6: 89 | V6: 73 | W6: 143 | X6: 204 | Y6: * | Z6: 110 | AA6: 119 | AB6: 180 | AC6: 162 | AD6: 178 | AE6: 182 | AF6: 318 | AG6: 244 | AH6: 266 | AI6: 285 | AJ6: * | AK6: 194
A7: March | H7: 114 | I7: 94 | J7: 43 | K7: 81 | L7: 121 | P7: 101 | Q7: 85 | R7: 191 | S7: 63 | T7: 92 | U7: 117 | V7: 32 | W7: 132 | X7: 242 | Y7: 6 | Z7: 166 | AA7: 122 | AB7: 318 | AC7: 105 | AD7: 156 | AE7: 299 | AF7: 335 | AG7: 433 | AH7: 221 | AI7: 188 | AJ7: * | AK7: 263
A8: April | H8: 156 | I8: 95 | J8: 158 | K8: 124 | L8: 149 | P8: 155 | Q8: 112 | R8: 151 | S8: 90 | T8: 133 | U8: 121 | V8: 93 | W8: 124 | X8: 179 | Y8: 142 | Z8: 96 | AA8: 133 | AB8: 225 | AC8: 218 | AD8: 95 | AE8: 151 | AF8: 176 | AG8: 221 | AH8: 217 | AI8: 162 | AJ8: * | AK8: 172
A9: May | H9: 257 | I9: 221 | J9: 275 | K9: 376 | L9: 240 | P9: 232 | Q9: 194 | R9: 196 | S9: 201 | T9: 260 | U9: 238 | V9: 300 | W9: 271 | X9: 255 | Y9: 229 | Z9: 284 | AA9: 332 | AB9: 244 | AC9: 279 | AD9: 220 | AE9: 276 | AF9: 553 | AG9: 440 | AH9: 377 | AI9: 384 | AJ9: * | AK9: 284
A10: June | H10: 264 | I10: 327 | J10: 205 | K10: 246 | L10: 192 | P10: 262 | Q10: 122 | R10: 159 | S10: 234 | T10: 194 | U10: 177 | V10: 157 | W10: 258 | X10: 146 | Y10: 232 | Z10: 224 | AA10: 244 | AB10: 268 | AC10: 235 | AD10: 248 | AE10: 412 | AF10: 507 | AG10: 329 | AH10: 334 | AI10: 230 | AJ10: 4 | AK10: 311
A11: July | H11: 202 | I11: 257 | J11: 299 | K11: 353 | L11: 332 | P11: 234 | Q11: 201 | R11: 270 | S11: 240 | T11: 221 | U11: 351 | V11: 251 | W11: 363 | X11: 251 | Y11: 234 | Z11: 282 | AA11: 305 | AB11: 343 | AC11: 398 | AD11: 324 | AE11: 372 | AF11: 553 | AG11: 315 | AH11: 407 | AI11: 365 | AJ11: 286 | AK11: 417
A12: August | I12: 310 | J12: 493 | K12: 253 | L12: 220 | P12: 224 | Q12: 47 | R12: 257 | S12: 211 | T12: 305 | U12: 291 | V12: 246 | W12: 241 | X12: 203 | Y12: 265 | Z12: 346 | AA12: 340 | AB12: 350 | AC12: 344 | AD12: 297 | AE12: 454 | AF12: 580 | AG12: 436 | AH12: 271 | AI12: 371 | AJ12: 269 | AK12: 428
A13: September | I13: 233 | J13: 257 | K13: 339 | L13: 278 | P13: 294 | Q13: 231 | R13: 194 | S13: 328 | T13: 215 | U13: 231 | V13: 275 | W13: 66 | X13: 84 | Y13: 250 | Z13: 186 | AA13: 298 | AB13: 319 | AC13: 262 | AD13: 239 | AE13: 420 | AF13: 503 | AG13: 287 | AH13: 261 | AI13: 238 | AJ13: 267 | AK13: 347
A14: October | I14: 509 | J14: 330 | K14: 267 | L14: 430 | P14: 297 | Q14: 167 | R14: 214 | S14: 257 | T14: 304 | U14: 189 | V14: 346 | W14: 251 | X14: * | Y14: 316 | Z14: 257 | AA14: 330 | AB14: 316 | AC14: 252 | AD14: 298 | AE14: 389 | AF14: 462 | AG14: 513 | AH14: 501 | AI14: 335 | AJ14: 425 | AK14: 349
A15: November | I15: 84 | J15: 166 | K15: 182 | L15: 164 | P15: 148 | Q15: 153 | R15: 120 | S15: 106 | T15: 141 | U15: 184 | V15: 171 | W15: 178 | X15: * | Y15: 166 | Z15: 131 | AA15: 185 | AB15: 157 | AC15: 165 | AD15: 134 | AE15: 269 | AF15: 369 | AG15: 224 | AH15: 201 | AI15: 114 | AJ15: 292 | AK15: 124
A16: December | I16: 107 | J16: 123 | K16: 88 | L16: 47 | P16: 28 | Q16: 74 | R16: 94 | S16: 79 | T16: 59 | U16: 42 | V16: 96 | W16: 213 | X16: * | Y16: 78 | Z16: 100 | AA16: 226 | AB16: 88 | AC16: 163 | AD16: 179 | AE16: 214 | AF16: 282 | AG16: 305 | AH16: 232 | AJ16: 154 | AL16: *Registers missing
A18: Yearly Totals | B18: 1718 | C18: 1848 | D18: 1873 | E18: 2014 | F18: 2361 | G18: 2580 | H18: =SUM(H5:H17) -> 1130 | I18: =SUM(I5:I17) -> 2373 | J18: =SUM(J5:J17) -> 2616 | K18: =SUM(K5:K17) -> 2518 | L18: =SUM(L5:L17) -> 2394 | M18: 2167 | N18: 2196 | O18: 2067 | P18: =SUM(P5:P17) -> 2202 | Q18: =SUM(Q5:Q16) -> 1509 | R18: =SUM(R5:R16) -> 2090 | S18: =SUM(S5:S16) -> 1997 | T18: =SUM(T5:T16) -> 2129 | U18: =SUM(U5:U16) -> 2132 | V18: =SUM(V5:V16) -> 2197 | W18: =SUM(W5:W16) -> 2367 | X18: =SUM(X5:X16) -> 1780 | ... AC18: =SUM(AC5:AC16) -> 2756 | AD18: =SUM(AD5:AD17) -> 2517 | AE18: =SUM(AE5:AE16) -> 3690 | AF18: =SUM(AF5:AF17) -> 4907 | AG18: =SUM(AG5:AG17) -> 3933 | AH18: =SUM(AH5:AH17) -> 3528 | AI18: =SUM(AI5:AI17) -> 3024 | AJ18: =SUM(AJ5:AJ17) -> 1697 | AK18: =SUM(AK5:AK17) -> 3063
I19: 2395

Sheet Becker Hollow
A1: Hunter-West Kill Mountain Wilderness
A2: Becker Hollow | X2: R10
B3: 1990 | C3: 1991 | D3: 1992 | E3: 1993 | F3: 1994 | G3: 1995 | H3: 1996 | I3: 1997 | J3: 1998 | K3: 1999 | L3: 2000 | M3: 2001 | N3: 2002 | O3: 2003 | P3: 2004 | Q3: 2005 | R3: 2006 | S3: 2007 | T3: 2008 | U3: 2009 | V3: 2010 | W3: 2011 | X3: 2012 | Y3: 2013 | Z3: 2014 | AA3: 2015 | AB3: 2016 | AC3: 2017 | AD3: 2018 | AE3: 2019 | AF3: 2020 | AG3: 2021 | AH3: 2022 | AI3: 2023 | AJ3: 2024 | AK3: 2025
A5: January | H5: 22 | I5: 47 | J5: 75 | K5: 23 | L5: 60 | P5: 46 | Q5: 25 | R5: 36 | S5: 61 | T5: 20 | U5: 17 | V5: 76 | W5: 8 | X5: 83 | Y5: * | Z5: 131 | AA5: 71 | AB5: 95 | AC5: 8 | AD5: 51 | AE5: 69 | AF5: 266 | AG5: 162 | AH5: 133 | AI5: * | AJ5: 137 | AK5: 26
A6: February | H6: 30 | I6: 31 | J6: 74 | K6: 33 | L6: 87 | P6: 42 | Q6: 57 | R6: 43 | S6: 25 | T6: 41 | U6: 101 | V6: 32 | W6: 50 | X6: 84 | Y6: * | Z6: 83 | AA6: 22 | AB6: 59 | AC6: 34 | AD6: 59 | AE6: 98 | AF6: 116 | AG6: 77 | AH6: 90 | AI6: * | AJ6: 98 | AK6: 59
A7: March | H7: 18 | I7: 48 | J7: 50 | K7: 25 | L7: 51 | P7: 29 | Q7: 30 | R7: 19 | S7: 29 | T7: 82 | U7: 45 | V7: 38 | W7: 49 | X7: 46 | Y7: * | Z7: 112 | AA7: * | AB7: 113 | AC7: 50 | AD7: 59 | AE7: 97 | AF7: 166 | AG7: 137 | AH7: 73 | AI7: 22 | AJ7: 97 | AK7: 127
A8: April | I8: 47 | J8: 67 | K8: 79 | L8: 69 | P8: 58 | Q8: 2 | R8: 67 | S8: 80 | T8: 72 | U8: 75 | V8: 78 | W8: 58 | X8: 114 | Y8: 63 | Z8: 98 | AA8: 86 | AB8: 108 | AC8: 107 | AD8: 94 | AE8: 145 | AF8: 106 | AG8: 163 | AH8: 175 | AI8: 182 | AJ8: 140 | AK8: 130
A9: May | I9: 107 | J9: 186 | K9: 256 | L9: 152 | P9: 186 | Q9: 43 | R9: 173 | S9: 122 | T9: 215 | U9: 139 | V9: 166 | W9: 144 | X9: 191 | Y9: 176 | Z9: 158 | AA9: 201 | AB9: 133 | AC9: 140 | AD9: 210 | AE9: 357 | AF9: 215 | AG9: 279 | AH9: 294 | AI9: 284 | AJ9: 285 | AK9: 242
A10: June | H10: 104 | I10: 108 | J10: 144 | K10: 99 | L10: 107 | P10: 146 | Q10: 133 | R10: 132 | S10: 112 | T10: 146 | U10: 213 | V10: 112 | W10: 136 | X10: 208 | Y10: 224 | Z10: 184 | AA10: 185 | AB10: 134 | AC10: 166 | AD10: 245 | AE10: 362 | AF10: 313 | AG10: 320 | AH10: 158 | AI10: 229 | AJ10: 194 | AK10: 303
A11: July | H11: 40 | I11: 264 | J11: 230 | K11: 73 | L11: 101 | P11: 173 | Q11: 257 | R11: 146 | S11: 221 | T11: 237 | U11: 305 | V11: 318 | W11: 21 | X11: 256 | Y11: 226 | Z11: 282 | AA11: 261 | AB11: 188 | AC11: 255 | AD11: 175 | AE11: 431 | AF11: 384 | AG11: 372 | AH11: 123 | AI11: 281 | AJ11: 74 | AK11: 302
A12: August | I12: 283 | J12: 251 | K12: 86 | L12: 282 | P12: 223 | Q12: 264 | R12: 295 | S12: 310 | T12: 266 | U12: 260 | V12: 253 | W12: 239 | X12: 369 | Y12: 348 | Z12: 310 | AA12: 343 | AB12: 224 | AC12: 312 | AD12: 49 | AE12: 330 | AF12: 569 | AG12: 333 | AH12: 288 | AI12: 335 | AJ12: 81 | AK12: 40
A13: September | I13: 163 | J13: 184 | K13: 189 | L13: 168 | P13: 155 | Q13: 216 | R13: 116 | S13: 217 | T13: 114 | U13: 21 | V13: 217 | W13: 171 | X13: 88 | Y13: 231 | Z13: 167 | AA13: 199 | AB13: 130 | AC13: 232 | AD13: 115 | AE13: 502 | AF13: 370 | AG13: 252 | AH13: 215 | AI13: 280 | AJ13: *
A14: October | I14: 138 | J14: 190 | K14: 185 | L14: 189 | P14: 202 | Q14: 117 | R14: 162 | S14: 186 | T14: 188 | U14: 54 | V14: 192 | W14: 288 | X14: * | Y14: 219 | Z14: 208 | AA14: 260 | AB14: 158 | AC14: 334 | AD14: 205 | AE14: 525 | AF14: 459 | AG14: 332 | AH14: 186 | AI14: 272 | AJ14: *
A15: November | I15: 66 | J15: 155 | K15: 107 | L15: 78 | P15: 76 | Q15: 78 | R15: 113 | S15: 67 | T15: 83 | U15: 110 | V15: 83 | W15: 140 | X15: * | Y15: 131 | Z15: 99 | AA15: 140 | AB15: 130 | AC15: 135 | AD15: 112 | AE15: 311 | AF15: 260 | AG15: 178 | AH15: 200 | AI15: 209 | AJ15: *
A16: December | I16: 38 | J16: 36 | K16: 60 | P16: 36 | Q16: 41 | R16: 39 | S16: 55 | T16: 27 | U16: 29 | V16: 40 | W16: 72 | X16: * | Y16: 120 | Z16: 60 | AA16: 90 | AB16: 47 | AC16: 48 | AD16: 113 | AE16: 92 | AF16: 123 | AG16: 117 | AH16: * | AI16: 87 | AJ16: * | AM16: *Registers missing
A18: Yearly Totals | B18: 1175 | C18: 1645 | D18: 1115 | E18: 1146 | F18: 1802 | G18: 886 | H18: =SUM(H5:H16) -> 214 | I18: =SUM(I5:I17) -> 1340 | J18: =SUM(J5:J17) -> 1642 | K18: =SUM(K5:K17) -> 1215 | L18: =SUM(L5:L17) -> 1344 | M18: 1036 | N18: 1098 | O18: 1091 | P18: =SUM(P5:P17) -> 1372 | Q18: =SUM(Q5:Q16) -> 1263 | R18: =SUM(R5:R16) -> 1341 | S18: =SUM(S5:S16) -> 1485 | T18: =SUM(T5:T16) -> 1491 | U18: =SUM(U5:U16) -> 1369 | V18: =SUM(V5:V16) -> 1605 | W18: =SUM(W5:W16) -> 1376 | X18: =SUM(X5:X16) -> 1439 | ... AK18: =SUM(AK5:AK16) -> 1229
K19: 1382

Sheet Beech Hill Rd
A1: Delaware Wild Forest
A2: Beech Hill Rd | V2: R53
B3: 1991 | C3: 1992 | D3: 1993 | E3: 1994 | F3: 1995 | G3: 1996 | H3: 1997 | I3: 1998 | J3: 1999 | K3: 2000 | L3: 2001 | M3: 2002 | N3: 2003 | O3: 2004 | P3: 2005 | Q3: 2006 | R3: 2007 | S3: 2008 | T3: 2009 | U3: 2010 | V3: 2011 | W3: 2012 | X3: 2013 | Y3: 2014 | Z3: 2015 | AA3: 2016 | AB3: 2017 | AC3: 2018 | AD3: 2019 | AE3: 2020 | AF3: 2021 | AG3: 2022 | AH3: 2023 | AI3: 2024 | AJ3: 2025 | AK3: 2026
A5: January | H5: 1 | I5: 3 | J5: 4 | K5: 2 | O5: 5 | P5: 15 | Q5: 12 | R5: 9 | S5: 1 | T5: 2 | U5: 3 | V5: 8 | W5: 1 | X5: * | Y5: 0 | Z5: 6 | AA5: 5 | AB5: 7 | AC5: 1 | AD5: 2 | AE5: 6 | AF5: 3 | AG5: 10 | AH5: 5 | AI5: 8 | AJ5: 5 | AK5: 3 | AL5: =AVERAGE(Q5:AA5) -> 4.7 | AM5: =AVERAGE(R5:AA5) -> 3.8888889
A6: February | I6: 1 | J6: 0 | K6: 0 | O6: 1 | P6: 1 | Q6: 4 | R6: 1 | S6: 3 | T6: 1 | U6: 0 | V6: 0 | W6: 21 | X6: * | Y6: 0 | Z6: 0 | AA6: 2 | AB6: 4 | AC6: 1 | AD6: 1 | AE6: 1 | AF6: 1 | AG6: 7 | AH6: 10 | AI6: * | AL6: =AVERAGE(Q6:AA6) -> 3.2 | AM6: =AVERAGE(R6:AA6) -> 3.1111111
A7: March | H7: 1 | I7: 3 | J7: 0 | K7: 3 | O7: 5 | Q7: 14 | R7: 2 | S7: 11 | T7: 4 | U7: 3 | V7: 1 | W7: 4 | X7: * | Y7: 0 | Z7: 3 | AA7: 12 | AB7: 3 | AC7: * | AD7: 3 | AE7: 5 | AF7: 6 | AG7: 13 | AH7: * | AI7: 4 | AJ7: 6 | AL7: =AVERAGE(Q7:AA7) -> 5.4 | AM7: =AVERAGE(R7:AA7) -> 4.4444444
A8: April | H8: 20 | I8: 1 | J8: 3 | K8: 9 | O8: 8 | P8: 8 | Q8: 2 | R8: 0 | S8: 2 | T8: 8 | U8: 13 | V8: 0 | W8: 9 | X8: * | Y8: 3 | Z8: 4 | AA8: 23 | AB8: 10 | AC8: * | AD8: 12 | AE8: 12 | AF8: 5 | AG8: 22 | AH8: 21 | AI8: 11 | AJ8: 2 | AL8: =AVERAGE(Q8:AA8) -> 6.4 | AM8: =AVERAGE(R8:AA8) -> 6.8888889
A9: May | H9: 10 | I9: 30 | J9: 27 | K9: 41 | O9: 28 | P9: 40 | Q9: 20 | R9: 11 | S9: 22 | T9: 23 | U9: 27 | V9: 22 | W9: 12 | X9: 3 | Y9: 16 | Z9: 40 | AA9: 14 | AB9: 20 | AC9: 22 | AD9: 33 | AE9: 26 | AF9: 13 | AG9: 3 | AH9: 17 | AI9: 12 | AJ9: 4 | AL9: =AVERAGE(Q9:AA9) -> 19.090909 | AM9: =AVERAGE(R9:AA9) -> 19
A10: June | H10: 15 | I10: 7 | J10: 5 | K10: 8 | O10: 12 | P10: 31 | Q10: 12 | R10: 12 | S10: 24 | T10: 27 | U10: 10 | V10: 14 | W10: 20 | X10: 8 | Y10: 17 | Z10: 23 | AA10: 9 | AB10: 8 | AC10: 14 | AD10: 46 | AE10: 20 | AF10: 24 | AG10: 10 | AH10: 12 | AI10: 12 | AJ10: 12 | AL10: =AVERAGE(Q10:AA10) -> 16 | AM10: =AVERAGE(R10:AA10) -> 16.4
A11: July | H11: 27 | I11: 15 | J11: 19 | K11: 20 | O11: 32 | P11: 32 | Q11: 16 | R11: 27 | S11: 14 | T11: 76 | U11: 15 | V11: 85 | W11: 40 | X11: 26 | Y11: 14 | Z11: 14 | AA11: 21 | AB11: 25 | AC11: 13 | AD11: 23 | AE11: 40 | AF11: 31 | AG11: 32 | AH11: 13 | AI11: 19 | AJ11: 31 | AL11: =AVERAGE(Q11:AA11) -> 31.636364 | AM11: =AVERAGE(R11:AA11) -> 33.2
A12: August | H12: 26 | I12: 60 | J12: 17 | K12: 61 | O12: 9 | P12: 23 | Q12: 28 | R12: 31 | S12: 67 | T12: 30 | U12: 12 | V12: 39 | W12: 22 | X12: 29 | Y12: 29 | Z12: 23 | AA12: 16 | AB12: 44 | AC12: 50 | AD12: 52 | AE12: 63 | AF12: 20 | AG12: 20 | AH12: 17 | AI12: 22 | AJ12: 31 | AL12: =AVERAGE(Q12:AA12) -> 29.636364 | AM12: =AVERAGE(R12:AA12) -> 29.8
A13: September | H13: 18 | I13: 21 | J13: 20 | K13: 26 | O13: 20 | P13: 34 | Q13: 18 | R13: 5 | S13: 27 | T13: 8 | U13: 16 | V13: 17 | W13: 30 | X13: 23 | Y13: 19 | Z13: 18 | AA13: 21 | AB13: 19 | AC13: 5 | AD13: 37 | AE13: 52 | AF13: 33 | AG13: 31 | AH13: 24 | AI13: 16 | AJ13: 20 | AL13: =AVERAGE(Q13:AA13) -> 18.363636 | AM13: =AVERAGE(R13:AA13) -> 18.4
A14: October | H14: 15 | I14: 25 | J14: 25 | K14: 22 | O14: 31 | P14: 15 | Q14: 22 | R14: 48 | S14: 30 | T14: 3 | U14: 19 | V14: 13 | W14: * | X14: 26 | Y14: 13 | Z14: 37 | AA14: 21 | AB14: 17 | AC14: 25 | AD14: 20 | AE14: 46 | AF14: 36 | AG14: 31 | AH14: 20 | AI14: 7 | AJ14: 29 | AL14: =AVERAGE(Q14:AA14) -> 23.2 | AM14: =AVERAGE(R14:AA14) -> 23.333333
A15: November | H15: 4 | I15: 7 | J15: 16 | K15: 32 | O15: 9 | P15: 9 | Q15: 4 | R15: 9 | S15: 13 | T15: 9 | U15: 15 | V15: 8 | W15: * | X15: 2 | Y15: 6 | Z15: 7 | AA15: 26 | AB15: 11 | AC15: 2 | AD15: 9 | AE15: 8 | AF15: 17 | AG15: 12 | AH15: 2 | AI15: 7 | AJ15: 9 | AL15: =AVERAGE(Q15:AA15) -> 9.9 | AM15: =AVERAGE(R15:AA15) -> 10.555556
A16: December | H16: 0 | I16: 6 | J16: 12 | K16: 2 | O16: 7 | P16: 12 | Q16: 2 | R16: 6 | S16: 1 | T16: 4 | U16: 7 | V16: 4 | W16: * | X16: 2 | Y16: 1 | Z16: 21 | AA16: 10 | AB16: * | AC16: 16 | AD16: * | AE16: 16 | AF16: 21 | AG16: 14 | AH16: 5 | AI16: 3 | AJ16: 4 | AL16: =AVERAGE(Q16:AA16) -> 5.8 | AM16: =AVERAGE(R16:AA16) -> 6.2222222 | AO16: *Registers missing
A18: Yearly Totals | B18: =SUM(B5:B16) -> 0 | C18: =SUM(C5:C16) -> 0 | D18: =SUM(D5:D16) -> 0 | E18: =SUM(E5:E16) -> 0 | F18: =SUM(F5:F16) -> 0 | G18: =SUM(G5:G16) -> 0 | H18: =SUM(H5:H17) -> 137 | I18: =SUM(I5:I17) -> 179 | J18: =SUM(J5:J17) -> 148 | K18: =SUM(K5:K17) -> 226 | L18: 186 | M18: 141 | N18: 158 | O18: =SUM(O5:O17) -> 167 | P18: =SUM(P5:P17) -> 220 | Q18: =SUM(Q5:Q17) -> 154 | R18: =SUM(R5:R17) -> 161 | S18: =SUM(S5:S16) -> 215 | T18: =SUM(T5:T16) -> 195 | U18: =SUM(U5:U16) -> 140 | V18: =SUM(V5:V16) -> 211 | W18: =SUM(W5:W16) -> 159 | X18: =SUM(X5:X16) -> 119 | Y18: =SUM(Y5:Y16) -> 118 | Z18: =SUM(Z5:Z16) -> 196 | ... AB18: =SUM(AB5:AB16) -> 168 | AC18: =SUM(AC5:AC17) -> 149 | AD18: =SUM(AD5:AD17) -> 238 | AE18: =SUM(AE5:AE17) -> 295 | AF18: =SUM(AF5:AF17) -> 210 | AG18: =SUM(AG5:AG17) -> 205 | AH18: =SUM(AH5:AH17) -> 146 | AI18: =SUM(AI5:AI17) -> 121 | AJ18: =SUM(AJ5:AJ17) -> 153 | AK18: =SUM(AK5:AK17) -> 3
H19: 180

Sheet Big Pond East
A1: Delaware Wild Forest
A2: Big Pond East | V2: R49
B3: 1991 | C3: 1992 | D3: 1993 | E3: 1994 | F3: 1995 | G3: 1996 | H3: 1997 | I3: 1998 | J3: 1999 | K3: 2000 | L3: 2001 | M3: 2002 | N3: 2003 | O3: 2004 | P3: 2005 | Q3: 2006 | R3: 2007 | S3: 2008 | T3: 2009 | U3: 2010 | V3: 2011 | W3: 2012 | X3: 2013 | Y3: 2014 | Z3: 2015 | AA3: 2016 | AB3: 2017 | AC3: 2018 | AD3: 2019 | AE3: 2020 | AF3: 2021 | AG3: 2022 | AH3: 2023 | AI3: 2024 | AJ3: 2025 | AK3: 2026
A5: January | I5: 4 | J5: 1 | O5: 1 | P5: 3 | Q5: 2 | R5: 9 | S5: 7 | T5: 0 | U5: 0 | V5: 3 | W5: 1 | X5: * | Y5: 0 | Z5: 6 | AA5: 5 | AB5: 4 | AC5: 6 | AD5: * | AE5: 6 | AF5: 15 | AG5: 0 | AH5: 3 | AI5: 5 | AJ5: 3 | AK5: 6
A6: February | I6: 7 | J6: 6 | K6: 0 | O6: 1 | P6: 1 | Q6: 6 | R6: 0 | S6: 2 | T6: 0 | U6: 13 | V6: 0 | W6: 5 | X6: * | Y6: 1 | Z6: 1 | AA6: 6 | AB6: 5 | AC6: 0 | AD6: 3 | AE6: 3 | AF6: 0 | AG6: 7 | AH6: 3 | AI6: 7 | AJ6: 0
A7: March | I7: 4 | J7: 3 | K7: 5 | O7: 7 | Q7: 4 | R7: 3 | S7: 6 | T7: 0 | U7: 5 | V7: 5 | W7: 16 | X7: * | Y7: 23 | Z7: 2 | AA7: 18 | AB7: 1 | AC7: 4 | AD7: 1 | AE7: 5 | AF7: 14 | AG7: 7 | AH7: 12 | AI7: 12 | AJ7: 12
A8: April | H8: 9 | I8: 5 | J8: 10 | K8: 10 | O8: 23 | P8: 19 | Q8: 18 | R8: 11 | S8: 27 | T8: 0 | U8: 19 | V8: 33 | W8: 42 | X8: * | Y8: 22 | Z8: 9 | AA8: 20 | AB8: 13 | AC8: 12 | AD8: 25 | AE8: 10 | AF8: 26 | AG8: 17 | AH8: 42 | AI8: 8 | AJ8: 16
A9: May | H9: 20 | I9: 17 | J9: 35 | K9: 66 | O9: 38 | P9: 32 | Q9: 22 | R9: 44 | S9: 73 | T9: 17 | U9: 59 | V9: 44 | W9: 70 | X9: 48 | Y9: 58 | Z9: 69 | AA9: 81 | AB9: 33 | AC9: 24 | AD9: 48 | AE9: 60 | AF9: 40 | AG9: 60 | AH9: 37 | AI9: 78 | AJ9: 33
A10: June | H10: 17 | I10: 17 | J10: 0 | K10: 22 | O10: 40 | P10: 22 | Q10: 28 | R10: 21 | S10: 65 | T10: 60 | U10: 29 | V10: 42 | W10: 74 | X10: 67 | Y10: 88 | Z10: 44 | AA10: 76 | AB10: 72 | AC10: 73 | AD10: 64 | AE10: 120 | AF10: 72 | AG10: 65 | AH10: 42 | AI10: 40 | AJ10: 73
A11: July | H11: 26 | I11: 44 | J11: 13 | K11: 37 | O11: 52 | P11: 52 | Q11: 42 | R11: 74 | S11: 94 | T11: 95 | U11: 60 | V11: 145 | W11: 79 | X11: 88 | Y11: 87 | Z11: 117 | AA11: 118 | AB11: 140 | AC11: 67 | AD11: 48 | AE11: 165 | AF11: 86 | AG11: 110 | AH11: 19 | AI11: 66 | AJ11: 44
A12: August | H12: 13 | K12: 35 | O12: 40 | P12: 44 | Q12: 70 | R12: 70 | S12: 65 | T12: 94 | U12: 72 | V12: 137 | W12: 56 | X12: 161 | Y12: 177 | Z12: 88 | AA12: 107 | AB12: 132 | AC12: 102 | AD12: 114 | AE12: 148 | AF12: 67 | AG12: 70 | AH12: 43 | AI12: 37 | AJ12: 92
A13: September | H13: 12 | I13: 42 | K13: 16 | O13: 41 | P13: 44 | Q13: 31 | R13: 28 | S13: 27 | T13: 31 | U13: 52 | V13: 54 | W13: 29 | X13: 51 | Y13: 45 | Z13: 92 | AA13: 56 | AB13: 52 | AC13: 28 | AD13: 41 | AE13: 106 | AF13: 41 | AG13: 42 | AH13: 31 | AI13: 19 | AJ13: 59
A14: October | H14: 11 | I14: 54 | J14: 13 | K14: 36 | O14: 21 | P14: 101 | Q14: 25 | R14: 71 | S14: 34 | T14: 44 | U14: 52 | V14: 37 | W14: * | X14: 44 | Y14: 51 | Z14: 34 | AA14: 43 | AB14: 50 | AC14: 13 | AD14: 31 | AE14: 75 | AF14: 46 | AG14: 41 | AH14: 30 | AI14: 31 | AJ14: 36 | AL14: *Sheets from October 2009 possibly missing
A15: November | H15: 5 | I15: 21 | J15: 8 | K15: 39 | O15: 6 | P15: 50 | Q15: 28 | R15: 21 | S15: 5 | T15: 17 | U15: 33 | V15: 36 | W15: * | X15: 19 | Y15: 5 | Z15: 21 | AA15: 37 | AB15: 12 | AC15: 8 | AD15: 14 | AE15: 28 | AF15: 12 | AG15: 6 | AH15: 22 | AI15: 23 | AJ15: 4
A16: December | H16: 7 | I16: 8 | J16: 3 | K16: 6 | O16: 3 | P16: 13 | Q16: 14 | R16: 2 | S16: 0 | T16: 3 | U16: 9 | V16: 15 | W16: * | X16: 2 | Y16: 0 | Z16: 6 | AA16: 6 | AB16: 3 | AC16: 17 | AD16: 2 | AE16: 6 | AF16: 10 | AG16: 6 | AH16: * | AI16: 1 | AJ16: 2 | AL16: *Registers missing
A18: Yearly Totals | B18: =SUM(B5:B16) -> 0 | C18: =SUM(C5:C16) -> 0 | D18: =SUM(D5:D16) -> 0 | E18: =SUM(E5:E16) -> 0 | F18: =SUM(F5:F16) -> 0 | G18: =SUM(G5:G16) -> 0 | H18: =SUM(H5:H17) -> 120 | I18: =SUM(I5:I17) -> 223 | J18: =SUM(J5:J17) -> 92 | K18: =SUM(K5:K17) -> 272 | L18: 285 | M18: 297 | N18: 302 | O18: =SUM(O5:O17) -> 273 | P18: =SUM(P5:P17) -> 381 | Q18: =SUM(Q5:Q17) -> 290 | R18: =SUM(R5:R17) -> 354 | S18: =SUM(S5:S16) -> 405 | T18: =SUM(T5:T16) -> 361 | U18: =SUM(U5:U16) -> 403 | V18: =SUM(V5:V16) -> 551 | W18: =SUM(W5:W16) -> 372 | X18: =SUM(X5:X16) -> 480 | Y18: =SUM(Y5:Y16) -> 557 | Z18: =SUM(Z5:Z16) -> 489 | AA18: =SUM(AA5:AA16) -> 573 | AB18: =SUM(AB5:AB17) -> 517 | AC18: =SUM(AC5:AC17) -> 354 | AD18: =SUM(AD5:AD17) -> 391 | AE18: =SUM(AE5:AE17) -> 732 | AF18: =SUM(AF5:AF17) -> 429 | AG18: =SUM(AG5:AG17) -> 431 | AH18: =SUM(AH5:AH17) -> 284 | AI18: =SUM(AI5:AI17) -> 327 | ... AK18: =SUM(AK5:AK17) -> 6
F19: 8 | H19: 144 | I19: 256 | J19: 231

Sheet Big Pond West
A1: Delaware Wild Forest
A2: Big Pond West | V2: R41
B3: 1991 | C3: 1992 | D3: 1993 | E3: 1994 | F3: 1995 | G3: 1996 | H3: 1997 | I3: 1998 | J3: 1999 | K3: 2000 | L3: 2001 | M3: 2002 | N3: 2003 | O3: 2004 | P3: 2005 | Q3: 2006 | R3: 2007 | S3: 2008 | T3: 2009 | U3: 2010 | V3: 2011 | W3: 2012 | X3: 2013 | Y3: 2014 | Z3: 2015 | AA3: 2016 | AB3: 2017 | AC3: 2018 | AD3: 2019 | AE3: 2020 | AF3: 2021 | AG3: 2022 | AH3: 2023 | AI3: 2024 | AJ3: 2025 | AK3: 2026
A5: January | H5: 7 | I5: 6 | J5: 2 | K5: * | O5: 3 | P5: 1 | Q5: 1 | R5: 0 | S5: 1 | T5: 3 | U5: 6 | V5: 14 | W5: 1 | X5: * | Y5: 1 | Z5: 2 | AA5: * | AB5: 10 | AC5: 0 | AD5: 0 | AE5: 6 | AF5: 4 | AG5: 1 | AH5: 3 | AI5: 8 | AJ5: 3 | AK5: 2
A6: February | H6: 1 | I6: 4 | J6: 7 | K6: * | O6: 4 | P6: 1 | Q6: 6 | R6: 0 | S6: 3 | T6: 0 | U6: 0 | V6: 2 | W6: 5 | X6: * | Y6: 0 | Z6: 2 | AA6: * | AB6: 1 | AC6: 5 | AD6: 2 | AE6: 10 | AF6: 2 | AG6: 3 | AH6: 9 | AI6: 2 | AJ6: 4
A7: March | H7: 4 | I7: 8 | J7: 0 | K7: 5 | O7: 4 | Q7: 17 | R7: 1 | S7: 3 | T7: 1 | U7: 5 | V7: 4 | W7: 5 | X7: * | Y7: 10 | Z7: 0 | AA7: * | AB7: 1 | AC7: 3 | AD7: 4 | AE7: 23 | AF7: 22 | AG7: 5 | AH7: 6 | AI7: 25 | AJ7: 8
A8: April | H8: 21 | I8: 3 | J8: 2 | K8: 3 | O8: 7 | P8: 1 | Q8: 8 | R8: 7 | S8: 8 | T8: 4 | U8: 20 | V8: 8 | W8: 32 | X8: * | Y8: 32 | Z8: 7 | AA8: 34 | AB8: 16 | AC8: 5 | AD8: 16 | AE8: 29 | AF8: 18 | AG8: 14 | AH8: 29 | AI8: 15 | AJ8: 15
A9: May | H9: 25 | I9: 22 | J9: 51 | K9: 41 | O9: 15 | P9: 16 | Q9: 23 | R9: 0 | S9: 35 | T9: 24 | U9: 18 | V9: 22 | W9: 24 | X9: 31 | Y9: 17 | Z9: 19 | AA9: 23 | AB9: 22 | AC9: 25 | AD9: 15 | AE9: 26 | AF9: 51 | AG9: 24 | AH9: 12 | AI9: 38 | AJ9: 25
A10: June | H10: 24 | I10: 3 | J10: 12 | K10: 14 | O10: 11 | P10: 26 | Q10: 19 | R10: 20 | S10: 22 | T10: 27 | U10: 11 | V10: 24 | W10: 36 | X10: 25 | Y10: 31 | Z10: 20 | AA10: 20 | AB10: 23 | AC10: 12 | AD10: 41 | AE10: 57 | AF10: 42 | AG10: 46 | AH10: 33 | AI10: 13 | AJ10: 36
A11: July | H11: 58 | I11: 20 | J11: 17 | K11: 108 | O11: 24 | P11: 41 | Q11: 24 | R11: 34 | S11: 35 | T11: 70 | U11: 48 | V11: 84 | W11: 44 | X11: 14 | Y11: 17 | Z11: 23 | AA11: 41 | AB11: 34 | AC11: 48 | AD11: 32 | AE11: 53 | AF11: 57 | AG11: 46 | AH11: 22 | AI11: 20 | AJ11: 49
A12: August | H12: 38 | I12: 65 | J12: 34 | K12: 29 | O12: 63 | P12: 33 | Q12: 64 | R12: 34 | S12: 64 | T12: 38 | U12: 44 | V12: 57 | W12: 41 | X12: 92 | Y12: 74 | Z12: 42 | AA12: 20 | AB12: 87 | AC12: 50 | AD12: 72 | AE12: 68 | AF12: 71 | AG12: 33 | AH12: 36 | AI12: 45 | AJ12: 59
A13: September | H13: 8 | I13: 25 | J13: 34 | K13: 21 | O13: 17 | P13: 29 | Q13: 18 | R13: 33 | S13: 0 | T13: 16 | U13: 58 | V13: 20 | W13: * | X13: 21 | Y13: 40 | Z13: 42 | AA13: 22 | AB13: 27 | AC13: 34 | AD13: 36 | AE13: 79 | AF13: 31 | AG13: 33 | AH13: 14 | AI13: 16 | AJ13: 34
A14: October | H14: 19 | I14: 28 | J14: 37 | K14: 27 | O14: 25 | P14: 45 | Q14: 20 | R14: 54 | S14: 6 | T14: 64 | U14: 22 | V14: 21 | W14: * | X14: 36 | Y14: 39 | Z14: 43 | AA14: 24 | AB14: 30 | AC14: 9 | AD14: 37 | AE14: 54 | AF14: 55 | AG14: 14 | AH14: 16 | AI14: 17 | AJ14: 18
A15: November | H15: 8 | I15: 2 | J15: 16 | K15: 9 | O15: 7 | P15: 5 | Q15: 28 | R15: 7 | S15: 4 | T15: 24 | U15: 14 | V15: 11 | W15: * | X15: 8 | Y15: 12 | Z15: 8 | AA15: 4 | AB15: 16 | AC15: 1 | AD15: 12 | AE15: 20 | AF15: 6 | AG15: 9 | AH15: 13 | AI15: 10 | AJ15: 10
A16: December | H16: 0 | I16: 4 | J16: 1 | K16: 1 | O16: 1 | P16: 4 | Q16: 1 | R16: 5 | S16: 0 | T16: 3 | U16: 1 | V16: 20 | W16: * | X16: 0 | Y16: 8 | Z16: 5 | AA16: 11 | AB16: 1 | AC16: 7 | AD16: 12 | AE16: 6 | AF16: 12 | AG16: 3 | AH16: 1 | AI16: 1 | AJ16: 4 | AM16: *Registers missing
A18: Yearly Totals | B18: =SUM(B5:B16) -> 0 | C18: =SUM(C5:C16) -> 0 | D18: =SUM(D5:D16) -> 0 | E18: =SUM(E5:E16) -> 0 | F18: =SUM(F5:F16) -> 0 | G18: =SUM(G5:G16) -> 0 | H18: =SUM(H5:H16) -> 213 | I18: =SUM(I5:I17) -> 190 | J18: =SUM(J5:J17) -> 213 | K18: =SUM(K7:K17) -> 258 | L18: 214 | M18: 219 | N18: 185 | O18: =SUM(O5:O17) -> 181 | P18: =SUM(P5:P17) -> 202 | Q18: =SUM(Q5:Q17) -> 229 | R18: =SUM(R5:R17) -> 195 | S18: =SUM(S5:S16) -> 181 | T18: =SUM(T5:T16) -> 274 | U18: =SUM(U5:U16) -> 247 | V18: =SUM(V5:V16) -> 287 | W18: =SUM(W5:W16) -> 188 | X18: =SUM(X5:X16) -> 227 | Y18: =SUM(Y5:Y16) -> 281 | Z18: =SUM(Z5:Z16) -> 213 | AA18: =SUM(AA5:AA16) -> 199 | AB18: =SUM(AB5:AB17) -> 268 | AC18: =SUM(AC5:AC17) -> 199 | AD18: =SUM(AD5:AD17) -> 279 | AE18: =SUM(AE5:AE17) -> 431 | AF18: =SUM(AF5:AF17) -> 371 | AG18: =SUM(AG5:AG17) -> 231 | AH18: =SUM(AH5:AH17) -> 194 | AI18: =SUM(AI5:AI17) -> 210 | ... AK18: =SUM(AK5:AK17) -> 2
F19: 452 | H19: 227

Sheet Bouchoux Trail
A1: Detached Forest Parcel Wild Forest
A2: Bouchoux Trail | Y2: R59
B3: 1991 | C3: 1992 | D3: 1993 | E3: 1994 | F3: 1995 | G3: 1996 | H3: 1997 | I3: 1998 | J3: 1999 | K3: 2000 | L3: 2001 | M3: 2002 | N3: 2003 | O3: 2004 | P3: 2005 | Q3: 2006 | R3: 2007 | S3: 2008 | T3: 2009 | U3: 2010 | V3: 2011 | W3: 2012 | X3: 2013 | Y3: 2014 | Z3: 2015 | AA3: 2016 | AB3: 2017 | AC3: 2018 | AD3: 2019 | AE3: 2020 | AF3: 2021 | AG3: 2022 | AH3: 2023 | AI3: 2024 | AJ3: 2025
A5: January | K5: 11 | O5: 14 | P5: 33 | Q5: 30 | R5: 40 | S5: 9 | T5: 9 | U5: 12 | V5: 14 | W5: 48 | X5: * | Y5: 6 | Z5: 42 | AA5: 63 | AB5: 32 | AC5: 22 | AD5: 30 | AE5: 51 | AF5: 32 | AG5: 19 | AH5: 45 | AI5: 21 | AJ5: 3
A6: February | K6: 2 | O6: 22 | P6: 14 | Q6: 11 | R6: 2 | S6: 10 | T6: 1 | U6: 13 | V6: 20 | W6: 17 | X6: * | Y6: 2 | Z6: 8 | AA6: 64 | AB6: 28 | AC6: 51 | AD6: 18 | AE6: 11 | AF6: 12 | AG6: 47 | AH6: 40 | AI6: 33 | AJ6: 11
A7: March | K7: 35 | O7: 44 | P7: 21 | Q7: 15 | R7: 24 | S7: 3 | T7: 37 | U7: 23 | V7: 33 | W7: 63 | X7: * | Y7: 29 | Z7: 9 | AA7: 84 | AB7: 11 | AC7: 47 | AD7: 45 | AE7: 111 | AF7: 84 | AG7: 62 | AH7: 30 | AI7: 69 | AJ7: 88
A8: April | K8: 58 | O8: 56 | P8: 54 | Q8: 90 | R8: 29 | S8: 58 | T8: 35 | U8: 68 | V8: 34 | W8: 36 | X8: * | Y8: 76 | Z8: 65 | AA8: 109 | AB8: 151 | AC8: 97 | AD8: 75 | AE8: 170 | AF8: 144 | AG8: 101 | AH8: 132 | AI8: 55 | AJ8: 62
A9: May | K9: 90 | O9: 104 | P9: 59 | Q9: 97 | R9: 99 | S9: 74 | T9: 63 | U9: 124 | V9: 281 | W9: 300 | X9: 80 | Y9: 135 | Z9: 163 | AA9: 182 | AB9: 64 | AC9: 111 | AD9: 180 | AE9: 273 | AF9: 153 | AG9: 154 | AH9: 69 | AI9: 115 | AJ9: 132
A10: June | K10: 46 | O10: 89 | P10: 122 | Q10: 47 | R10: 39 | S10: 101 | T10: 67 | U10: 111 | V10: 24 | W10: 401 | X10: 290 | Y10: 189 | Z10: 111 | AA10: 202 | AB10: 328 | AC10: 313 | AD10: 308 | AE10: 231 | AF10: 147 | AG10: 133 | AH10: 100 | AI10: 224 | AJ10: 133
A11: July | K11: 127 | O11: 184 | P11: 376 | Q11: 309 | R11: 259 | S11: 258 | T11: 639 | U11: 420 | V11: 219 | W11: 327 | X11: 146 | Y11: 391 | Z11: 491 | AA11: 381 | AB11: 566 | AC11: 399 | AD11: 635 | AE11: 368 | AF11: 375 | AG11: 351 | AH11: 257 | AI11: 271 | AJ11: 291
A12: August | K12: 191 | O12: 128 | P12: 271 | Q12: 128 | R12: 128 | S12: 215 | T12: 175 | U12: 152 | V12: 304 | W12: 255 | X12: 177 | Y12: 313 | Z12: 289 | AA12: 268 | AB12: 311 | AC12: 292 | AD12: 295 | AE12: 363 | AF12: 265 | AG12: 174 | AH12: 216 | AI12: 153 | AJ12: 316
A13: September | K13: 60 | O13: 149 | P13: 80 | Q13: 79 | R13: 72 | S13: 27 | T13: 99 | U13: 113 | V13: 86 | W13: 96 | X13: 147 | Y13: 99 | Z13: 209 | AA13: 265 | AB13: 383 | AC13: 197 | AD13: 210 | AE13: 294 | AF13: 209 | AG13: 80 | AH13: 164 | AI13: 122 | AJ13: 95
A14: October | K14: 101 | O14: 112 | Q14: 136 | R14: 93 | S14: 61 | T14: 87 | U14: 115 | V14: 12 | W14: 61 | X14: 177 | Y14: 107 | Z14: 152 | AA14: 116 | AB14: 307 | AC14: 158 | AD14: 200 | AE14: 345 | AF14: 268 | AG14: 213 | AH14: 189 | AI14: 257 | AJ14: 125
A15: November | K15: 36 | O15: 36 | P15: 14 | Q15: 18 | R15: 47 | S15: 30 | T15: 43 | U15: 75 | V15: 72 | W15: * | X15: 45 | Y15: 45 | Z15: 101 | AA15: 128 | AB15: 135 | AC15: 55 | AD15: 117 | AE15: 50 | AF15: 58 | AG15: 34 | AH15: 94 | AI15: 106 | AJ15: 38
A16: December | K16: 32 | O16: 2 | P16: 3 | Q16: 37 | S16: 6 | T16: 14 | V16: 42 | W16: * | X16: 27 | Y16: 40 | Z16: 61 | AA16: 9 | AB16: 40 | AC16: 19 | AD16: 32 | AE16: 57 | AF16: 60 | AG16: * | AH16: 50 | AI16: 12 | AJ16: 12 | AK16: *Registers missing
A18: Yearly Totals | B18: =SUM(B5:B16) -> 0 | C18: =SUM(C5:C16) -> 0 | D18: =SUM(D5:D16) -> 0 | E18: =SUM(E5:E16) -> 0 | F18: =SUM(F5:F16) -> 0 | G18: =SUM(G5:G16) -> 0 | H18: =SUM(H5:H16) -> 0 | I18: =SUM(I5:I16) -> 0 | J18: 666 | K18: =SUM(K5:K17) -> 789 | L18: 814 | M18: 854 | N18: 597 | O18: =SUM(O5:O17) -> 940 | P18: =SUM(P5:P16) -> 1047 | Q18: =SUM(Q5:Q16) -> 997 | R18: =SUM(R5:R16) -> 832 | S18: =SUM(S5:S16) -> 852 | T18: =SUM(T5:T16) -> 1269 | U18: =SUM(U5:U16) -> 1226 | V18: =SUM(V5:V16) -> 1141 | W18: =SUM(W5:W16) -> 1604 | ... AA18: =SUM(AA5:AA16) -> 1871 | AB18: =SUM(AB5:AB17) -> 2356 | AC18: =SUM(AC5:AC17) -> 1761 | AD18: =SUM(AD5:AD17) -> 2145 | AE18: =SUM(AE5:AE17) -> 2324 | AF18: =SUM(AF5:AF17) -> 1807 | AG18: =SUM(AG5:AG17) -> 1368 | AH18: =SUM(AH5:AH17) -> 1386 | AI18: =SUM(AI5:AI17) -> 1438 | AJ18: =SUM(AJ5:AJ17) -> 1306

Sheet Boulder Rock (REMOVED)
A1: Kaaterskill Wild Forest
A2: Boulder Rock | W2: R29
B3: 1991 | C3: 1992 | D3: 1993 | E3: 1994 | F3: 1995 | G3: 1996 | H3: 1997 | I3: 1998 | J3: 1999 | K3: 2000 | L3: 2001 | M3: 2002 | N3: 2003 | O3: 2004 | P3: 2005 | Q3: 2006 | R3: 2007 | S3: 2008 | T3: 2009 | U3: 2010 | V3: 2011 | W3: 2012 | X3: 2013 | Y3: 2014 | Z3: 2015 | AA3: 2016 | AB3: 2017 | AC3: 2018 | AD3: 2019
A5: January | H5: 2 | I5: 16 | J5: 0 | K5: 12 | O5: 37 | P5: 3 | Q5: 5 | R5: 12 | S5: 6 | T5: 13 | U5: 8 | V5: 5 | W5: 116 | X5: * | Y5: 23 | Z5: 25 | AA5: 14 | AB5: 18 | AC5: 20
A6: February | H6: 10 | I6: 25 | J6: 7 | K6: 6 | O6: 70 | P6: 21 | Q6: 6 | R6: 13 | S6: 13 | T6: 7 | U6: 10 | V6: 6 | W6: 135 | X6: * | Y6: 11 | Z6: 19 | AA6: 38 | AB6: 30 | AC6: 39
A7: March | G7: 3 | H7: 26 | I7: 12 | J7: 8 | K7: 24 | O7: 58 | P7: 16 | Q7: 19 | R7: 5 | S7: 7 | T7: 21 | U7: 35 | V7: 5 | W7: 116 | X7: * | Y7: 2 | Z7: 2 | AA7: 77 | AB7: 14 | AC7: 17
A8: April | G8: 56 | H8: 36 | I8: 85 | J8: 45 | K8: 72 | O8: 163 | P8: 22 | Q8: 64 | R8: 32 | S8: 24 | T8: 52 | U8: 74 | V8: 63 | W8: 66 | X8: * | Y8: 69 | Z8: 2 | AA8: 135 | AB8: 103 | AC8: 50
A9: May | G9: 208 | H9: 193 | I9: 304 | J9: 341 | K9: 258 | O9: 298 | P9: 267 | Q9: 180 | R9: 150 | S9: 242 | T9: 224 | U9: 216 | V9: 248 | W9: 238 | X9: * | Y9: 341 | Z9: 405 | AA9: 291 | AB9: 245 | AC9: 179
A10: June | G10: 235 | H10: 415 | I10: 233 | J10: 303 | K10: 198 | O10: 568 | P10: 352 | Q10: 189 | R10: 307 | S10: 492 | T10: 240 | U10: 328 | V10: 313 | W10: 366 | X10: 2 | Y10: 337 | Z10: 411 | AA10: 554 | AB10: 371 | AC10: 376
A11: July | G11: 250 | H11: 768 | I11: 195 | J11: 222 | K11: 617 | O11: 742 | P11: 874 | Q11: 335 | R11: 266 | S11: 541 | T11: 784 | U11: 681 | V11: 638 | W11: 479 | X11: 413 | Y11: 513 | Z11: 571 | AA11: 648 | AB11: 471 | AC11: 357
A12: August | G12: 380 | H12: 866 | J12: 240 | K12: 444 | O12: 954 | P12: 1096 | Q12: 555 | R12: 621 | S12: 751 | T12: 479 | U12: 661 | V12: 467 | W12: 514 | X12: 619 | Y12: 480 | Z12: 857 | AA12: 625 | AB12: 705 | AC12: 336
A13: September | H13: 427 | J13: 262 | K13: 210 | O13: 160 | P13: 344 | Q13: 220 | R13: 337 | S13: 185 | T13: 373 | U13: 371 | V13: 98 | W13: 2 | X13: 376 | Y13: 417 | Z13: 433 | AA13: 474 | AB13: 349 | AC13: 234
A14: October | H14: 600 | I14: 473 | J14: 318 | K14: 416 | O14: 641 | P14: 231 | Q14: 173 | R14: 187 | S14: 227 | T14: 305 | U14: 241 | V14: 275 | W14: * | X14: 372 | Y14: 182 | Z14: 444 | AA14: 419 | AB14: 442 | AC14: 276 | AD14: 21
A15: November | H15: 8 | I15: 82 | J15: 73 | K15: 40 | O15: 58 | P15: 42 | Q15: 36 | R15: 47 | S15: 47 | T15: 83 | U15: 40 | V15: 57 | W15: * | X15: * | Y15: 14 | Z15: 89 | AA15: 85 | AB15: 83 | AC15: 38
A16: December | I16: 18 | J16: 30 | K16: 6 | O16: 24 | P16: 1 | Q16: 26 | R16: 21 | S16: 6 | T16: 9 | U16: 10 | V16: 35 | W16: * | X16: * | Y16: 16 | Z16: 49 | AA16: 18 | AB16: 18 | AC16: 26 | AE16: *Registers missing
A18: Yearly Totals | B18: =SUM(B5:B16) -> 0 | C18: =SUM(C5:C16) -> 0 | D18: =SUM(D5:D16) -> 0 | E18: 1083 | F18: 1433 | G18: =SUM(G5:G17) -> 1132 | H18: =SUM(H5:H17) -> 3351 | I18: =SUM(I5:I17) -> 1443 | J18: =SUM(J5:J17) -> 1849 | K18: =SUM(K5:K17) -> 2303 | L18: 2381 | M18: 1356 | N18: 2305 | O18: =SUM(O5:O16) -> 3773 | P18: =SUM(P5:P17) -> 3269 | Q18: =SUM(Q5:Q17) -> 1808 | R18: =SUM(R5:R17) -> 1998 | S18: =SUM(S5:S16) -> 2541 | T18: =SUM(T5:T16) -> 2590 | U18: =SUM(U5:U16) -> 2675 | V18: =SUM(V5:V16) -> 2210 | W18: =SUM(W5:W16) -> 2032 | X18: =SUM(X5:X16) -> 1782 | Y18: =SUM(Y5:Y16) -> 2405 | Z18: =SUM(Z5:Z16) -> 3307 | ... AC18: =SUM(AC5:AC16) -> 1948 | AD18: 21
H19: 3555 | I19: 1775 | J19: 2104

Sheet Campbell Mt
A1: Delaware Wild Forest
A2: Campbell Mt | W2: R??
B3: 1991 | C3: 1992 | D3: 1993 | E3: 1994 | F3: 1995 | G3: 1996 | H3: 1997 | I3: 1998 | J3: 1999 | K3: 2000 | L3: 2001 | M3: 2002 | N3: 2003 | O3: 2004 | P3: 2005 | Q3: 2006 | R3: 2007 | S3: 2008 | T3: 2009 | U3: 2010 | V3: 2011 | W3: 2012 | X3: 2013 | Y3: 2014 | Z3: 2015 | AA3: 2016 | AB3: 2017 | AC3: 2018 | AD3: 2019 | AE3: 2020 | AF3: 2021 | AG3: 2022 | AH3: 2023 | AI3: 2024 | AJ3: 2025
A5: January | AC5: * | AD5: 1 | AE5: 0 | AF5: 1 | AG5: 2 | AH5: 0 | AI5: 3 | AJ5: 7
A6: February | AC6: * | AD6: 4 | AE6: 5 | AF6: 0 | AG6: 1 | AH6: 2 | AI6: 1 | AJ6: 5
A7: March | AC7: * | AD7: 1 | AE7: 5 | AF7: 5 | AG7: 2 | AH7: 0 | AI7: 1 | AJ7: 2
A8: April | AC8: * | AD8: 4 | AE8: 1 | AF8: 6 | AG8: 4 | AH8: 7 | AI8: 7 | AJ8: 12
A9: May | AC9: * | AD9: 7 | AE9: 16 | AF9: 6 | AG9: 2 | AH9: 7 | AI9: 2 | AJ9: 1
A10: June | AC10: * | AD10: 9 | AE10: 8 | AF10: 13 | AG10: 3 | AH10: 2 | AI10: 10 | AJ10: 12
A11: July | AC11: * | AD11: 11 | AE11: 4 | AF11: 6 | AG11: 9 | AH11: 4 | AI11: 7 | AJ11: 4
A12: August | AC12: * | AD12: 3 | AE12: 9 | AF12: 5 | AG12: 14 | AH12: 7 | AI12: 1 | AJ12: 7
A13: September | AC13: 11 | AD13: 22 | AE13: 9 | AF13: 5 | AG13: 12 | AH13: 12 | AI13: 16 | AJ13: 1
A14: October | AC14: 4 | AD14: 5 | AE14: 9 | AF14: 19 | AG14: 2 | AH14: 4 | AI14: 1* | AJ14: 6
A15: November | AC15: 4 | AD15: 5 | AE15: 6 | AF15: 3 | AG15: 20 | AH15: 6 | AI15: 17 | AJ15: 1
A16: December | AC16: 2 | AD16: 0 | AE16: 1 | AF16: 6 | AG16: 9 | AH16: 8 | AI16: 2 | AJ16: 2 | AK16: *Registers missing
A18: Yearly Totals | B18: =SUM(B5:B16) -> 0 | C18: =SUM(C5:C16) -> 0 | D18: =SUM(D5:D16) -> 0 | E18: =SUM(E5:E16) -> 0 | F18: =SUM(F5:F16) -> 0 | G18: =SUM(G5:G16) -> 0 | H18: =SUM(H5:H16) -> 0 | I18: =SUM(I5:I16) -> 0 | ... AJ18: =SUM(AJ5:AJ16) -> 60

Sheet Campbell Brook
A1: Delaware Wild Forest
A2: Campbell Brook | W2: R63
B3: 1991 | C3: 1992 | D3: 1993 | E3: 1994 | F3: 1995 | G3: 1996 | H3: 1997 | I3: 1998 | J3: 1999 | K3: 2000 | L3: 2001 | M3: 2002 | N3: 2003 | O3: 2004 | P3: 2005 | Q3: 2006 | R3: 2007 | S3: 2008 | T3: 2009 | U3: 2010 | V3: 2011 | W3: 2012 | X3: 2013 | Y3: 2014 | Z3: 2015 | AA3: 2016 | AB3: 2017 | AC3: 2018 | AD3: 2019 | AE3: 2020 | AF3: 2021 | AG3: 2022 | AH3: 2023 | AI3: 2024 | AJ3: 2025
A5: January | O5: 7 | P5: 5 | Q5: 5 | T5: 17 | U5: 14 | V5: 22 | W5: 3 | X5: * | Y5: 5 | Z5: 6 | AA5: 5 | AB5: 10 | AC5: 3 | AD5: 1 | AE5: 5 | AF5: 16 | AG5: 2 | AH5: 1 | AI5: 4 | AJ5: 14
A6: February | O6: 5 | P6: 34 | Q6: 26 | T6: 80 | U6: 70 | V6: 107 | W6: 1 | X6: * | Y6: 52 | Z6: 70 | AA6: 6 | AB6: 10 | AC6: 6 | AD6: 4 | AE6: 1 | AF6: 10 | AG6: 5 | AH6: 7 | AI6: 4 | AJ6: 3
A7: March | O7: 5 | P7: 24 | Q7: 6 | T7: 6 | U7: 43 | V7: 1 | W7: 4 | X7: * | Y7: 20 | Z7: 27 | AA7: 4 | AB7: 2 | AC7: 13 | AD7: 22 | AE7: 4 | AF7: 15 | AG7: 2 | AH7: * | AI7: 1 | AJ7: 11
A8: April | O8: 12 | P8: 6 | Q8: 17 | T8: 4 | U8: 14 | V8: 11 | W8: 3 | X8: 11 | Y8: 6 | Z8: 1 | AA8: 7 | AB8: 1 | AC8: 2 | AD8: 4 | AE8: 12 | AF8: 8 | AG8: 32 | AH8: 4 | AI8: 5 | AJ8: 12
A9: May | O9: 18 | P9: 18 | Q9: 17 | T9: 20 | U9: 17 | V9: 7 | W9: 18 | X9: 5 | Y9: 5 | Z9: 16 | AA9: 7 | AB9: 7 | AC9: 11 | AD9: 8 | AE9: 20 | AF9: 14 | AG9: 22 | AH9: 15 | AI9: 7 | AJ9: 13
A10: June | O10: 13 | P10: 29 | Q10: 17 | T10: 10 | U10: 8 | V10: 23 | W10: 27 | X10: 10 | Y10: 8 | Z10: 3 | AA10: 10 | AB10: 25 | AC10: 12 | AD10: 7 | AE10: 29 | AF10: 9 | AG10: 22 | AH10: 6 | AI10: 10 | AJ10: 37
A11: July | O11: 13 | P11: 12 | Q11: 26 | T11: 34 | U11: 19 | V11: 13 | W11: 31 | X11: 46 | Y11: 9 | Z11: 7 | AA11: 19 | AB11: 10 | AC11: 21 | AD11: 30 | AE11: 41 | AF11: 19 | AG11: 13 | AH11: 12 | AI11: 4 | AJ11: 22
A12: August | O12: 30 | P12: 31 | Q12: 26 | T12: 66 | U12: 25 | V12: 27 | W12: 21 | X12: 14 | Y12: 13 | Z12: 24 | AA12: 11 | AB12: 22 | AC12: 64 | AD12: 17 | AE12: 48 | AF12: 19 | AG12: 46 | AH12: 12 | AI12: 9 | AJ12: 31
A13: September | O13: 9 | P13: 12 | Q13: 39 | T13: 31 | U13: 35 | V13: 5 | W13: 14 | X13: 2 | Y13: 12 | Z13: 4 | AA13: 5 | AB13: 11 | AC13: 8 | AD13: 29 | AE13: 19 | AF13: 16 | AG13: 34 | AH13: 15 | AI13: 29 | AJ13: 7
A14: October | O14: 20 | P14: 15 | Q14: 12 | T14: 10 | U14: 9 | V14: 5 | W14: * | X14: 5 | Y14: 7 | Z14: 14 | AA14: 32 | AB14: 13 | AC14: 4 | AD14: 22 | AE14: 23 | AF14: 19 | AG14: 25 | AH14: 9 | AI14: 9 | AJ14: 16
A15: November | O15: 12 | P15: 8 | Q15: 15 | T15: 19 | U15: 5 | V15: 5 | W15: * | X15: 4 | Y15: 8 | Z15: 2 | AA15: 10 | AB15: 3 | AC15: 4 | AD15: 4 | AE15: 9 | AF15: 4 | AG15: 26 | AH15: 8 | AI15: 23 | AJ15: 19
A16: December | O16: 3 | P16: 4 | Q16: 13 | S16: 2 | T16: 13 | U16: 1 | V16: 9 | W16: * | X16: 2 | Y16: 7 | Z16: 2 | AA16: 0 | AB16: * | AC16: 2 | AD16: 2 | AE16: 0 | AF16: 17 | AG16: 14 | AH16: 1 | AI16: 2 | AJ16: 1 | AK16: *Registers missing
A18: Yearly Totals | B18: =SUM(B5:B16) -> 0 | C18: =SUM(C5:C16) -> 0 | D18: =SUM(D5:D16) -> 0 | E18: =SUM(E5:E16) -> 0 | F18: =SUM(F5:F16) -> 0 | G18: =SUM(G5:G16) -> 0 | H18: =SUM(H5:H16) -> 0 | I18: =SUM(I5:I16) -> 0 | ... L18: =SUM(L5:L16) -> 0 | M18: 103 | N18: 120 | O18: =SUM(O5:O17) -> 147 | P18: =(SUM(P5:P16)) -> 198 | Q18: =(SUM(Q5:Q16)) -> 219 | R18: 175 | S18: 59 | T18: =SUM(T5:T16) -> 310 | U18: =SUM(U5:U16) -> 260 | V18: =SUM(V5:V16) -> 235 | W18: =SUM(W5:W16) -> 122 | X18: =SUM(X5:X16) -> 99 | Y18: =SUM(Y5:Y16) -> 152 | Z18: =SUM(Z5:Z16) -> 176 | AA18: =SUM(AA5:AA16) -> 116 | AB18: =SUM(AB5:AB16) -> 114 | AC18: =SUM(AC5:AC17) -> 150 | AD18: =SUM(AD5:AD17) -> 150 | AE18: =SUM(AE5:AE17) -> 211 | AF18: =SUM(AF5:AF17) -> 166 | AG18: =SUM(AG5:AG17) -> 243 | AH18: =SUM(AH4:AH17) -> 90 | AI18: =SUM(AI4:AI17) -> 107 | AJ18: =SUM(AJ4:AJ17) -> 186

Sheet Catskill Mt. House
A1: North South Lake Campground
A2: Catskill Mt. House
B3: 1991 | C3: 1992 | D3: 1993 | E3: 1994 | F3: 1995 | G3: 1996 | H3: 1997 | I3: 1998 | J3: 1999 | K3: 2000 | L3: 2001 | M3: 2002 | N3: 2003 | O3: 2004 | P3: 2005 | Q3: 2006 | R3: 2007 | S3: 2008 | T3: 2009 | U3: 2010 | V3: 2011 | W3: 2012 | X3: 2013 | Y3: 2014 | Z3: 2015 | AA3: 2016 | AB3: 2017 | AC3: 2018 | AD3: 2019 | AE3: 2020 | AF3: 2021 | AG3: 2022 | AH3: 2023 | AI3: 2024 | AJ3: 2025
A5: January | Y5: 23 | Z5: 25 | AA5: 24 | AB5: 18 | AC5: 20 | AD5: 7 | AE5: 25 | AF5: 29 | AG5: 0 | AH5: 21 | AI5: 22 | AJ5: 5
A6: February | Y6: 11 | Z6: 19 | AA6: 38 | AB6: 30 | AC6: 39 | AD6: 22 | AE6: 42 | AF6: 13 | AG6: 15 | AH6: 19 | AI6: 18 | AJ6: 7
A7: March | Y7: 2 | Z7: 2 | AA7: 77 | AB7: 14 | AC7: 17 | AD7: 20 | AE7: 45 | AF7: 61 | AG7: 36 | AH7: 7 | AI7: 31 | AJ7: 18
A8: April | Y8: 69 | Z8: 2 | AA8: 135 | AB8: 103 | AC8: 50 | AD8: 71 | AE8: 38 | AF8: 83 | AG8: 69 | AH8: 53 | AI8: 44 | AJ8: 66
A9: May | Y9: 341 | Z9: 458 | AA9: 291 | AB9: 245 | AC9: 179 | AD9: 183 | AE9: 114 | AF9: 125 | AG9: 145 | AH9: 176 | AI9: 140 | AJ9: 160
A10: June | Y10: 337 | Z10: 84 | AA10: 554 | AB10: 371 | AC10: 376 | AD10: 326 | AE10: 97 | AF10: 250 | AG10: 354 | AH10: 180 | AI10: 237 | AJ10: 239
A11: July | Y11: 513 | Z11: 320 | AA11: 648 | AB11: 471 | AC11: 357 | AD11: 342 | AE11: 288 | AF11: 444 | AG11: 134 | AH11: 290 | AI11: 360 | AJ11: 407
A12: August | Y12: 480 | Z12: 970 | AA12: 625 | AB12: 705 | AC12: 336 | AD12: 395 | AE12: 268 | AF12: 181 | AG12: 235 | AH12: 221 | AI12: 238 | AJ12: 346
A13: September | Y13: 417 | Z13: 301 | AA13: 474 | AB13: 349 | AC13: 234 | AD13: 268 | AE13: 202 | AF13: 206 | AG13: 217 | AH13: 185 | AI13: 186 | AJ13: 302
A14: October | Y14: 182 | Z14: 515 | AA14: 419 | AB14: 442 | AC14: 276 | AD14: 6 | AE14: 338 | AF14: 68 | AG14: 260 | AH14: 243 | AI14: 124 | AJ14: 58
A15: November | Y15: 14 | Z15: 89 | AA15: 85 | AB15: 83 | AC15: 38 | AD15: 68 | AE15: 92 | AF15: 67 | AG15: 56 | AH15: 56 | AI15: 68 | AJ15: 52
A16: December | Y16: 16 | Z16: 49 | AA16: 18 | AB16: 18 | AC16: 26 | AD16: 38 | AE16: 43 | AF16: 35 | AG16: 16 | AH16: 26 | AI16: 29 | AJ16: 13
AK17: *Registers missing
A18: Yearly Totals | B18: =SUM(B5:B16) -> 0 | C18: =SUM(C5:C16) -> 0 | D18: =SUM(D5:D16) -> 0 | E18: =SUM(E5:E16) -> 0 | F18: =SUM(F5:F16) -> 0 | G18: =SUM(G5:G16) -> 0 | H18: =SUM(H5:H16) -> 0 | I18: =SUM(I5:I16) -> 0 | ... AC18: =SUM(AC5:AC16) -> 1948 | AD18: =SUM(AD4:AD17) -> 1746 | AE18: =SUM(AE4:AE17) -> 1592 | AF18: =SUM(AF4:AF17) -> 1562 | AG18: =SUM(AG5:AG17) -> 1537 | AH18: =SUM(AH5:AH17) -> 1477 | AI18: =SUM(AI5:AI17) -> 1497 | AJ18: =SUM(AJ5:AJ17) -> 1673

Sheet Colgate Lake (Dutcher Notch)
A1: Colgate Lake Wild Forest
A2: Colgate Lake (Dutcher Notch) | Y2: R23
B3: 1990 | C3: 1991 | D3: 1992 | E3: 1993 | F3: 1994 | G3: 1995 | H3: 1996 | I3: 1997 | J3: 1998 | K3: 1999 | L3: 2000 | M3: 2001 | N3: 2002 | O3: 2003 | P3: 2004 | Q3: 2005 | R3: 2006 | S3: 2007 | T3: 2008 | U3: 2009 | V3: 2010 | W3: 2011 | X3: 2012 | Y3: 2013 | Z3: 2014 | AA3: 2015 | AB3: 2016 | AC3: 2017 | AD3: 2018 | AE3: 2019 | AF3: 2020 | AG3: 2021 | AH3: 2022 | AI3: 2023 | AJ3: 2024 | AK3: 2025
A5: January | H5: 14 | I5: 39 | J5: 46 | K5: 30 | L5: 36 | P5: 48 | Q5: 41 | R5: 28 | S5: 41 | T5: 34 | U5: 34 | V5: 24 | W5: 40 | X5: 19 | Y5: * | Z5: 1 | AA5: 18 | AB5: 22 | AC5: 10 | AD5: 16 | AE5: 9 | AF5: 34 | AG5: 54 | AH5: 34 | AI5: 19 | AJ5: 19
A6: February | H6: 48 | I6: 24 | J6: 79 | K6: 19 | L6: 59 | P6: 36 | Q6: 33 | R6: 14 | S6: 44 | T6: 26 | U6: 32 | V6: 27 | W6: 40 | X6: 35 | Y6: * | Z6: 23 | AA6: 15 | AB6: 41 | AC6: 0 | AD6: 30 | AE6: 31 | AF6: 35 | AG6: 29 | AH6: 26 | AI6: 37 | AJ6: 21
A7: March | H7: 24 | I7: 17 | J7: 37 | K7: 35 | L7: 27 | P7: 38 | Q7: 56 | R7: 29 | S7: 37 | T7: 18 | U7: 23 | V7: 6 | W7: 11 | X7: 38 | Y7: * | Z7: 15 | AA7: 2 | AB7: 45 | AC7: 3 | AD7: 26 | AE7: 13 | AF7: 46 | AG7: 22 | AH7: 10 | AI7: 30 | AJ7: 22
A8: April | H8: 28 | I8: 37 | J8: 47 | K8: 76 | L8: 40 | P8: 78 | Q8: 27 | R8: 39 | S8: 41 | T8: 45 | U8: 34 | V8: 43 | W8: 43 | X8: 46 | Y8: 42 | Z8: 40 | AA8: * | AB8: 34 | AC8: 64 | AD8: 41 | AE8: 55 | AF8: * | AG8: 71 | AH8: 49 | AI8: 19 | AJ8: 33
A9: May | H9: 74 | I9: 64 | J9: 147 | K9: 128 | L9: 54 | P9: 113 | Q9: 42 | R9: 175 | S9: 69 | T9: 112 | U9: 87 | V9: 73 | W9: 91 | X9: 57 | Y9: 65 | Z9: 82 | AA9: 82 | AB9: 82 | AC9: 56 | AD9: 78 | AE9: 60 | AF9: * | AG9: 85 | AH9: 44 | AI9: 48 | AJ9: 102
A10: June | H10: 193 | I10: 82 | J10: 89 | K10: 63 | L10: 61 | P10: 113 | Q10: 65 | R10: 29 | S10: 14 | T10: 66 | U10: 96 | V10: 79 | W10: 90 | X10: 107 | Y10: 55 | Z10: 75 | AA10: 62 | AB10: 122 | AC10: 110 | AD10: 96 | AE10: 66 | AF10: * | AG10: 77 | AH10: 54 | AI10: 59 | AJ10: 63
A11: July | H11: 158 | I11: 173 | J11: 167 | K11: 118 | L11: 113 | P11: 119 | Q11: 201 | R11: 105 | T11: 112 | U11: 110 | V11: 207 | W11: 136 | X11: 101 | Y11: 89 | Z11: 144 | AA11: 157 | AB11: 145 | AC11: 153 | AD11: 92 | AE11: 124 | AF11: * | AG11: 116 | AH11: 144 | AI11: 65 | AJ11: 112
A12: August | H12: 100 | I12: 210 | J12: 181 | K12: 164 | L12: 145 | P12: 147 | Q12: 110 | R12: 104 | T12: 109 | U12: 98 | V12: 169 | W12: 89 | X12: 39 | Y12: 185 | Z12: 142 | AA12: 229 | AB12: 176 | AC12: 168 | AD12: 98 | AE12: 130 | AF12: 125 | AG12: 90 | AH12: 140 | AI12: 120 | AJ12: 79
A13: September | I13: 69 | J13: 175 | K13: 114 | L13: 110 | P13: 100 | Q13: 153 | R13: 96 | T13: 39 | U13: 106 | V13: 117 | W13: 36 | X13: * | Y13: 61 | Z13: 74 | AA13: 108 | AB13: 143 | AC13: 106 | AD13: 106 | AE13: 64 | AF13: 135 | AG13: 98 | AH13: 89 | AI13: 97 | AJ13: 118
A14: October | I14: 135 | J14: 118 | K14: 98 | L14: 94 | P14: 116 | Q14: 66 | R14: 35 | T14: 69 | U14: 58 | V14: 106 | W14: 67 | X14: * | Y14: 73 | Z14: 66 | AA14: 89 | AB14: 84 | AC14: 160 | AD14: 105 | AE14: 69 | AF14: 160 | AG14: 106 | AH14: 73 | AI14: 60 | AJ14: 67
A15: November | I15: 23 | J15: 68 | K15: 58 | L15: 50 | P15: 21 | Q15: 70 | R15: 58 | T15: 34 | U15: 86 | V15: 28 | W15: 28 | X15: * | Y15: 41 | Z15: 23 | AA15: 58 | AB15: 36 | AC15: 3 | AD15: 29 | AE15: 29 | AF15: 58 | AG15: 27 | AH15: 42 | AI15: 41 | AJ15: 61
A16: December | I16: 23 | J16: 23 | K16: 24 | L16: 30 | Q16: 33 | R16: 34 | T16: 23 | U16: 12 | V16: 27 | W16: 25 | X16: * | Y16: 13 | Z16: 38 | AA16: 46 | AB16: 26 | AC16: 26 | AD16: 23 | AE16: 30 | AF16: 33 | AG16: 27 | AH16: 15 | AI16: 18 | AJ16: 12 | AL16: *Registers missing
A18: Yearly Totals | B18: 570 | C18: 620 | D18: 683 | E18: 721 | F18: 646 | G18: 592 | H18: =SUM(H5:H17) -> 639 | I18: =SUM(I5:I17) -> 896 | J18: =SUM(J5:J17) -> 1177 | K18: =SUM(K5:K17) -> 927 | L18: =SUM(L5:L17) -> 819 | M18: 776 | N18: 911 | O18: 724 | P18: 967 | Q18: =SUM(Q5:Q16) -> 897 | R18: =SUM(R5:R16) -> 746 | S18: =SUM(S5:S16) -> 246 | T18: =SUM(T5:T16) -> 687 | U18: =SUM(U5:U16) -> 776 | V18: =SUM(V5:V16) -> 906 | W18: =SUM(W5:W17) -> 696 | X18: =SUM(X5:X16) -> 442 | Y18: =SUM(Y5:Y16) -> 624 | Z18: =SUM(Z5:Z16) -> 723 | AA18: =SUM(AA5:AA16) -> 866 | AB18: =SUM(AB5:AB16) -> 956 | AC18: =SUM(AC5:AC16) -> 859 | AD18: =SUM(AD5:AD16) -> 740 | AE18: =SUM(AE5:AE17) -> 680 | AF18: =SUM(AF5:AF17) -> 626 | AG18: =SUM(AG5:AG17) -> 802 | AH18: =SUM(AH5:AH17) -> 720 | AI18: =SUM(AI5:AI17) -> 613 | AJ18: =SUM(AJ5:AJ17) -> 709 | AK18: =SUM(AK5:AK17) -> 0

Sheet Colonel's Chair
A1: Rusk Mountain Wild Forest
A2: Colonel's Chair | W2: R11
B3: 1990 | C3: 1991 | D3: 1992 | E3: 1993 | F3: 1994 | G3: 1995 | H3: 1996 | I3: 1997 | J3: 1998 | K3: 1999 | L3: 2000 | M3: 2001 | N3: 2002 | O3: 2003 | P3: 2004 | Q3: 2005 | R3: 2006 | S3: 2007 | T3: 2008 | U3: 2009 | V3: 2010 | W3: 2011 | X3: 2012 | Y3: 2013 | Z3: 2014 | AA3: 2015 | AB3: 2016 | AC3: 2017 | AD3: 2018 | AE3: 2019 | AF3: 2020 | AG3: 2021 | AH3: 2022 | AI3: 2023 | AJ3: 2024 | AK3: 2025
A5: January | I5: 1 | J5: 10 | K5: 7 | L5: 13 | P5: 12 | R5: 14 | S5: 1 | T5: 17 | U5: 7 | V5: * | W5: 6 | X5: 5 | Y5: 2 | Z5: 0 | AA5: 0 | AB5: 9 | AC5: 18 | AD5: 9 | AE5: 5 | AF5: * | AG5: 6 | AH5: * | AI5: 6
A6: February | I6: 51 | J6: 10 | K6: 17 | L6: 50 | P6: 24 | R6: 5 | S6: 12 | T6: 22 | U6: 0 | V6: 14 | W6: 8 | X6: 6 | Y6: 0 | Z6: 25 | AA6: 14 | AB6: 1 | AC6: 15 | AD6: 3 | AE6: 7 | AF6: * | AG6: 16 | AH6: 1 | AI6: 5
A7: March | I7: 3 | J7: 1 | K7: 11 | L7: 2 | P7: 9 | Q7: 10 | S7: 12 | T7: 7 | U7: 8 | V7: 35 | W7: 16 | X7: 6 | Y7: 7 | Z7: 7 | AA7: 3 | AB7: 14 | AC7: 11 | AD7: 14 | AE7: 11 | AF7: * | AG7: 5 | AH7: 12 | AI7: 1
A8: April | J8: 16 | K8: 8 | L8: 9 | P8: 3 | R8: 10 | S8: 2 | T8: 9 | U8: 7 | V8: 5 | W8: 3 | X8: 4 | Y8: 4 | Z8: 1 | AA8: 0 | AB8: 9 | AC8: 9 | AD8: 5 | AE8: 5 | AF8: * | AG8: 5 | AH8: 9 | AI8: 9
A9: May | J9: 32 | K9: 5 | L9: 2 | P9: 6 | S9: 14 | T9: 69 | U9: 19 | V9: 0 | W9: 43 | X9: 52 | Y9: 29 | Z9: 41 | AA9: 67 | AB9: 76 | AC9: 68 | AD9: 60 | AE9: 56 | AF9: * | AG9: 7 | AH9: 4 | AI9: 6
A10: June | J10: 40 | K10: 7 | L10: 36 | Q10: 4 | R10: 6 | S10: 10 | T10: 3 | U10: 25 | V10: 5 | W10: 40 | X10: 70 | Y10: 21 | Z10: 52 | AA10: 22 | AB10: 56 | AC10: 65 | AD10: 176 | AE10: 50 | AF10: * | AG10: 20 | AH10: 13 | AI10: 4
A11: July | I11: 15 | J11: 21 | K11: 0 | L11: 26 | Q11: 44 | R11: 113 | S11: 70 | T11: 115 | U11: 83 | V11: 24 | W11: 180 | X11: 125 | Y11: 190 | Z11: 190 | AA11: 163 | AB11: 286 | AC11: 280 | AD11: 459 | AE11: 107 | AF11: * | AG11: 82 | AH11: 163 | AI11: 50
A12: August | H12: 46 | I12: 58 | J12: 77 | K12: 36 | L12: 43 | Q12: 130 | R12: 125 | S12: 158 | T12: 111 | U12: 69 | V12: 22 | W12: 141 | X12: 180 | Y12: 121 | Z12: 303 | AA12: 156 | AB12: 337 | AC12: 389 | AD12: 155 | AE12: 428 | AF12: * | AG12: 166 | AH12: 136 | AI12: *
A13: September | I13: 50 | J13: 48 | K13: 40 | L13: 29 | Q13: 99 | R13: 68 | S13: 226 | T13: 58 | U13: 85 | V13: 22 | W13: 42 | X13: 68 | Y13: 58 | Z13: 56 | AA13: 97 | AB13: 155 | AC13: 84 | AD13: 144 | AE13: 183 | AF13: * | AG13: 115 | AH13: 94 | AI13: *
A14: October | I14: 90 | J14: 64 | K14: 3 | L14: 130 | Q14: 24 | R14: 111 | S14: 35 | T14: 157 | U14: 56 | V14: 25 | W14: 140 | X14: 97 | Y14: 164 | Z14: 125 | AA14: 233 | AB14: 124 | AC14: 176 | AD14: 80 | AE14: 274 | AF14: * | AG14: 107 | AH14: 124 | AI14: *
A15: November | I15: 3 | J15: 3 | K15: * | L15: 12 | Q15: 38 | S15: 2 | T15: 4 | U15: * | V15: 11 | W15: 0 | X15: 3 | Y15: 8 | Z15: 0 | AA15: 14 | AB15: 1 | AC15: 12 | AD15: 3 | AE15: 1 | AF15: 6 | AG15: 5 | AH15: 11 | AI15: *
A16: December | I16: 0 | J16: 4 | K16: * | L16: 1 | Q16: 10 | R16: =+Spruceton!R548 -> 0 | S16: 4 | T16: 5 | U16: * | V16: 6 | W16: 1 | X16: 1 | Y16: 0 | Z16: 3 | AA16: 9 | AB16: 4 | AC16: 2 | AD16: 4 | AE16: 6 | AF16: 7 | AG16: 4 | AH16: * | AI16: * | AL16: *Registers missing
A18: Yearly Totals | B18: 623 | C18: 600 | D18: 620 | E18: 600 | F18: 397 | G18: 65 | H18: =SUM(H5:H16) -> 46 | I18: =SUM(I5:I17) -> 271 | J18: =SUM(J5:J17) -> 326 | K18: =SUM(K5:K17) -> 134 | L18: =SUM(L5:L17) -> 353 | M18: 590 | N18: 583 | O18: 516 | P18: =SUM(P5:P17) -> 54 | Q18: =SUM(Q5:Q16) -> 359 | R18: =SUM(R5:R16) -> 452 | S18: =SUM(S5:S16) -> 546 | T18: =SUM(T5:T17) -> 577 | U18: =SUM(U5:U16) -> 359 | V18: =SUM(V5:V16) -> 169 | W18: =SUM(W5:W16) -> 620 | X18: =SUM(X5:X16) -> 617 | Y18: =SUM(Y5:Y16) -> 604 | Z18: =SUM(Z5:Z16) -> 803 | AA18: =SUM(AA5:AA16) -> 778 | AB18: =SUM(AB5:AB16) -> 1072 | ... AD18: =SUM(AD5:AD16) -> 1112 | AE18: =SUM(AE5:AE17) -> 1133 | AF18: =SUM(AF5:AF17) -> 13 | AG18: =SUM(AG5:AG17) -> 538 | AH18: =SUM(AH5:AH17) -> 567 | AI18: 81 | AJ18: =SUM(AJ5:AJ17) -> 0 | AK18: =SUM(AK5:AK17) -> 0
I19: 387 | K19: 152
AE27: no data until 1989

Sheet Devils Tombstone (Hunter Mtn)
A1: Hunter-Westkill Mountain Wilderness
A2: Devils Tombstone (Hunter Mtn) | Z2: R04
B3: 1990 | C3: 1991 | D3: 1992 | E3: 1993 | F3: 1994 | G3: 1995 | H3: 1996 | I3: 1997 | J3: 1998 | K3: 1999 | L3: 2000 | M3: 2001 | N3: 2002 | O3: 2003 | P3: 2004 | Q3: 2005 | R3: 2006 | S3: 2007 | T3: 2008 | U3: 2009 | V3: 2010 | W3: 2011 | X3: 2012 | Y3: 2013 | Z3: 2014 | AA3: 2015 | AB3: 2016 | AC3: 2017 | AD3: 2018 | AE3: 2019 | AF3: 2020 | AG3: 2021 | AH3: 2022 | AI3: 2023 | AJ3: 2024 | AK3: 2025
A5: January | H5: 14 | I5: 73 | J5: 75 | K5: 29 | L5: 50 | P5: 9 | Q5: 20 | R5: 25 | S5: 36 | T5: 31 | U5: * | V5: 56 | W5: 13 | X5: 76 | Y5: * | Z5: 25 | AA5: 25 | AB5: 66 | AC5: 20 | AD5: * | AE5: 22 | AF5: 37 | AG5: 54 | AH5: 27 | AI5: 18 | AJ5: 20
A6: February | H6: 12 | I6: 44 | J6: 51 | K6: 24 | L6: 36 | P6: 67 | Q6: 82 | R6: 31 | S6: 26 | T6: 41 | U6: 1 | V6: 26 | W6: 5 | X6: 61 | Y6: * | Z6: 13 | AA6: 16 | AB6: 54 | AC6: 32 | AD6: * | AE6: 23 | AF6: 32 | AG6: 30 | AH6: 32 | AI6: 32 | AJ6: 71
A7: March | H7: 23 | I7: 42 | J7: 37 | K7: 38 | L7: 34 | P7: 17 | Q7: 52 | R7: 77 | S7: 9 | T7: 53 | U7: 37 | V7: 10 | W7: 25 | X7: 73 | Y7: * | Z7: 48 | AA7: 27 | AB7: 74 | AC7: 24 | AD7: * | AE7: 27 | AF7: 54 | AG7: 49 | AH7: 31 | AI7: 15 | AJ7: 25
A8: April | I8: 46 | J8: 60 | K8: 34 | L8: 88 | P8: 48 | Q8: 68 | R8: 95 | S8: 57 | T8: 57 | U8: 53 | V8: 64 | W8: 29 | X8: 187 | Y8: 180 | Z8: 86 | AA8: 53 | AB8: 59 | AC8: 84 | AD8: * | AE8: 51 | AF8: 66 | AG8: 66 | AH8: 79 | AI8: 40 | AJ8: 39
