Workbook

Sheet Alder Lake
A1: Balsam Lake Mountain Wild Forest | BA1: =+BL:AAE:AV -> #NAME?
A2: ALDER LAKE
B3: 1991 | C3: 1992 | D3: 1993 | E3: 1994 | F3: 1995 | G3: 1996 | H3: 1997 | I3: 1998 | J3: 1999 | K3: 2000 | L3: 2001 | M3: 2002 | N3: 2003 | O3: 2004 | P3: 2005 | Q3: 2006 | R3: 2007 | S3: 2008 | T3: 2009 | U3: 2010 | V3: 2011 | W3: 2012 | X3: 2013 | Y3: 2014 | Z3: 2015 | AA3: 2016 | AB3: 2017 | AC3: 2018 | AD3: 2019 | AE3: 2020 | AF3: 2021 | AG3: 2022 | AH3: 2023 | AI3: 2024 | AJ3: 2025 | AK3: 2026 | AL3: 2027 | AM3: 2028 | AN3: 2029 | AO3: 2030 | AP3: 2031 | AQ3: 2032 | AR3: 2033 | AS3: 2034 | AT3: 2035 | AU3: 2036 | AV3: 2037 | AW3: 2038 | AX3: 2039 | AY3: 2040 | AZ3: 2041 | BA3: 10 Year Rolling Averages | BK3: 2001 | BL3: 2002 | BM3: 2003 | BN3: 2004 | BO3: 2005 | BP3: 2006 | BQ3: 2007 | BR3: 2008 | BS3: 2009 | BT3: 2010 | BU3: 2011 | BV3: 2012 | BW3: 2013 | BX3: 2014 | BY3: 2015 | BZ3: 10-YEAR-AVG-2016 | CA3: 10-YEAR-AVG-2017 | CB3: 10-YEAR-AVG-2018 | CC3: 10-YEAR-AVG 2019 | CD3: 10-YEAR-AVG-2020 | CE3: 2021 | CF3: 2022 | CG3: 2023 | CH3: 2024 | CI3: 2025 | CJ3: 2026 | CK3: 2027 | CL3: 2028 | CM3: 2029 | CN3: 2030 | CO3: 2031 | CP3: 2032 | CQ3: 2033 | CR3: 2034 | CS3: 2035 | CT3: 2036 | CU3: 2037 | CV3: 2038 | CW3: 2039 | CX3: 2040 | CY3: 2041 | CZ3: 2042 | DA3: 2043 | DB3: 2044 | DC3: 2045 | DD3: 2046
A5: January | C5: 34 | D5: 19 | E5: 2 | F5: 2 | G5: 5 | H5: 0 | I5: 41 | J5: 14 | K5: 48 | L5: 7 | M5: 0 | N5: 34 | O5: 21 | P5: 25 | Q5: 24 | R5: 46 | U5: 25 | W5: 19 | Y5: 25 | Z5: 24 | AA5: 36 | AB5: 26 | AC5: 26 | AD5: 31 | AE5: 39 | AF5: 90 | AG5: 22 | AH5: =8+32 -> 40 | AI5: =(2+6+1+2+1+1+6)+(2+1+2+2+1+1+2+2+1) -> 33 | BB5: #N/A | BC5: #N/A | BD5: #N/A | BE5: #N/A | BF5: #N/A | BG5: #N/A | BH5: #N/A | BI5: #N/A | BJ5: =AVERAGE(B5:K5) -> 18.333333 | BK5: =AVERAGE(C5:L5) -> 17.2 | BL5: =AVERAGE(D5:M5) -> 13.8 | BM5: =AVERAGE(E5:N5) -> 15.3 | BN5: =AVERAGE(F5:O5) -> 17.2 | BO5: =AVERAGE(G5:P5) -> 19.5 | BP5: =AVERAGE(H5:Q5) -> 21.4 | BQ5: =AVERAGE(I5:R5) -> 26 | ... DD5: =AVERAGE(AV5:BE5) -> #N/A
A6: February | C6: 21 | D6: 21 | E6: 6 | F6: 10 | G6: 10 | H6: 0 | I6: 28 | J6: 10 | K6: 51 | L6: 9 | M6: 21 | N6: 20 | O6: 13 | P6: 24 | Q6: 11 | R6: 23 | U6: 45 | W6: 27 | Y6: 24 | Z6: 12 | AA6: 44 | AB6: 10 | AC6: 10 | AD6: 15 | AE6: 38 | AF6: 36 | AG6: 31 | AH6: =11+48-14 -> 45 | AI6: =(2+2+2+3+5+4+2+1+2+2)+(1+2+5+2+2+1+2+2+1+2+5+2)+(2)+(1) -> 55 | BA6: #N/A | BB6: #N/A | BC6: #N/A | BD6: #N/A | BE6: #N/A | BF6: #N/A | BG6: #N/A | BH6: #N/A | BI6: #N/A | BJ6: =AVERAGE(B6:K6) -> 17.444444 | BK6: =AVERAGE(C6:L6) -> 16.6 | BL6: =AVERAGE(D6:M6) -> 16.6 | BM6: =AVERAGE(E6:N6) -> 16.5 | BN6: =AVERAGE(F6:O6) -> 17.2 | BO6: =AVERAGE(G6:P6) -> 18.6 | BP6: =AVERAGE(H6:Q6) -> 18.7 | BQ6: =AVERAGE(I6:R6) -> 21 | ... DD6: =AVERAGE(AV6:BE6) -> #N/A
A7: March | C7: 12 | D7: 1 | E7: 6 | F7: 29 | G7: 10 | H7: 14 | I7: 38 | J7: 16 | K7: 23 | L7: 9 | M7: 69 | N7: 9 | O7: 24 | P7: 14 | Q7: 20 | R7: 43 | U7: 13 | W7: 87 | Y7: 8 | Z7: 10 | AA7: 47 | AB7: 6 | AC7: 6 | AD7: 59 | AE7: 108 | AF7: 85 | AG7: 42 | AH7: =14+37 -> 51 | AI7: =(4)+(1+2+2+1+1+1+2+1)+(2+2+1+2+4+4+1+2+1+3+9+3+2+2+1+3+1+2)+(2+1) -> 63 | BA7: #N/A | BB7: #N/A | BC7: #N/A | BD7: #N/A | BE7: #N/A | BF7: #N/A | BG7: #N/A | BH7: #N/A | BI7: #N/A | BJ7: =AVERAGE(B7:K7) -> 16.555556 | BK7: =AVERAGE(C7:L7) -> 15.8 | BL7: =AVERAGE(D7:M7) -> 21.5 | BM7: =AVERAGE(E7:N7) -> 22.3 | BN7: =AVERAGE(F7:O7) -> 24.1 | BO7: =AVERAGE(G7:P7) -> 22.6 | BP7: =AVERAGE(H7:Q7) -> 23.6 | BQ7: =AVERAGE(I7:R7) -> 26.5 | ... DD7: =AVERAGE(AV7:BE7) -> #N/A
A8: April | B8: 144 | C8: 50 | D8: 48 | E8: 50 | F8: 90 | G8: 60 | H8: 110 | I8: 148 | J8: 116 | K8: 95 | L8: 59 | M8: 69 | N8: 88 | O8: 73 | P8: 53 | Q8: 137 | R8: 68 | U8: 156 | W8: 110 | Y8: 66 | Z8: 94 | AA8: 113 | AB8: 168 | AC8: 168 | AD8: 34 | AE8: 105 | AF8: 209 | AG8: =49+37 -> 86 | AH8: =10+43+57+24 -> 134 | AI8: =(1+2+2+2+1+2+2+4+4+2+1+1+3+2+1+3+12+4)+(2+7+1+3+8+1+1+5+2+5+2+2+4+4+3+4+3)+(1+2+1+1)+(1+1+2+2+6+2+2) -> 127 | BA8: #N/A | BB8: #N/A | BC8: #N/A | BD8: #N/A | BE8: #N/A | BF8: #N/A | BG8: #N/A | BH8: #N/A | BI8: #N/A | BJ8: =AVERAGE(B8:K8) -> 91.1 | BK8: =AVERAGE(C8:L8) -> 82.6 | BL8: =AVERAGE(D8:M8) -> 84.5 | BM8: =AVERAGE(E8:N8) -> 88.5 | BN8: =AVERAGE(F8:O8) -> 90.8 | BO8: =AVERAGE(G8:P8) -> 87.1 | BP8: =AVERAGE(H8:Q8) -> 94.8 | BQ8: =AVERAGE(I8:R8) -> 90.6 | ... DD8: =AVERAGE(AV8:BE8) -> #N/A
A9: May | B9: 218 | C9: 75 | D9: 174 | E9: 129 | F9: 313 | G9: 94 | H9: 190 | I9: 266 | J9: 208 | K9: 130 | L9: 165 | M9: 238 | N9: 125 | O9: 52 | P9: 119 | Q9: 225 | R9: 172 | U9: 250 | W9: 154 | Y9: 208 | Z9: 183 | AA9: 176 | AB9: 179 | AC9: 179 | AD9: 300 | AE9: 241 | AF9: 246 | AG9: =52+46+56+41+11 -> 206 | AH9: =32+5+(1+1+2+2+9+2+2+1+7+3+2+3+3+2+2+4+1+1+2+4)+(2+2+2+2+7+1+2+9+2+1+2+4+3+4+8+2+1+2+5+4)+(2+2+2+2+1+3+2) -> 170 | AI9: =(2+1+4+1+3+2+2+3+3+1+3+2+8+1+6)+(4+1+2+12+2+5+2+2+5+1+1+2+3+2+2+2+1+2+3+2)+(3+2+2+1+2+2+2+2+2+3+2+3+1+2+10+1+3)+(2+1+1+2) -> 147 | BA9: #N/A | BB9: #N/A | BC9: #N/A | BD9: #N/A | BE9: #N/A | BF9: #N/A | BG9: #N/A | BH9: #N/A | BI9: #N/A | BJ9: =AVERAGE(B9:K9) -> 179.7 | BK9: =AVERAGE(C9:L9) -> 174.4 | BL9: =AVERAGE(D9:M9) -> 190.7 | BM9: =AVERAGE(E9:N9) -> 185.8 | BN9: =AVERAGE(F9:O9) -> 178.1 | BO9: =AVERAGE(G9:P9) -> 158.7 | BP9: =AVERAGE(H9:Q9) -> 171.8 | BQ9: =AVERAGE(I9:R9) -> 170 | ... DD9: =AVERAGE(AV9:BE9) -> #N/A
A10: June | B10: 165 | C10: 75 | D10: 123 | E10: 124 | F10: 101 | G10: 117 | H10: 146 | I10: 182 | J10: 647 | K10: 86 | L10: 211 | M10: 287 | N10: 252 | O10: 224 | P10: 198 | Q10: 197 | R10: 243 | U10: 264 | W10: 238 | Y10: 239 | Z10: 282 | AA10: 332 | AB10: 328 | AC10: 328 | AD10: 282 | AE10: 313 | AF10: 264 | AG10: =27+47+38+77+39 -> 228 | AH10: =(2+2+1+2+3+8+5+4+3+3+1)+(3+1+2+2+2+1+2+13+3+2+2+3+3+5+2+1+2+6)+(2+3+1+2+2+4+4+4+1+2+4+3+5+1+2+9+3+2+6+2)+(4+1+1+3+9+3+2+1+4+2+2)+(8+10+2+2+13+9+6+1) -> 234 | AI10: =(2)+(1)+(1+2+2+2+2+1+1+1+1+3+1+3+2+2+1+3+2+2+1+4)+(2+1+1+8+1+3+2+2+3+2+3+4+1+10+4+2+1+4+2+1)+(1+4+4+3+1+2+7+4+2+4+2+7+4+2+10+2+4+3)+(5) -> 168 | BA10: #N/A | BB10: #N/A | BC10: #N/A | BD10: #N/A | BE10: #N/A | BF10: #N/A | BG10: #N/A | BH10: #N/A | BI10: #N/A | BJ10: =AVERAGE(B10:K10) -> 176.6 | BK10: =AVERAGE(C10:L10) -> 181.2 | BL10: =AVERAGE(D10:M10) -> 202.4 | BM10: =AVERAGE(E10:N10) -> 215.3 | BN10: =AVERAGE(F10:O10) -> 225.3 | BO10: =AVERAGE(G10:P10) -> 235 | BP10: =AVERAGE(H10:Q10) -> 243 | BQ10: =AVERAGE(I10:R10) -> 252.7 | ... DD10: =AVERAGE(AV10:BE10) -> #N/A
A11: July | B11: 320 | C11: 108 | D11: 269 | E11: 85 | F11: 321 | G11: 231 | H11: 255 | I11: 372 | J11: 322 | K11: 216 | L11: 355 | M11: 404 | N11: 349 | O11: 366 | P11: 272 | Q11: 239 | R11: 351 | U11: 549 | W11: 331 | Y11: 349 | Z11: 295 | AA11: 649 | AB11: 446 | AC11: 446 | AD11: 393 | AE11: 378 | AF11: 408 | AG11: =41+69+58+60+66+24 -> 318 | AH11: =(1+6+3+2+2+6+2+2)+(8+6+12+1+2+3+2+2+2+1+1+1)+(2+5+6+2+4+4+5+7+4+2+2+4+4+4+1+2+1+3+2)+(7+2+5+3+2+2+2+1+7+1+2+5+1+2+4+2+2+2)+(4+2+5+3+4+2+3+4+2+5+3+3+5+2+2+1+4+2)+(3+1+2+2+11+4+5+2+1+1+1+2+1+2+5+3+4)+(4+5+1+2)+2+3+2+2+2 -> 310 | AI11: =(1+2+4+2+2+3+2+3+2+5+2+3+2+2+3+2+2+2+5+2)+(3+4+2+2+2+2+4+1+2+3+1+2+1+2+1+1+2+2)+(2+1+4+2+1+1+3+6+2+1+3+2+1+2+2+2+1+3+2)+(2+2+4+4+6+2+4+1+2+2+2+6+1+1+2+4+4)+(4+5+5+3+3+2+3+2+4+5+1+1+2+1+4+3+2+1+5+4)+(2+2+2+4+7+2+1+1+2+17+2+3+2)+(2)+(2+3+3+1)+(2+1) -> 299 | BA11: #N/A | BB11: #N/A | BC11: #N/A | BD11: #N/A | BE11: #N/A | BF11: #N/A | BG11: #N/A | BH11: #N/A | BI11: #N/A | BJ11: =AVERAGE(B11:K11) -> 249.9 | BK11: =AVERAGE(C11:L11) -> 253.4 | BL11: =AVERAGE(D11:M11) -> 283 | BM11: =AVERAGE(E11:N11) -> 291 | BN11: =AVERAGE(F11:O11) -> 319.1 | BO11: =AVERAGE(G11:P11) -> 314.2 | BP11: =AVERAGE(H11:Q11) -> 315 | BQ11: =AVERAGE(I11:R11) -> 324.6 | ... DD11: =AVERAGE(AV11:BE11) -> #N/A
A12: August | B12: 216 | C12: 182 | D12: 217 | E12: 163 | F12: 219 | G12: 359 | H12: 211 | I12: 375 | J12: 328 | K12: 354 | L12: 346 | M12: 379 | N12: 377 | O12: 289 | P12: 236 | Q12: 380 | R12: 351 | U12: 274 | W12: 335 | Y12: 277 | Z12: 342 | AA12: 553 | AB12: 452 | AC12: 452 | AD12: 521 | AE12: 387 | AF12: 290 | AG12: =30+45+46+47+55+40+40+17 -> 320 | AH12: =(1+2+7+2+5+2+2+3+4+5+5+3+2)+(3+2+3+4+7+2+2+3+2+3+2+2+5+2+2+1)+(3+1+1+9+3+4+5+12+2+7+5+7+2+2+2+2)+(2+4+4+2+2+2+2+2+2+3+1+4+3+2+2+4+2+4+1+2)+(4+6+1+9+2+2+5+2+12+2+1+4+1+2+1+6+2+1)+(1+2+2+4+2)+(1) -> 280 | AI12: =(3)+(2+2+2+2+7+1)+(2+2+2+5+2+2+1+3+4+3+4+3+1+8+2+1)+(3+6+2+4+1+2+2+2+1+2+4+2+3+1+4+2+3+2+2)+(4+1+9+2+9+2+4+1+2+6+2+2+1+3+3+2+2+4+1)+(5+1+2+2+3+1+9+1+2+8+1+2+2+2+3+6+2+3)+(3+3+2+2+2+3+3+1+1+2+4+2+2+1+4+4+2+1)+(4+1+6+6+2+4+2+2+4+2)+(1) -> 303 | BA12: #N/A | BB12: #N/A | BC12: #N/A | BD12: #N/A | BE12: #N/A | BF12: #N/A | BG12: #N/A | BH12: #N/A | BI12: #N/A | BJ12: =AVERAGE(B12:K12) -> 262.4 | BK12: =AVERAGE(C12:L12) -> 275.4 | BL12: =AVERAGE(D12:M12) -> 295.1 | BM12: =AVERAGE(E12:N12) -> 311.1 | BN12: =AVERAGE(F12:O12) -> 323.7 | BO12: =AVERAGE(G12:P12) -> 325.4 | BP12: =AVERAGE(H12:Q12) -> 327.5 | BQ12: =AVERAGE(I12:R12) -> 341.5 | ... DD12: =AVERAGE(AV12:BE12) -> #N/A
A13: September | B13: 118 | C13: 102 | D13: 148 | E13: 113 | F13: 117 | G13: 63 | H13: 124 | I13: 214 | J13: 240 | K13: 210 | L13: 246 | M13: 190 | N13: 91 | O13: 129 | P13: 216 | Q13: 133 | R13: 196 | U13: 123 | W13: 181 | Y13: 177 | Z13: 272 | AA13: 260 | AB13: 299 | AC13: 299 | AD13: 284 | AE13: 444 | AF13: 261 | AG13: =40+40+39+38+19 -> 176 | AH13: =(3+7+1+2+2+1+1+1+3+10+3+2+2+1+1)+(2+2+1+1+2+4+2+2+2+14+4+3+3+2+2+2+3+1)+(2+1+3+2+3+4+2+5+2+3+2+1+1+2+1+5+6+2)+(1+2+4+2+2+3+2+2+1+3+5+2+1+3+6+1+2+2+2+17)+(2+2+2) -> 208 | AI13: =(1+2+4+3+2+2)+(5+2+5+2+6+2+1+2+2+3+2+1+2+2+1+4+1+1+5)+(2+2+1+4+2+2+3+2+3+1+2+4+1+2+2+2+2+2+6)+(5+1+1+2+2+1+2+2+1+1+1+1+2+2+2+4+2+2)+(2+3+4+6+3+1+2+2+2+2+1+2+2+2+1+4+1+2+1)+(2+2+6+2+2+3+4+5+2+3+2+3+2+2+2+1+1) -> 229 | BA13: #N/A | BB13: #N/A | BC13: #N/A | BD13: #N/A | BE13: #N/A | BF13: #N/A | BG13: #N/A | BH13: #N/A | BI13: #N/A | BJ13: =AVERAGE(B13:K13) -> 144.9 | BK13: =AVERAGE(C13:L13) -> 157.7 | BL13: =AVERAGE(D13:M13) -> 166.5 | BM13: =AVERAGE(E13:N13) -> 160.8 | BN13: =AVERAGE(F13:O13) -> 162.4 | BO13: =AVERAGE(G13:P13) -> 172.3 | BP13: =AVERAGE(H13:Q13) -> 179.3 | BQ13: =AVERAGE(I13:R13) -> 186.5 | ... DD13: =AVERAGE(AV13:BE13) -> #N/A
A14: October | B14: 83 | C14: 90 | D14: 95 | E14: 93 | F14: 54 | G14: 143 | H14: 122 | I14: 215 | J14: 143 | K14: 130 | L14: 99 | M14: 100 | N14: 153 | O14: 182 | P14: 122 | Q14: 124 | R14: 91 | U14: 61 | W14: 124 | Y14: 186 | Z14: 196 | AA14: 274 | AB14: 261 | AC14: 82 | AD14: 242 | AE14: 241 | AF14: 226 | AG14: =25+54+49+55+20 -> 203 | AH14: =(2+2+1+1+2+1+2+1+2+4+2+2+4+2+2+2+2)+(4+2+2+2+2+2+5+4+2+2+1+1+1+2+2+2+2+2+2+2)+(2+3+4+1+2+2+2+4+2+2+2+2+1+1+3+2+1)+(2+1+1+2+1+1+2+2+2+1+3+2+2+2+3+3+2+1) -> 147 | AI14: =(2+2+2+2+2+4+2+1) -> 17 | BA14: #N/A | BB14: #N/A | BC14: #N/A | BD14: #N/A | BE14: #N/A | BF14: #N/A | BG14: #N/A | BH14: #N/A | BI14: #N/A | BJ14: =AVERAGE(B14:K14) -> 116.8 | BK14: =AVERAGE(C14:L14) -> 118.4 | BL14: =AVERAGE(D14:M14) -> 119.4 | BM14: =AVERAGE(E14:N14) -> 125.2 | BN14: =AVERAGE(F14:O14) -> 134.1 | BO14: =AVERAGE(G14:P14) -> 140.9 | BP14: =AVERAGE(H14:Q14) -> 139 | BQ14: =AVERAGE(I14:R14) -> 135.9 | ... DD14: =AVERAGE(AV14:BE14) -> #N/A
A15: November | B15: 77 | C15: 67 | D15: 48 | E15: 42 | F15: 22 | G15: 49 | H15: 56 | I15: 86 | J15: 57 | K15: 76 | L15: 54 | M15: 57 | N15: 119 | O15: 49 | P15: 79 | Q15: 91 | R15: 24 | U15: 0 | W15: 63 | Y15: 49 | Z15: 77 | AA15: 168 | AB15: 118 | AC15: 23 | AD15: 61 | AE15: 170 | AF15: 106 | AG15: =16+24 -> 40 | AH15: =(2+4)+(4+2+2+2+2+1+2+2+1+4+2+2+2+5+3+2+1+2)+(2+1+2+3+4+2+5+1+1+2) -> 70 | BA15: #N/A | BB15: #N/A | BC15: #N/A | BD15: #N/A | BE15: #N/A | BF15: #N/A | BG15: #N/A | BH15: #N/A | BI15: #N/A | BJ15: =AVERAGE(B15:K15) -> 58 | BK15: =AVERAGE(C15:L15) -> 55.7 | BL15: =AVERAGE(D15:M15) -> 54.7 | BM15: =AVERAGE(E15:N15) -> 61.8 | BN15: =AVERAGE(F15:O15) -> 62.5 | BO15: =AVERAGE(G15:P15) -> 68.2 | BP15: =AVERAGE(H15:Q15) -> 72.4 | BQ15: =AVERAGE(I15:R15) -> 69.2 | ... DD15: =AVERAGE(AV15:BE15) -> #N/A
A16: December | B16: 7 | C16: 7 | D16: 7 | E16: 13 | F16: 18 | G16: 10 | H16: 22 | I16: 48 | J16: 34 | K16: 53 | L16: 19 | M16: 14 | N16: 13 | O16: 18 | P16: 10 | Q16: 27 | R16: 8 | U16: 0 | W16: 22 | Y16: 14 | Z16: 37 | AA16: 26 | AB16: 23 | AC16: 39 | AD16: 20 | AE16: 12 | AF16: 62 | AG16: =10+41 -> 51 | AH16: =(2+2+1+1+1+1+3+4)+(5+6+5+2+2+1+3+2+2+2) -> 45 | BA16: #N/A | BB16: #N/A | BC16: #N/A | BD16: #N/A | BE16: #N/A | BF16: #N/A | BG16: #N/A | BH16: #N/A | BI16: #N/A | BJ16: =AVERAGE(B16:K16) -> 21.9 | BK16: =AVERAGE(C16:L16) -> 23.1 | BL16: =AVERAGE(D16:M16) -> 23.8 | BM16: =AVERAGE(E16:N16) -> 24.4 | BN16: =AVERAGE(F16:O16) -> 24.9 | BO16: =AVERAGE(G16:P16) -> 24.1 | BP16: =AVERAGE(H16:Q16) -> 25.8 | BQ16: =AVERAGE(I16:R16) -> 24.4 | ... DD16: =AVERAGE(AV16:BE16) -> #N/A
A18: Yearly Totals | B18: =SUM(B5:B16) -> 1348 | C18: =SUM(C5:C16) -> 823 | D18: =SUM(D5:D16) -> 1170 | E18: =SUM(E5:E16) -> 826 | F18: =SUM(F5:F16) -> 1296 | G18: =SUM(G5:G16) -> 1151 | H18: =SUM(H5:H16) -> 1250 | I18: =SUM(I5:I16) -> 2013 | ... AZ18: =SUM(AZ5:AZ16) -> 0 | BY18: =AVERAGE(Q18:Z18) -> 1012.1 | BZ18: =AVERAGE(R18:AA18) -> 1119.1 | CA18: =AVERAGE(S18:AB18) -> 1189.1 | CB18: =AVERAGE(T18:AC18) -> 1394.9 | CC18: =AVERAGE(U18:AD18) -> 1619.1

Sheet Beaverkill Road to BLM FT
A1: Balsam Lake Mountain Wild Forest
A2: BEAVERKILL (To Fire Tower) | C2: TO FIRE TOWER BLM TH
B3: 1991 | C3: 1992 | D3: 1993 | E3: 1994 | F3: 1995 | G3: 1996 | H3: 1997 | I3: 1998 | J3: 1999 | K3: 2000 | L3: 2001 | M3: 2002 | N3: 2003 | O3: 2004 | P3: 2005 | Q3: 2006 | R3: 2007 | S3: 2008 | T3: 2009 | U3: 2010 | V3: 2011 | W3: 2012 | X3: 2013 | Y3: 2014 | Z3: 2015 | AA3: 2016 | AB3: 2017 | AC3: 2018 | AD3: 2019 | AE3: 2020 | AF3: 2021 | AG3: 2022 | AH3: 2023 | AI3: 2024 | AJ3: 2025 | AK3: 2026 | AL3: 2027 | AM3: 2028 | AN3: 2029 | AO3: 2030 | AP3: 2031 | AQ3: 2032 | AR3: 2033 | AS3: 2034 | AT3: 2035 | AU3: 2036 | AV3: 2037 | AW3: 2038 | AX3: 2039 | AY3: 2040 | AZ3: 2041 | BA3: 10 Year Rolling Averages | BK3: 2001 | BL3: 2002 | BM3: 2003 | BN3: 2004 | BO3: 2005 | BP3: 2006 | BQ3: 2007 | BR3: 2008 | BS3: 2009 | BT3: 2010 | BU3: 2011 | BV3: 2012 | BW3: 2013 | BX3: 2014 | BY3: 2015 | BZ3: 10-YEAR-AVG- 2016 | CA3: 10-YEAR-AVG- 2017 | CB3: 10-YEAR-AVG- 2018 | CC3: 10-YEAR-AVG 2019 | CD3: 10-YEAR-AVG-2020 | CE3: 2021 | CF3: 2022 | CG3: 2023 | CH3: 2024 | CI3: 2025 | CJ3: 2026 | CK3: 2027 | CL3: 2028 | CM3: 2029 | CN3: 2030 | CO3: 2031 | CP3: 2032 | CQ3: 2033 | CR3: 2034 | CS3: 2035 | CT3: 2036 | CU3: 2037 | CV3: 2038 | CW3: 2039 | CX3: 2040 | CY3: 2041 | CZ3: 2042 | DA3: 2043 | DB3: 2044 | DC3: 2045 | DD3: 2046
A5: January | F5: 29 | G5: 4 | H5: 10 | I5: 27 | J5: 7 | K5: 23 | L5: 23 | M5: 10 | N5: 61 | O5: 18 | P5: 10 | Q5: 25 | R5: 38 | U5: 17 | W5: 79 | Y5: 28 | Z5: 41 | AA5: 30 | AB5: 21 | AC5: 26 | AD5: =AVERAGE(AA5:AC5) -> 25.666667 | AE5: 23 | AF5: 119 | AG5: =38+28 -> 66 | AH5: =32+27 -> 59 | AI5: =(2+2+1+2+2+1+2+2+1+1+2+2+2+2+2+1+1+3)+(2) -> 33 | BB5: #N/A | BC5: #N/A | BD5: #N/A | BE5: #N/A | BF5: #N/A | BG5: #N/A | BH5: #N/A | BI5: #N/A | BJ5: =AVERAGE(B5:K5) -> 16.666667 | BK5: =AVERAGE(C5:L5) -> 17.571429 | BL5: =AVERAGE(D5:M5) -> 16.625 | BM5: =AVERAGE(E5:N5) -> 21.555556 | BN5: =AVERAGE(F5:O5) -> 21.2 | BO5: =AVERAGE(G5:P5) -> 19.3 | BP5: =AVERAGE(H5:Q5) -> 21.4 | BQ5: =AVERAGE(I5:R5) -> 24.2 | ... DD5: =AVERAGE(AV5:BE5) -> #N/A
A6: February | F6: 5 | G6: 16 | H6: 10 | I6: 41 | J6: 39 | K6: 20 | L6: 11 | M6: 30 | N6: 14 | O6: 40 | P6: 20 | Q6: 27 | R6: 44 | U6: 33 | W6: 184 | Y6: 42 | Z6: 7 | AA6: 39 | AB6: 30 | AC6: 34 | AD6: =AVERAGE(AA6:AC6) -> 34.333333 | AE6: 30 | AF6: 73 | AG6: =10+44+12 -> 66 | AH6: =4+49+18 -> 71 | AI6: =(4+2+2+3+2+2+2+2+2+4+3+1+1+1+2+1+2+2)+(6+2+2+2+3+2+2+3+1+2+2+2+2+2+1+2+2+1+2+1)+(1) -> 81 | BA6: #N/A | BB6: #N/A | BC6: #N/A | BD6: #N/A | BE6: #N/A | BF6: #N/A | BG6: #N/A | BH6: #N/A | BI6: #N/A | BJ6: =AVERAGE(B6:K6) -> 21.833333 | BK6: =AVERAGE(C6:L6) -> 20.285714 | BL6: =AVERAGE(D6:M6) -> 21.5 | BM6: =AVERAGE(E6:N6) -> 20.666667 | BN6: =AVERAGE(F6:O6) -> 22.6 | BO6: =AVERAGE(G6:P6) -> 24.1 | BP6: =AVERAGE(H6:Q6) -> 25.2 | BQ6: =AVERAGE(I6:R6) -> 28.6 | ... DD6: =AVERAGE(AV6:BE6) -> #N/A
A7: March | F7: 16 | G7: 10 | H7: 14 | I7: 34 | J7: 22 | K7: 33 | L7: 25 | M7: 14 | N7: 31 | O7: 29 | P7: 11 | Q7: 21 | R7: 20 | U7: 20 | W7: 111 | Y7: 31 | Z7: 23 | AA7: 67 | AB7: 8 | AC7: 22 | AD7: =AVERAGE(AA7:AC7) -> 32.333333 | AE7: 80 | AF7: 105 | AG7: =24+20 -> 44 | AH7: =11+14 -> 25 | AI7: =(2)+(2+2+3+1+1+1+1+2+1+2+3+1+4+1+1+2+3+3+1)+(2+5+1+2+2+2+2+2+2+1+2+3+2+2+2+2+4+2)+(2+2+1) -> 82 | BA7: #N/A | BB7: #N/A | BC7: #N/A | BD7: #N/A | BE7: #N/A | BF7: #N/A | BG7: #N/A | BH7: #N/A | BI7: #N/A | BJ7: =AVERAGE(B7:K7) -> 21.5 | BK7: =AVERAGE(C7:L7) -> 22 | BL7: =AVERAGE(D7:M7) -> 21 | BM7: =AVERAGE(E7:N7) -> 22.111111 | BN7: =AVERAGE(F7:O7) -> 22.8 | BO7: =AVERAGE(G7:P7) -> 22.3 | BP7: =AVERAGE(H7:Q7) -> 23.4 | BQ7: =AVERAGE(I7:R7) -> 24 | ... DD7: =AVERAGE(AV7:BE7) -> #N/A
A8: April | F8: 48 | G8: 21 | H8: 35 | I8: 51 | J8: 24 | K8: 34 | L8: 23 | M8: 57 | N8: 52 | O8: 47 | P8: 52 | Q8: 91 | R8: 49 | U8: 71 | W8: 114 | Y8: 55 | Z8: 77 | AA8: 152 | AB8: 81 | AC8: 47 | AD8: 69 | AE8: 72 | AF8: 152 | AG8: =24+41+35+31+2 -> 133 | AH8: =26+46+29+7 -> 108 | AI8: =(1+3+1+2+2+2+9+1+1+2+1+1+1+1+1+3)+(1+3+2+12+1+1+1+2+2+6+1+1+1+2+2+2+1+3+2)+(3+1+3+2+1+6+2+9+2+2+1) -> 110 | BA8: #N/A | BB8: #N/A | BC8: #N/A | BD8: #N/A | BE8: #N/A | BF8: #N/A | BG8: #N/A | BH8: #N/A | BI8: #N/A | BJ8: =AVERAGE(B8:K8) -> 35.5 | BK8: =AVERAGE(C8:L8) -> 33.714286 | BL8: =AVERAGE(D8:M8) -> 36.625 | BM8: =AVERAGE(E8:N8) -> 38.333333 | BN8: =AVERAGE(F8:O8) -> 39.2 | BO8: =AVERAGE(G8:P8) -> 39.6 | BP8: =AVERAGE(H8:Q8) -> 46.6 | BQ8: =AVERAGE(I8:R8) -> 48 | ... DD8: =AVERAGE(AV8:BE8) -> #N/A
A9: May | F9: 59 | G9: 79 | H9: 86 | I9: 121 | J9: 117 | K9: 110 | L9: 151 | M9: 83 | N9: 142 | O9: 47 | P9: 90 | Q9: 132 | R9: 58 | U9: 72 | W9: 170 | Y9: 108 | Z9: 151 | AA9: 175 | AB9: 147 | AC9: 135 | AD9: 127 | AE9: 136 | AF9: 171 | AG9: =34+61+47+32+38+5 -> 217 | AH9: =6+17+(1+1+2+1+1+2+1+1+2+3+2+2+3+2+1+1+3+3+1+1)+(1+2+1+2+2+2+2+4+2+2+1+2+2+5+1+1+2+2+2+2)+(2+3+1+2+1+6+2+2+7+2+2+4+1+2+2+3+1)+(1+2+1+2+2+2+2+2+2+2+2+2+2+2+2+1+3+2+2+4)+(1+2+5+2+2+2+1+2+1+2+1) -> 201 | AI9: =(4)+(2+6+1+1+2)+(1+3+2+2+3+2+3+1+2+4+4+2+2+3+1+3+1+2+1+1)+(2+2+4+1+3+1+1+1+2+2+2+2+2+2+2+2+1+2+1)+(2+1+1+1+2+2+1+5+1+1+2+2+4+4+2+5+1+2+3)+(2+1+3+2+4+1+2+2+2+1+5+1+3+1+2+1+1+2+2+4)+(1+4+1+1+2+2) -> 189 | BA9: #N/A | BB9: #N/A | BC9: #N/A | BD9: #N/A | BE9: #N/A | BF9: #N/A | BG9: #N/A | BH9: #N/A | BI9: #N/A | BJ9: =AVERAGE(B9:K9) -> 95.333333 | BK9: =AVERAGE(C9:L9) -> 103.28571 | BL9: =AVERAGE(D9:M9) -> 100.75 | BM9: =AVERAGE(E9:N9) -> 105.33333 | BN9: =AVERAGE(F9:O9) -> 99.5 | BO9: =AVERAGE(G9:P9) -> 102.6 | BP9: =AVERAGE(H9:Q9) -> 107.9 | BQ9: =AVERAGE(I9:R9) -> 105.1 | ... DD9: =AVERAGE(AV9:BE9) -> #N/A
A10: June | F10: 69 | G10: 61 | H10: 95 | I10: 123 | J10: 79 | K10: 93 | L10: 119 | M10: 123 | N10: 95 | O10: 121 | P10: 82 | Q10: 98 | R10: 130 | U10: 142 | W10: 159 | Y10: 114 | Z10: 78 | AA10: 339 | AB10: 96 | AC10: 185 | AD10: 195 | AE10: 163 | AF10: 187 | AG10: =34+39+43+52+29 -> 197 | AH10: =(2+3)+(2+4+2+2+13+2+1+1+2)+(3+2+1+2+3+3+1+2+2+2+2+2+1+1+15)+(1+4+2+2+2+2+1+1+5+2+2+1+2+4+13+1+1+10+1+1)+(4+2+3+1+3+3+3+1+3+3+2+1+2+4+6+2+6+2+2+2)+(2+1+4+2+1+3+1+1+1+2+1+2+2+2+1+4+1+2+2)+(2+6+2+1+1+2) -> 238 | AI10: =(4+2+1+5+6+2+2+1+4+6+2+2+2)+(2+1+1+2+1+1+1+1+2+3+2+6+2+2+1+1+4+3)+(2+1+1+2+2+6+3+2+1+3+2+2+2+2+2+2+3+1+4+2)+(2+1+2+1+4+1+1+2+2+2+1+2+1+3+2+3+4+4+1)+(1+1+2+4+3+4+2+1+2+1+4+1+3+2) -> 190 | BA10: #N/A | BB10: #N/A | BC10: #N/A | BD10: #N/A | BE10: #N/A | BF10: #N/A | BG10: #N/A | BH10: #N/A | BI10: #N/A | BJ10: =AVERAGE(B10:K10) -> 86.666667 | BK10: =AVERAGE(C10:L10) -> 91.285714 | BL10: =AVERAGE(D10:M10) -> 95.25 | BM10: =AVERAGE(E10:N10) -> 95.222222 | BN10: =AVERAGE(F10:O10) -> 97.8 | BO10: =AVERAGE(G10:P10) -> 99.1 | BP10: =AVERAGE(H10:Q10) -> 102.8 | BQ10: =AVERAGE(I10:R10) -> 106.3 | ... DD10: =AVERAGE(AV10:BE10) -> #N/A
A11: July | E11: 173 | F11: 196 | G11: 112 | H11: 169 | I11: 170 | J11: 99 | K11: 160 | L11: 209 | M11: 223 | N11: 214 | O11: 189 | P11: 210 | Q11: 131 | R11: 212 | U11: 173 | W11: 180 | Y11: 196 | Z11: 187 | AA11: 219 | AB11: 307 | AC11: 237 | AD11: 312 | AE11: 329 | AF11: 275 | AG11: =44+61+42+55+60+49 -> 311 | AH11: =(2+5+2+2+4+1+1+2+2+4+2+2+3)+(2+1+1+2+1+1+7+2+3+3+1+1+2+4+2+5+4+3)+(1+2+2+1+1+2+1+2+1+1+3+2+1+2+2+2+2+2)+(1+1+2+8+1+1+1+1+1+1+9+2+1+3+2+2+2+2+4+1)+(1+2+1+2+1+3+2+1+1+2+1+3+4+4+1+1+2+1+2+2)+(1+1+1+1+2+3+4+2+1+1) -> 207 | AI11: =(1+2+2+1+2+2)+(1+2+4+2+2+2+4+1+2+6+1+2+1+1+2+4+3+2+2)+(3+2+2+2+1+3+1+8+1+1+8+3+5+8+2+2+4+1+8+4)+(1+1+5+2+3+2+1+2+2+1+2+2+2+3+5+1+3+2+2)+(2+4+2+2+2+2+2+2+2+2+1+2+1+2) -> 193 | BA11: #N/A | BB11: #N/A | BC11: #N/A | BD11: #N/A | BE11: #N/A | BF11: #N/A | BG11: #N/A | BH11: #N/A | BI11: #N/A | BJ11: =AVERAGE(B11:K11) -> 154.14286 | BK11: =AVERAGE(C11:L11) -> 161 | BL11: =AVERAGE(D11:M11) -> 167.88889 | BM11: =AVERAGE(E11:N11) -> 172.5 | BN11: =AVERAGE(F11:O11) -> 174.1 | BO11: =AVERAGE(G11:P11) -> 175.5 | BP11: =AVERAGE(H11:Q11) -> 177.4 | BQ11: =AVERAGE(I11:R11) -> 181.7 | ... DD11: =AVERAGE(AV11:BE11) -> #N/A
A12: August | E12: 143 | F12: 157 | G12: 123 | H12: 179 | I12: 157 | J12: 174 | K12: 190 | L12: 137 | M12: 110 | N12: 155 | O12: 147 | P12: 139 | Q12: 147 | R12: 191 | U12: 342 | W12: 172 | Y12: 252 | Z12: 266 | AA12: 187 | AB12: 257 | AC12: 189 | AD12: 465 | AE12: 318 | AF12: 146 | AG12: =10+25+51+50+31+59+17+6 -> 249 | AH12: =(2+2+1+2+2+3+3+1+1)+(4+1+1+3+2+2+2+2+1+2+2+2+2+1+1)+(2+4+4+1+4+2+4+1+5+2+2+4+5+2+2+2+2+2+2+2)+(7+2+1+4+3+1+1+1+1+3+2+2+1+2+1+4+2+2)+(4+2+3+1+1+1+2+2+1+3+2+3+2+12+4+4+2+1+4+1)+(2+1+2+4+1+6+6+1+2+2+5+2+2+2+1+2+1)+(2+17+1+7+2+1+2+1+3+2+2+1+1+2+2+3) -> 285 | AI12: =(1+2)+(7+2+2+2+1+2+3+2+7+5+3+2+5+4)+(2+3+1+4+2+2+2+2+1+2+2+2+5+2+3+2)+(4+2+4+3+3+9+1+1+3+3+2+1+1+1+1+1+1+1+2)+(1+1+2+2+2+3+2+9+1+1+1+2+1+1+2+2+4+4)+(2+1+2+2+1+2+2+2+2+6+2) -> 196 | BA12: #N/A | BB12: #N/A | BC12: #N/A | BD12: #N/A | BE12: #N/A | BF12: #N/A | BG12: #N/A | BH12: #N/A | BI12: #N/A | BJ12: =AVERAGE(B12:K12) -> 160.42857 | BK12: =AVERAGE(C12:L12) -> 157.5 | BL12: =AVERAGE(D12:M12) -> 152.22222 | BM12: =AVERAGE(E12:N12) -> 152.5 | BN12: =AVERAGE(F12:O12) -> 152.9 | BO12: =AVERAGE(G12:P12) -> 151.1 | BP12: =AVERAGE(H12:Q12) -> 153.5 | BQ12: =AVERAGE(I12:R12) -> 154.7 | ... DD12: =AVERAGE(AV12:BE12) -> #N/A
A13: September | E13: 181 | F13: 133 | G13: 61 | H13: 76 | I13: 121 | J13: 156 | K13: 74 | L13: 93 | M13: 120 | N13: 77 | O13: 173 | P13: 161 | Q13: 97 | R13: 144 | U13: 182 | W13: 119 | Y13: 133 | Z13: 144 | AA13: 166 | AB13: 167 | AC13: 225 | AD13: 284 | AE13: 331 | AF13: 219 | AG13: =24+49+49+30+48+13+31 -> 244 | AH13: =(1+2)+(2+3+1+1+2+2+2+2+2+2+8+2+4+1+2+6+2)+(1+3+4+1+1+3+2+1+1+1+2+2+2+1+2+5+2+2+3+2)+(1+3+2+2+2+2+2+1+2+1+2+2+3+3+1+3+2+1+3+1) -> 127 | AI13: =(2+2+3+5+3+5+2+1+2)+(2+2+1+2+4+1+1+2+1+2+2+5+2+1+1+5+2+2+2+2)+(1+1+4+2+3+1+2+1+3+1+2+3+2+2+2+2+4+1+5)+(2+2+1+1+2+3+2+2+2+2+2+3+2+2+2+2+3+1+2)+(1+2+1+2+3+3+2+2+2+1+2+1+3+2+4+2+1+2+1+2)+(4+1+10+1+1) -> 203 | BA13: #N/A | BB13: #N/A | BC13: #N/A | BD13: #N/A | BE13: #N/A | BF13: #N/A | BG13: #N/A | BH13: #N/A | BI13: #N/A | BJ13: =AVERAGE(B13:K13) -> 114.57143 | BK13: =AVERAGE(C13:L13) -> 111.875 | BL13: =AVERAGE(D13:M13) -> 112.77778 | BM13: =AVERAGE(E13:N13) -> 109.2 | BN13: =AVERAGE(F13:O13) -> 108.4 | BO13: =AVERAGE(G13:P13) -> 111.2 | BP13: =AVERAGE(H13:Q13) -> 114.8 | BQ13: =AVERAGE(I13:R13) -> 121.6 | ... DD13: =AVERAGE(AV13:BE13) -> #N/A
A14: October | E14: 122 | F14: 56 | G14: 77 | H14: 146 | I14: 131 | J14: 99 | K14: 138 | L14: 156 | M14: 76 | N14: 136 | O14: 141 | P14: 84 | Q14: 154 | R14: 131 | U14: 278 | W14: 170 | Y14: 141 | Z14: 196 | AA14: 247 | AB14: 128 | AC14: 140 | AD14: 369 | AE14: 342 | AF14: 303 | AG14: =21+35+50+49+43+43+29+6+4 -> 280 | AH14: =(11+2+2+2+2+2+2+2+2+1+4+2+2+1+2+1+1+1+2+1)+(2+5+4+3+2+1+3+2+4+2+4+3+9+2+4+2+2+1+2+2)+(1+2+2+1+2+2+1+2+2+2+3+2+2+5+1+5+4+8+2+4)+(1+1+2+6+4+1+1+2+1+2+2+2+1+2+2)+(2+2+2+1+2+5+2+2+1+2+4+4+2+1+2+1+1+1+2)+(2+1+2+2+2+3+2+2+3+1+2) -> 248 | AI14: =(2+1+2+1+2+2+1+1) -> 12 | BA14: #N/A | BB14: #N/A | BC14: #N/A | BD14: #N/A | BE14: #N/A | BF14: #N/A | BG14: #N/A | BH14: #N/A | BI14: #N/A | BJ14: =AVERAGE(B14:K14) -> 109.85714 | BK14: =AVERAGE(C14:L14) -> 115.625 | BL14: =AVERAGE(D14:M14) -> 111.22222 | BM14: =AVERAGE(E14:N14) -> 113.7 | BN14: =AVERAGE(F14:O14) -> 115.6 | BO14: =AVERAGE(G14:P14) -> 118.4 | BP14: =AVERAGE(H14:Q14) -> 126.1 | BQ14: =AVERAGE(I14:R14) -> 124.6 | ... DD14: =AVERAGE(AV14:BE14) -> #N/A
A15: November | E15: 21 | F15: 34 | G15: 37 | H15: 33 | I15: 79 | J15: 105 | K15: 42 | L15: 31 | M15: 41 | N15: 63 | O15: 66 | P15: 76 | Q15: 67 | R15: 43 | U15: 48 | W15: 102 | Y15: 64 | Z15: 89 | AA15: 76 | AB15: 69 | AC15: 54 | AD15: 148 | AE15: 67 | AF15: 135 | AG15: =28+40+8+8+2 -> 86 | AH15: =(2+2+2+2+3+3+3+2)+(4+2+3+2+3+1+1+1+2+2+2+1+3+3+1+1+2+5+4+5)+(1+3+1+1+4+1+2+2+1+7+1+3+1+2+2+3+2+1)+(2+1+3+2+1+2+1+2+2+2+2+2+4+1+2+1) -> 135 | BA15: #N/A | BB15: #N/A | BC15: #N/A | BD15: #N/A | BE15: #N/A | BF15: #N/A | BG15: #N/A | BH15: #N/A | BI15: #N/A | BJ15: =AVERAGE(B15:K15) -> 50.142857 | BK15: =AVERAGE(C15:L15) -> 47.75 | BL15: =AVERAGE(D15:M15) -> 47 | BM15: =AVERAGE(E15:N15) -> 48.6 | BN15: =AVERAGE(F15:O15) -> 53.1 | BO15: =AVERAGE(G15:P15) -> 57.3 | BP15: =AVERAGE(H15:Q15) -> 60.3 | BQ15: =AVERAGE(I15:R15) -> 61.3 | ... DD15: =AVERAGE(AV15:BE15) -> #N/A
A16: December | E16: 31 | F16: 28 | G16: 16 | H16: 18 | I16: 21 | J16: 25 | K16: 27 | L16: 25 | M16: 8 | N16: 19 | O16: 42 | P16: 19 | Q16: 31 | R16: 28 | U16: 20 | W16: 81 | Y16: 29 | Z16: 48 | AA16: 35 | AB16: 15 | AC16: 46 | AD16: 62 | AE16: 69 | AF16: 88 | AG16: =23+40 -> 63 | AH16: =(1+3+2)+(1+1+1+2+1+2+2+1+2+1+3+1+1+1+2+1+2+1+2+2)+(2+4+6+3+1+4+2+2+2+2+5+1+1+1+3+2)+(2+1+2+1+1) -> 84 | BA16: #N/A | BB16: #N/A | BC16: #N/A | BD16: #N/A | BE16: #N/A | BF16: #N/A | BG16: #N/A | BH16: #N/A | BI16: #N/A | BJ16: =AVERAGE(B16:K16) -> 23.714286 | BK16: =AVERAGE(C16:L16) -> 23.875 | BL16: =AVERAGE(D16:M16) -> 22.111111 | BM16: =AVERAGE(E16:N16) -> 21.8 | BN16: =AVERAGE(F16:O16) -> 22.9 | BO16: =AVERAGE(G16:P16) -> 22 | BP16: =AVERAGE(H16:Q16) -> 23.5 | BQ16: =AVERAGE(I16:R16) -> 24.5 | ... DD16: =AVERAGE(AV16:BE16) -> #N/A
A18: Yearly Totals | B18: =SUM(B5:B16) -> 0 | C18: =SUM(C5:C16) -> 0 | D18: =SUM(D5:D16) -> 0 | E18: =SUM(E5:E16) -> 671 | F18: =SUM(F5:F16) -> 830 | G18: =SUM(G5:G16) -> 617 | H18: =SUM(H5:H16) -> 871 | I18: =SUM(I5:I16) -> 1076 | ... AZ18: =SUM(AZ5:AZ16) -> 0 | BX18: =AVERAGE(P18:Y18) -> 729.5 | BY18: =AVERAGE(Q18:Z18) -> 764.8 | BZ18: =AVERAGE(R18:AA18) -> 835.9 | CA18: =AVERAGE(S18:AB18) -> 859.7 | CB18: =AVERAGE(T18:AC18) -> 993.7

Sheet Dry Brook Ridge to Lean-to 
A1: Balsam Lake Mountain Wild Forest
A2: DRY BROOK RIDGE - to Lean-to from Dry Brook Parking Area -Millbrook Road
B3: 1991 | C3: 1992 | D3: 1993 | E3: 1994 | F3: 1995 | G3: 1996 | H3: 1997 | I3: 1998 | J3: 1999 | K3: 2000 | L3: 2001 | M3: 2002 | N3: 2003 | O3: 2004 | P3: 2005 | Q3: 2006 | R3: 2007 | S3: 2008 | T3: 2009 | U3: 2010 | V3: 2011 | W3: 2012 | X3: 2013 | Y3: 2014 | Z3: 2015 | AA3: 2016 | AB3: 2017 | AC3: 2018 | AD3: 2019 | AE3: 2020 | AF3: 2021 | AG3: 2022 | AH3: 2023 | AI3: 2024 | AJ3: 2025 | AK3: 2026 | AL3: 2027 | AM3: 2028 | AN3: 2029 | AO3: 2030 | AP3: 2031 | AQ3: 2032 | AR3: 2033 | AS3: 2034 | AT3: 2035 | AU3: 2036 | AV3: 2037 | AW3: 2038 | AX3: 2039 | AY3: 2040 | AZ3: 2041 | BA3: 10 Year Rolling Averages | BK3: 2001 | BL3: 2002 | BM3: 2003 | BN3: 2004 | BO3: 2005 | BP3: 2006 | BQ3: 2007 | BR3: 2008 | BS3: 2009 | BT3: 2010 | BU3: 2011 | BV3: 2012 | BW3: 2013 | BX3: 2014 | BY3: 2015 | BZ3: 10-YEAR-AVG-2016 | CA3: 10-YEAR-AVG-2017 | CB3: 10-YEAR-AVG-2018 | CC3: 10-YEAR-AVG 2019 | CD3: 10-YEAR-AVG-2020 | CE3: 2021 | CF3: 2022 | CG3: 2023 | CH3: 2024 | CI3: 2025 | CJ3: 2026 | CK3: 2027 | CL3: 2028 | CM3: 2029 | CN3: 2030 | CO3: 2031 | CP3: 2032 | CQ3: 2033 | CR3: 2034 | CS3: 2035 | CT3: 2036 | CU3: 2037 | CV3: 2038 | CW3: 2039 | CX3: 2040 | CY3: 2041 | CZ3: 2042 | DA3: 2043 | DB3: 2044 | DC3: 2045 | DD3: 2046
A5: January | F5: 2 | G5: 1 | H5: 5 | I5: 1 | J5: 11 | K5: 5 | L5: 0 | M5: 1 | N5: 4 | O5: 3 | P5: 4 | Q5: 0 | R5: 2 | U5: 5 | W5: 11 | Y5: 1 | Z5: 4 | AA5: 20 | AB5: 2 | AC5: 34 | AD5: =AVERAGE(AA5:AC5) -> 18.666667 | AE5: =AVERAGE(AB5:AD5) -> 18.222222 | AF5: 15 | AG5: =11 -> 11 | AH5: 15 | AI5: =(1+2+4+2+1+1) -> 11 | BB5: #N/A | BC5: #N/A | BD5: #N/A | BE5: #N/A | BF5: #N/A | BG5: #N/A | BH5: #N/A | BI5: #N/A | BJ5: =AVERAGE(B5:K5) -> 4.1666667 | BK5: =AVERAGE(C5:L5) -> 3.5714286 | BL5: =AVERAGE(D5:M5) -> 3.25 | BM5: =AVERAGE(E5:N5) -> 3.3333333 | BN5: =AVERAGE(F5:O5) -> 3.3 | BO5: =AVERAGE(G5:P5) -> 3.5 | BP5: =AVERAGE(H5:Q5) -> 3.4 | BQ5: =AVERAGE(I5:R5) -> 3.1 | ... DD5: =AVERAGE(AV5:BE5) -> #N/A
A6: February | F6: 13 | G6: 3 | H6: 2 | I6: 6 | J6: 16 | K6: 0 | L6: 4 | M6: 0 | N6: 1 | O6: 5 | P6: 2 | Q6: 16 | R6: 3 | U6: 1 | W6: 8 | Y6: 11 | Z6: 7 | AA6: 30 | AB6: 9 | AC6: 17 | AD6: =AVERAGE(AA6:AC6) -> 18.666667 | AE6: =AVERAGE(AB6:AD6) -> 14.888889 | AF6: 7 | AG6: =16+3 -> 19 | AH6: 11 | AI6: =(2)+(1+4+1+1+1+1+1+8+1+1) -> 22 | BA6: #N/A | BB6: #N/A | BC6: #N/A | BD6: #N/A | BE6: #N/A | BF6: #N/A | BG6: #N/A | BH6: #N/A | BI6: #N/A | BJ6: =AVERAGE(B6:K6) -> 6.6666667 | BK6: =AVERAGE(C6:L6) -> 6.2857143 | BL6: =AVERAGE(D6:M6) -> 5.5 | BM6: =AVERAGE(E6:N6) -> 5 | BN6: =AVERAGE(F6:O6) -> 5 | BO6: =AVERAGE(G6:P6) -> 3.9 | BP6: =AVERAGE(H6:Q6) -> 5.2 | BQ6: =AVERAGE(I6:R6) -> 5.3 | ... DD6: =AVERAGE(AV6:BE6) -> #N/A
A7: March | F7: 5 | G7: 3 | H7: 11 | I7: 8 | J7: 15 | K7: 12 | L7: 9 | M7: 6 | N7: 5 | O7: 3 | P7: 4 | Q7: 1 | R7: 2 | U7: 6 | W7: 11 | X7: 11 | Y7: 8 | Z7: 6 | AA7: 7 | AB7: 0 | AC7: 4 | AD7: =AVERAGE(AA7:AC7) -> 3.6666667 | AE7: =AVERAGE(AB7:AD7) -> 2.5555556 | AF7: 13 | AG7: =12 -> 12 | AH7: 12 | AI7: =(2+1+2+1+2+1+1) -> 10 | BA7: #N/A | BB7: #N/A | BC7: #N/A | BD7: #N/A | BE7: #N/A | BF7: #N/A | BG7: #N/A | BH7: #N/A | BI7: #N/A | BJ7: =AVERAGE(B7:K7) -> 9 | BK7: =AVERAGE(C7:L7) -> 9 | BL7: =AVERAGE(D7:M7) -> 8.625 | BM7: =AVERAGE(E7:N7) -> 8.2222222 | BN7: =AVERAGE(F7:O7) -> 7.7 | BO7: =AVERAGE(G7:P7) -> 7.6 | BP7: =AVERAGE(H7:Q7) -> 7.4 | BQ7: =AVERAGE(I7:R7) -> 6.5 | ... DD7: =AVERAGE(AV7:BE7) -> #N/A
A8: April | F8: 20 | G8: 16 | H8: 7 | I8: 13 | J8: 6 | K8: 5 | L8: 7 | M8: 9 | N8: 5 | O8: 5 | P8: 8 | Q8: 7 | R8: 3 | U8: 4 | W8: 11 | X8: 15 | Y8: 27 | Z8: 11 | AA8: 20 | AB8: 26 | AC8: 22 | AD8: 24 | AE8: =AVERAGE(AB8:AD8) -> 24 | AF8: 43 | AG8: =17 -> 17 | AH8: 10 | AI8: =(2)+(2+1+2+2+4) -> 13 | BA8: #N/A | BB8: #N/A | BC8: #N/A | BD8: #N/A | BE8: #N/A | BF8: #N/A | BG8: #N/A | BH8: #N/A | BI8: #N/A | BJ8: =AVERAGE(B8:K8) -> 11.166667 | BK8: =AVERAGE(C8:L8) -> 10.571429 | BL8: =AVERAGE(D8:M8) -> 10.375 | BM8: =AVERAGE(E8:N8) -> 9.7777778 | BN8: =AVERAGE(F8:O8) -> 9.3 | BO8: =AVERAGE(G8:P8) -> 8.1 | BP8: =AVERAGE(H8:Q8) -> 7.2 | BQ8: =AVERAGE(I8:R8) -> 6.8 | ... DD8: =AVERAGE(AV8:BE8) -> #N/A
A9: May | E9: 33 | F9: 36 | G9: 47 | H9: 56 | I9: 13 | J9: 28 | K9: 23 | L9: 29 | M9: 26 | N9: 13 | O9: 52 | P9: 147 | Q9: 17 | R9: 15 | U9: 14 | W9: 38 | X9: 28 | Y9: 13 | Z9: 39 | AA9: 18 | AB9: 17 | AC9: 30 | AD9: 35 | AE9: =AVERAGE(AB9:AD9) -> 27.333333 | AF9: 25 | AG9: 35 | AH9: =4+(1+2+1+2+2+2+2+1+2+1+1+3+1) -> 25 | AI9: =(1+2+1+10+1+2) -> 17 | BA9: #N/A | BB9: #N/A | BC9: #N/A | BD9: #N/A | BE9: #N/A | BF9: #N/A | BG9: #N/A | BH9: #N/A | BI9: #N/A | BJ9: =AVERAGE(B9:K9) -> 33.714286 | BK9: =AVERAGE(C9:L9) -> 33.125 | BL9: =AVERAGE(D9:M9) -> 32.333333 | BM9: =AVERAGE(E9:N9) -> 30.4 | BN9: =AVERAGE(F9:O9) -> 32.3 | BO9: =AVERAGE(G9:P9) -> 43.4 | BP9: =AVERAGE(H9:Q9) -> 40.4 | BQ9: =AVERAGE(I9:R9) -> 36.3 | ... DD9: =AVERAGE(AV9:BE9) -> #N/A
A10: June | E10: 37 | F10: 22 | G10: 26 | H10: 17 | I10: 34 | J10: 34 | K10: 15 | L10: 24 | M10: 38 | N10: 14 | O10: 6 | P10: 5 | Q10: 6 | R10: 20 | U10: 15 | W10: 32 | X10: 7 | Y10: 16 | Z10: 14 | AA10: 22 | AB10: 24 | AC10: 40 | AD10: 49 | AE10: =AVERAGE(AB10:AD10) -> 37.666667 | AF10: 21 | AG10: 27 | AH10: =(1+1+4+1+2+6+1)+(2+1+2+2+2+2+2+12+1+2+3+2) -> 49 | AI10: =(2+2+1+2+2+3)+(1+2+2+3) -> 20 | BA10: #N/A | BB10: #N/A | BC10: #N/A | BD10: #N/A | BE10: #N/A | BF10: #N/A | BG10: #N/A | BH10: #N/A | BI10: #N/A | BJ10: =AVERAGE(B10:K10) -> 26.428571 | BK10: =AVERAGE(C10:L10) -> 26.125 | BL10: =AVERAGE(D10:M10) -> 27.444444 | BM10: =AVERAGE(E10:N10) -> 26.1 | BN10: =AVERAGE(F10:O10) -> 23 | BO10: =AVERAGE(G10:P10) -> 21.3 | BP10: =AVERAGE(H10:Q10) -> 19.3 | BQ10: =AVERAGE(I10:R10) -> 19.6 | ... DD10: =AVERAGE(AV10:BE10) -> #N/A
A11: July | E11: 58 | F11: 95 | G11: 84 | H11: 49 | I11: 98 | J11: 87 | K11: 94 | L11: 60 | M11: 30 | N11: 43 | O11: 41 | P11: 35 | Q11: 22 | R11: 14 | U11: 18 | W11: 34 | X11: 12 | Y11: 28 | Z11: 21 | AA11: 23 | AB11: 32 | AC11: 36 | AD11: 35 | AE11: =AVERAGE(AB11:AD11) -> 34.333333 | AF11: 60 | AG11: =9+27 -> 36 | AH11: =(7+1+1+1+1+2+2)+(2+3+1+1) -> 22 | AI11: =(2+1+1+2+7+2+2+8+2+1+1+2+2+2+1)+(2+1+2+2+2+1) -> 46 | BA11: #N/A | BB11: #N/A | BC11: #N/A | BD11: #N/A | BE11: #N/A | BF11: #N/A | BG11: #N/A | BH11: #N/A | BI11: #N/A | BJ11: =AVERAGE(B11:K11) -> 80.714286 | BK11: =AVERAGE(C11:L11) -> 78.125 | BL11: =AVERAGE(D11:M11) -> 72.777778 | BM11: =AVERAGE(E11:N11) -> 69.8 | BN11: =AVERAGE(F11:O11) -> 68.1 | BO11: =AVERAGE(G11:P11) -> 62.1 | BP11: =AVERAGE(H11:Q11) -> 55.9 | BQ11: =AVERAGE(I11:R11) -> 52.4 | ... DD11: =AVERAGE(AV11:BE11) -> #N/A
A12: August | E12: 56 | F12: 89 | G12: 71 | H12: 62 | I12: 34 | J12: 14 | K12: 14 | L12: 23 | M12: 34 | N12: 33 | O12: 22 | P12: 27 | Q12: 24 | R12: 33 | U12: 15 | W12: 23 | X12: 44 | Y12: 49 | Z12: 28 | AA12: 37 | AB12: 32 | AC12: 42 | AD12: 66 | AE12: =AVERAGE(AB12:AD12) -> 46.666667 | AF12: 21 | AG12: =10+36 -> 46 | AH12: =(1+1+1+1+4+2+1+2+1+4+2+1+1) -> 22 | AI12: =(2+1+1+2+2+2+2+1+3)+(1+2+2+3+2+1+1+2+1+1+1) -> 33 | BA12: #N/A | BB12: #N/A | BC12: #N/A | BD12: #N/A | BE12: #N/A | BF12: #N/A | BG12: #N/A | BH12: #N/A | BI12: #N/A | BJ12: =AVERAGE(B12:K12) -> 48.571429 | BK12: =AVERAGE(C12:L12) -> 45.375 | BL12: =AVERAGE(D12:M12) -> 44.111111 | BM12: =AVERAGE(E12:N12) -> 43 | BN12: =AVERAGE(F12:O12) -> 39.6 | BO12: =AVERAGE(G12:P12) -> 33.4 | BP12: =AVERAGE(H12:Q12) -> 28.7 | BQ12: =AVERAGE(I12:R12) -> 25.8 | ... DD12: =AVERAGE(AV12:BE12) -> #N/A
A13: September | E13: 75 | F13: 88 | G13: 18 | H13: 7 | I13: 34 | J13: 17 | K13: 22 | L13: 28 | M13: 18 | N13: 11 | O13: 13 | P13: 14 | Q13: 12 | R13: 20 | U13: 9 | W13: 38 | X13: 13 | Y13: 24 | Z13: 16 | AA13: 28 | AB13: 21 | AC13: 29 | AD13: 25 | AE13: =AVERAGE(AB13:AD13) -> 25 | AF13: 40 | AG13: =7+12 -> 19 | AH13: =(8+2+2+1+3+2+2+2) -> 22 | AI13: =(1)+(1+2+2+3+1)+(2+2) -> 14 | BA13: #N/A | BB13: #N/A | BC13: #N/A | BD13: #N/A | BE13: #N/A | BF13: #N/A | BG13: #N/A | BH13: #N/A | BI13: #N/A | BJ13: =AVERAGE(B13:K13) -> 37.285714 | BK13: =AVERAGE(C13:L13) -> 36.125 | BL13: =AVERAGE(D13:M13) -> 34.111111 | BM13: =AVERAGE(E13:N13) -> 31.8 | BN13: =AVERAGE(F13:O13) -> 25.6 | BO13: =AVERAGE(G13:P13) -> 18.2 | BP13: =AVERAGE(H13:Q13) -> 17.6 | BQ13: =AVERAGE(I13:R13) -> 18.9 | ... DD13: =AVERAGE(AV13:BE13) -> #N/A
A14: October | E14: 50 | F14: 64 | G14: 18 | H14: 27 | I14: 11 | J14: 12 | K14: 44 | L14: 18 | M14: 39 | N14: 30 | O14: 53 | P14: 45 | Q14: 26 | R14: 11 | U14: 32 | W14: 30 | X14: 14 | Y14: 10 | Z14: 17 | AA14: 32 | AB14: 18 | AC14: 18 | AD14: 50 | AE14: =AVERAGE(AB14:AD14) -> 28.666667 | AF14: 39 | AG14: =20+20 -> 40 | AH14: =1+2+2+1+1+3 -> 10 | BA14: #N/A | BB14: #N/A | BC14: #N/A | BD14: #N/A | BE14: #N/A | BF14: #N/A | BG14: #N/A | BH14: #N/A | BI14: #N/A | BJ14: =AVERAGE(B14:K14) -> 32.285714 | BK14: =AVERAGE(C14:L14) -> 30.5 | BL14: =AVERAGE(D14:M14) -> 31.444444 | BM14: =AVERAGE(E14:N14) -> 31.3 | BN14: =AVERAGE(F14:O14) -> 31.6 | BO14: =AVERAGE(G14:P14) -> 29.7 | BP14: =AVERAGE(H14:Q14) -> 30.5 | BQ14: =AVERAGE(I14:R14) -> 28.9 | ... DD14: =AVERAGE(AV14:BE14) -> #N/A
A15: November | E15: 26 | F15: 18 | G15: 26 | H15: 24 | I15: 16 | J15: 9 | K15: 23 | L15: 23 | M15: 36 | N15: 3 | O15: 15 | P15: 16 | Q15: 9 | R15: 26 | U15: 6 | W15: 17 | X15: 6 | Y15: 19 | Z15: 28 | AA15: 13 | AB15: 13 | AC15: 22 | AD15: 26 | AE15: =AVERAGE(AB15:AD15) -> 20.333333 | AF15: 37 | AG15: =30+7 -> 37 | AH15: =(2+1+4+3)+(2+2+3+3+3+2) -> 25 | BA15: #N/A | BB15: #N/A | BC15: #N/A | BD15: #N/A | BE15: #N/A | BF15: #N/A | BG15: #N/A | BH15: #N/A | BI15: #N/A | BJ15: =AVERAGE(B15:K15) -> 20.285714 | BK15: =AVERAGE(C15:L15) -> 20.625 | BL15: =AVERAGE(D15:M15) -> 22.333333 | BM15: =AVERAGE(E15:N15) -> 20.4 | BN15: =AVERAGE(F15:O15) -> 19.3 | BO15: =AVERAGE(G15:P15) -> 19.1 | BP15: =AVERAGE(H15:Q15) -> 17.4 | BQ15: =AVERAGE(I15:R15) -> 17.6 | ... DD15: =AVERAGE(AV15:BE15) -> #N/A
A16: December | E16: 14 | F16: 5 | G16: 0 | H16: 3 | I16: 3 | J16: 8 | K16: 6 | L16: 5 | M16: 6 | N16: 0 | O16: 18 | P16: 6 | Q16: 13 | R16: 3 | U16: 1 | W16: 7 | X16: 11 | Y16: 21 | Z16: 5 | AA16: 1 | AB16: 15 | AC16: 26 | AD16: 11 | AE16: =AVERAGE(AB16:AD16) -> 17.333333 | AF16: 22 | AG16: 0 | AH16: =1+4+1+1+3+2 -> 12 | BA16: #N/A | BB16: #N/A | BC16: #N/A | BD16: #N/A | BE16: #N/A | BF16: #N/A | BG16: #N/A | BH16: #N/A | BI16: #N/A | BJ16: =AVERAGE(B16:K16) -> 5.5714286 | BK16: =AVERAGE(C16:L16) -> 5.5 | BL16: =AVERAGE(D16:M16) -> 5.5555556 | BM16: =AVERAGE(E16:N16) -> 5 | BN16: =AVERAGE(F16:O16) -> 5.4 | BO16: =AVERAGE(G16:P16) -> 5.5 | BP16: =AVERAGE(H16:Q16) -> 6.8 | BQ16: =AVERAGE(I16:R16) -> 6.8 | ... DD16: =AVERAGE(AV16:BE16) -> #N/A
A18: Yearly Totals | B18: =SUM(B5:B16) -> 0 | C18: =SUM(C5:C16) -> 0 | D18: =SUM(D5:D16) -> 0 | E18: =SUM(E5:E16) -> 349 | F18: =SUM(F5:F16) -> 457 | G18: =SUM(G5:G16) -> 313 | H18: =SUM(H5:H16) -> 270 | I18: =SUM(I5:I16) -> 271 | ... AZ18: =SUM(AZ5:AZ16) -> 0 | BX18: =AVERAGE(P18:Y18) -> 139.2 | BY18: =AVERAGE(Q18:Z18) -> 127.5 | BZ18: =AVERAGE(R18:AA18) -> 137.3 | CA18: =AVERAGE(S18:AB18) -> 143 | CB18: =AVERAGE(T18:AC18) -> 175 | CC18: =AVERAGE(U18:AD18) -> 211.2

Sheet Kelly Hollow
A1: Balsam Lake Mountain Wild Forest
A2: KELLY HOLLOW
B3: 1991 | C3: 1992 | D3: 1993 | E3: 1994 | F3: 1995 | G3: 1996 | H3: 1997 | I3: 1998 | J3: 1999 | K3: 2000 | L3: 2001 | M3: 2002 | N3: 2003 | O3: 2004 | P3: 2005 | Q3: 2006 | R3: 2007 | S3: 2008 | T3: 2009 | U3: 2010 | V3: 2011 | W3: 2012 | X3: 2013 | Y3: 2014 | Z3: 2015 | AA3: 2016 | AB3: 2017 | AC3: 2018 | AD3: 2019 | AE3: 2020 | AF3: 2021 | AG3: 2022 | AH3: 2023 | AI3: 2024 | AJ3: 2025 | AK3: 2026 | AL3: 2027 | AM3: 2028 | AN3: 2029 | AO3: 2030 | AP3: 2031 | AQ3: 2032 | AR3: 2033 | AS3: 2034 | AT3: 2035 | AU3: 2036 | AV3: 2037 | AW3: 2038 | AX3: 2039 | AY3: 2040 | AZ3: 2041 | BA3: 10 Year Rolling Averages | BJ3: 2000 | BK3: 2001 | BL3: 2002 | BM3: 2003 | BN3: 2004 | BO3: 2005 | BP3: 2006 | BQ3: 2007 | BR3: 2008 | BS3: 2009 | BT3: 2010 | BU3: 2011 | BV3: 2012 | BW3: 2013 | BX3: 2014 | BY3: 2015 | BZ3: 10-YEAR-AVG-2016 | CA3: 10-YEAR-AVG-2017 | CB3: 10-YEAR-AVG-2018 | CC3: 10-YEAR-AVG-2019 | CD3: 10-YEAR-AVG-2020 | CE3: 2021 | CF3: 2022 | CG3: 2023 | CH3: 2024 | CI3: 2025 | CJ3: 2026 | CK3: 2027 | CL3: 2028 | CM3: 2029 | CN3: 2030 | CO3: 2031 | CP3: 2032 | CQ3: 2033 | CR3: 2034 | CS3: 2035 | CT3: 2036 | CU3: 2037 | CV3: 2038 | CW3: 2039 | CX3: 2040 | CY3: 2041 | CZ3: 2042 | DA3: 2043 | DB3: 2044 | DC3: 2045 | DD3: 2046
A5: January | B5: 10 | C5: 21 | D5: 14 | E5: 2 | F5: 7 | G5: 0 | H5: 20 | I5: 26 | J5: 20 | K5: 20 | L5: 46 | M5: 25 | N5: 31 | O5: 18 | P5: 10 | Q5: 10 | R5: 16 | U5: 22 | W5: 41 | X5: 23 | Y5: 20 | Z5: 19 | AA5: 65 | AB5: 52 | AC5: 39 | AD5: 51 | AE5: 40 | AF5: 108 | AG5: =49+23 -> 72 | AH5: =54+31 -> 85 | AI5: =10+2+32 -> 44 | BB5: #N/A | BC5: #N/A | BD5: #N/A | BE5: #N/A | BF5: #N/A | BG5: #N/A | BH5: #N/A | BI5: #N/A | BJ5: =AVERAGE(B5:K5) -> 14 | BK5: =AVERAGE(C5:L5) -> 17.6 | BL5: =AVERAGE(D5:M5) -> 18 | BM5: =AVERAGE(E5:N5) -> 19.7 | BN5: =AVERAGE(F5:O5) -> 21.3 | BO5: =AVERAGE(G5:P5) -> 21.6 | BP5: =AVERAGE(H5:Q5) -> 22.6 | BQ5: =AVERAGE(I5:R5) -> 22.2 | ... DD5: =AVERAGE(AV5:BE5) -> #N/A
A6: February | B6: 14 | C6: 13 | D6: 6 | E6: 15 | F6: 7 | G6: 19 | H6: 45 | I6: 8 | J6: 26 | K6: 25 | L6: 19 | M6: 38 | N6: 15 | O6: 35 | P6: 49 | Q6: 16 | R6: 11 | U6: 36 | W6: 61 | X6: 27 | Y6: 9 | Z6: 9 | AA6: 33 | AB6: 36 | AC6: 28 | AD6: 45 | AE6: 31 | AF6: 79 | AG6: =35+58+2 -> 95 | AH6: =10+20+39+45 -> 114 | AI6: =47+23 -> 70 | BA6: #N/A | BB6: #N/A | BC6: #N/A | BD6: #N/A | BE6: #N/A | BF6: #N/A | BG6: #N/A | BH6: #N/A | BI6: #N/A | BJ6: =AVERAGE(B6:K6) -> 17.8 | BK6: =AVERAGE(C6:L6) -> 18.3 | BL6: =AVERAGE(D6:M6) -> 20.8 | BM6: =AVERAGE(E6:N6) -> 21.7 | BN6: =AVERAGE(F6:O6) -> 23.7 | BO6: =AVERAGE(G6:P6) -> 27.9 | BP6: =AVERAGE(H6:Q6) -> 27.6 | BQ6: =AVERAGE(I6:R6) -> 24.2 | ... DD6: =AVERAGE(AV6:BE6) -> #N/A
A7: March | B7: 10 | C7: 3 | D7: 11 | E7: 6 | F7: 17 | G7: 6 | H7: 30 | I7: 13 | J7: 10 | K7: 15 | L7: 28 | M7: 32 | N7: 32 | O7: 19 | P7: 21 | Q7: 23 | R7: 36 | U7: 31 | W7: 39 | X7: 44 | Y7: 10 | Z7: 16 | AA7: 61 | AB7: 7 | AC7: 26 | AD7: 34 | AE7: 121 | AF7: 200 | AG7: =43+39+7 -> 89 | AH7: =44+26+4 -> 74 | AI7: =14+21+(1+3+1+2+2+7+2+2+2+5+1+2+1+1+15+4+2+2+2)+(1+3) -> 96 | BA7: #N/A | BB7: #N/A | BC7: #N/A | BD7: #N/A | BE7: #N/A | BF7: #N/A | BG7: #N/A | BH7: #N/A | BI7: #N/A | BJ7: =AVERAGE(B7:K7) -> 12.1 | BK7: =AVERAGE(C7:L7) -> 13.9 | BL7: =AVERAGE(D7:M7) -> 16.8 | BM7: =AVERAGE(E7:N7) -> 18.9 | BN7: =AVERAGE(F7:O7) -> 20.2 | BO7: =AVERAGE(G7:P7) -> 20.6 | BP7: =AVERAGE(H7:Q7) -> 22.3 | BQ7: =AVERAGE(I7:R7) -> 22.9 | ... DD7: =AVERAGE(AV7:BE7) -> #N/A
A8: April | B8: 7 | C8: 13 | D8: 4 | E8: 19 | F8: 19 | G8: 10 | H8: 40 | I8: 6 | J8: 26 | K8: 35 | L8: 41 | M8: 34 | N8: 40 | O8: 35 | P8: 32 | Q8: 72 | R8: 44 | U8: 66 | W8: 73 | X8: 41 | Y8: 49 | Z8: 58 | AA8: 73 | AB8: 66 | AC8: 43 | AD8: 116 | AE8: 97 | AF8: 229 | AG8: =48+98+60+27 -> 233 | AH8: =16+44+68+11 -> 139 | AI8: =(1+1+1+1+1+3+2+2+1+4+2+2+1+3+1+2)+(1+2+3+1+4+3+2+3+4+2+5+1+4+3+2+1+3+2+5+2)+(1+6+2+2+2+2+2+3+5+4+2+2+1+4+1+2+4+1) -> 127 | BA8: #N/A | BB8: #N/A | BC8: #N/A | BD8: #N/A | BE8: #N/A | BF8: #N/A | BG8: #N/A | BH8: #N/A | BI8: #N/A | BJ8: =AVERAGE(B8:K8) -> 17.9 | BK8: =AVERAGE(C8:L8) -> 21.3 | BL8: =AVERAGE(D8:M8) -> 23.4 | BM8: =AVERAGE(E8:N8) -> 27 | BN8: =AVERAGE(F8:O8) -> 28.6 | BO8: =AVERAGE(G8:P8) -> 29.9 | BP8: =AVERAGE(H8:Q8) -> 36.1 | BQ8: =AVERAGE(I8:R8) -> 36.5 | ... DD8: =AVERAGE(AV8:BE8) -> #N/A
A9: May | B9: 29 | C9: 37 | D9: 34 | E9: 48 | F9: 25 | G9: 19 | H9: 62 | I9: 75 | J9: 12 | K9: 59 | L9: 44 | M9: 71 | N9: 79 | O9: 56 | P9: 51 | Q9: 66 | R9: 92 | U9: 61 | W9: 160 | X9: 122 | Y9: 90 | Z9: 111 | AA9: 86 | AB9: 44 | AC9: 113 | AD9: 136 | AE9: 186 | AF9: 252 | AG9: =15+62+43+35+63+43 -> 261 | AH9: =27+31+41+47+12 -> 158 | AI9: =(2+1)+(4+1+7+6+1+1+2+2+4+2+2+2+2+1+1+6+2+1+1+1)+(2+2+2+2+3+1+1+2+5+2+2+3+2+4+2+2+1+5+4+3)+(2+5+2+2+3+2+2+3+2+2+4+2+5+6+1+4+1+2+4)+(2+2+4+1)+(2+3+1+7+4) -> 182 | BA9: #N/A | BB9: #N/A | BC9: #N/A | BD9: #N/A | BE9: #N/A | BF9: #N/A | BG9: #N/A | BH9: #N/A | BI9: #N/A | BJ9: =AVERAGE(B9:K9) -> 40 | BK9: =AVERAGE(C9:L9) -> 41.5 | BL9: =AVERAGE(D9:M9) -> 44.9 | BM9: =AVERAGE(E9:N9) -> 49.4 | BN9: =AVERAGE(F9:O9) -> 50.2 | BO9: =AVERAGE(G9:P9) -> 52.8 | BP9: =AVERAGE(H9:Q9) -> 57.5 | BQ9: =AVERAGE(I9:R9) -> 60.5 | ... DD9: =AVERAGE(AV9:BE9) -> #N/A
A10: June | B10: 23 | C10: 16 | D10: 10 | E10: 22 | F10: 42 | G10: 41 | H10: 25 | I10: 18 | J10: 4 | K10: 21 | L10: 39 | M10: 42 | N10: 39 | O10: 52 | P10: 60 | Q10: 31 | R10: 82 | U10: 71 | W10: 107 | X10: 77 | Y10: 82 | Z10: 66 | AA10: 101 | AB10: 79 | AC10: 128 | AD10: 118 | AE10: 243 | AF10: 277 | AG10: =13+43+42+40+46+40 -> 224 | AH10: =35+50+51+15 -> 151 | AI10: =(1+2+5+2+1+2+2+2+2+1+2+2+1+2+1+4)+(4+2+1+1+3+4+2+4+1+1+2+1+1+1+4+3+3+2+1)+(4+2+4+1+2+2+3+4+1+2+2+1+1+1+2+2)+(2+1+2+2+7+2+2+1+1+2+3+2+1+2+2+2+2+2+4+5)+(2) -> 156 | BA10: #N/A | BB10: #N/A | BC10: #N/A | BD10: #N/A | BE10: #N/A | BF10: #N/A | BG10: #N/A | BH10: #N/A | BI10: #N/A | BJ10: =AVERAGE(B10:K10) -> 22.2 | BK10: =AVERAGE(C10:L10) -> 23.8 | BL10: =AVERAGE(D10:M10) -> 26.4 | BM10: =AVERAGE(E10:N10) -> 29.3 | BN10: =AVERAGE(F10:O10) -> 32.3 | BO10: =AVERAGE(G10:P10) -> 34.1 | BP10: =AVERAGE(H10:Q10) -> 33.1 | BQ10: =AVERAGE(I10:R10) -> 38.8 | ... DD10: =AVERAGE(AV10:BE10) -> #N/A
A11: July | B11: 14 | C11: 20 | D11: 37 | E11: 30 | F11: 57 | G11: 21 | H11: 55 | I11: 44 | J11: 39 | K11: 70 | L11: 40 | M11: 68 | N11: 45 | O11: 70 | P11: 109 | Q11: 73 | R11: 98 | U11: 143 | W11: 84 | X11: 96 | Y11: 130 | Z11: 84 | AA11: 146 | AB11: 132 | AC11: 131 | AD11: 203 | AE11: 249 | AF11: 273 | AG11: =11+46+57+43+57+56+22+31+52 -> 375 | AH11: =47+45+48+53+65+21 -> 279 | AI11: =(2+1+2+17+1+3+2+3+2+2+4+3+2+1+4+1+1)+(5+4+1+4+4+2+2+1+2+2+1+2+3+1+2+2+2+1+1+2)+(4+1+1+2+6+3+5)+(2+2+3+1+1+1+2+9+5+4+3+2+2+2+4+2+2+2+2+1)+(2+4+6+3+2+2+3+3+2+4+3+2+2+1+2+2)+(2+1) -> 215 | BA11: #N/A | BB11: #N/A | BC11: #N/A | BD11: #N/A | BE11: #N/A | BF11: #N/A | BG11: #N/A | BH11: #N/A | BI11: #N/A | BJ11: =AVERAGE(B11:K11) -> 38.7 | BK11: =AVERAGE(C11:L11) -> 41.3 | BL11: =AVERAGE(D11:M11) -> 46.1 | BM11: =AVERAGE(E11:N11) -> 46.9 | BN11: =AVERAGE(F11:O11) -> 50.9 | BO11: =AVERAGE(G11:P11) -> 56.1 | BP11: =AVERAGE(H11:Q11) -> 61.3 | BQ11: =AVERAGE(I11:R11) -> 65.6 | ... DD11: =AVERAGE(AV11:BE11) -> #N/A
A12: August | B12: 38 | C12: 28 | D12: 26 | E12: 42 | F12: 33 | G12: 54 | H12: 53 | I12: 39 | J12: 63 | K12: 43 | L12: 63 | M12: 73 | N12: 81 | O12: 63 | P12: 78 | Q12: 84 | R12: 87 | U12: 122 | W12: 143 | X12: 131 | Y12: 120 | Z12: 150 | AA12: 110 | AB12: 144 | AC12: 142 | AD12: 166 | AE12: 323 | AF12: 279 | AG12: =29+14+50+31+26+52+59+40+41 -> 342 | AH12: =18+52+48+55+49+53+14 -> 289 | AI12: =(4+2+2+2+2+1+1+4+2+5+2+5+2+7+2+5+8+2)+(4+3+2+1+2+3+1+3+4+3+1+2+2+6+4+2+2+4)+(2+3+3+2+3+6+1+3+2+2+2+1+1+3+2+3+2+1+3)+(2+3+1+6+2+2+3+2+1+4+4+4+2+4+2+2+1+2+1)+(8+2)+(2+1+8+2+4+2+2+2+2+2+2+2+4+3) -> 248 | BA12: #N/A | BB12: #N/A | BC12: #N/A | BD12: #N/A | BE12: #N/A | BF12: #N/A | BG12: #N/A | BH12: #N/A | BI12: #N/A | BJ12: =AVERAGE(B12:K12) -> 41.9 | BK12: =AVERAGE(C12:L12) -> 44.4 | BL12: =AVERAGE(D12:M12) -> 48.9 | BM12: =AVERAGE(E12:N12) -> 54.4 | BN12: =AVERAGE(F12:O12) -> 56.5 | BO12: =AVERAGE(G12:P12) -> 61 | BP12: =AVERAGE(H12:Q12) -> 64 | BQ12: =AVERAGE(I12:R12) -> 67.4 | ... DD12: =AVERAGE(AV12:BE12) -> #N/A
A13: September | B13: 34 | C13: 47 | D13: 19 | E13: 27 | F13: 36 | G13: 48 | H13: 40 | I13: 41 | J13: 44 | K13: 48 | L13: 78 | M13: 52 | N13: 28 | O13: 72 | P13: 68 | Q13: 32 | R13: 65 | U13: 74 | W13: 65 | X13: 48 | Y13: 71 | Z13: 111 | AA13: 114 | AB13: 131 | AC13: 115 | AD13: 119 | AE13: 211 | AF13: 202 | AG13: =66+42+27+56 -> 191 | AH13: =57+37+29+17+11+18 -> 169 | AI13: =(3+3+2)+(4+3+2+2+2+1+5+4+2+3+2+1+1+2+2+2+3+2+1+2)+(3+3+2+3+1+2+1+2+1+2+2+2+1+2+2+2+2+1+2)+(2+3+4+2+1+2+2+2+1+2+2+1+2+4+2+2+1) -> 125 | BA13: #N/A | BB13: #N/A | BC13: #N/A | BD13: #N/A | BE13: #N/A | BF13: #N/A | BG13: #N/A | BH13: #N/A | BI13: #N/A | BJ13: =AVERAGE(B13:K13) -> 38.4 | BK13: =AVERAGE(C13:L13) -> 42.8 | BL13: =AVERAGE(D13:M13) -> 43.3 | BM13: =AVERAGE(E13:N13) -> 44.2 | BN13: =AVERAGE(F13:O13) -> 48.7 | BO13: =AVERAGE(G13:P13) -> 51.9 | BP13: =AVERAGE(H13:Q13) -> 50.3 | BQ13: =AVERAGE(I13:R13) -> 52.8 | ... DD13: =AVERAGE(AV13:BE13) -> #N/A
A14: October | B14: 24 | C14: 36 | D14: 40 | E14: 50 | F14: 40 | G14: 35 | H14: 26 | I14: 48 | J14: 56 | K14: 58 | L14: 23 | M14: 61 | N14: 52 | O14: 32 | P14: 57 | Q14: 76 | R14: 80 | U14: 107 | W14: 68 | X14: 91 | Y14: 58 | Z14: 70 | AA14: 95 | AB14: 116 | AC14: 102 | AD14: 121 | AE14: 243 | AF14: 219 | AG14: =44+54+48+50+60+48+33 -> 337 | AH14: =8+31+36+48+31+11 -> 165 | BA14: #N/A | BB14: #N/A | BC14: #N/A | BD14: #N/A | BE14: #N/A | BF14: #N/A | BG14: #N/A | BH14: #N/A | BI14: #N/A | BJ14: =AVERAGE(B14:K14) -> 41.3 | BK14: =AVERAGE(C14:L14) -> 41.2 | BL14: =AVERAGE(D14:M14) -> 43.7 | BM14: =AVERAGE(E14:N14) -> 44.9 | BN14: =AVERAGE(F14:O14) -> 43.1 | BO14: =AVERAGE(G14:P14) -> 44.8 | BP14: =AVERAGE(H14:Q14) -> 48.9 | BQ14: =AVERAGE(I14:R14) -> 54.3 | ... DD14: =AVERAGE(AV14:BE14) -> #N/A
A15: November | B15: 29 | C15: 35 | D15: 16 | E15: 58 | F15: 34 | G15: 22 | H15: 29 | I15: 37 | J15: 46 | K15: 17 | L15: 47 | M15: 28 | N15: 39 | O15: 36 | P15: 47 | Q15: 40 | R15: 45 | U15: 146 | W15: 41 | X15: 23 | Y15: 47 | Z15: 40 | AA15: 53 | AB15: 51 | AC15: 44 | AD15: 89 | AE15: 229 | AF15: 132 | AG15: =18+67+46+49 -> 180 | AH15: =3+63+35+53 -> 154 | BA15: #N/A | BB15: #N/A | BC15: #N/A | BD15: #N/A | BE15: #N/A | BF15: #N/A | BG15: #N/A | BH15: #N/A | BI15: #N/A | BJ15: =AVERAGE(B15:K15) -> 32.3 | BK15: =AVERAGE(C15:L15) -> 34.1 | BL15: =AVERAGE(D15:M15) -> 33.4 | BM15: =AVERAGE(E15:N15) -> 35.7 | BN15: =AVERAGE(F15:O15) -> 33.5 | BO15: =AVERAGE(G15:P15) -> 34.8 | BP15: =AVERAGE(H15:Q15) -> 36.6 | BQ15: =AVERAGE(I15:R15) -> 38.2 | ... DD15: =AVERAGE(AV15:BE15) -> #N/A
A16: December | B16: 10 | C16: 6 | D16: 6 | E16: 8 | F16: 28 | G16: 15 | H16: 3 | I16: 38 | J16: 33 | K16: 12 | L16: 0 | M16: 20 | N16: 30 | O16: 37 | P16: 13 | Q16: 75 | R16: 31 | U16: 37 | W16: 19 | X16: 10 | Y16: 28 | Z16: 26 | AA16: 15 | AB16: 43 | AC16: 63 | AD16: 31 | AE16: 41 | AF16: 130 | AG16: =5+40+45 -> 90 | AH16: =52+56+4 -> 112 | BA16: #N/A | BB16: #N/A | BC16: #N/A | BD16: #N/A | BE16: #N/A | BF16: #N/A | BG16: #N/A | BH16: #N/A | BI16: #N/A | BJ16: =AVERAGE(B16:K16) -> 15.9 | BK16: =AVERAGE(C16:L16) -> 14.9 | BL16: =AVERAGE(D16:M16) -> 16.3 | BM16: =AVERAGE(E16:N16) -> 18.7 | BN16: =AVERAGE(F16:O16) -> 21.6 | BO16: =AVERAGE(G16:P16) -> 20.1 | BP16: =AVERAGE(H16:Q16) -> 26.1 | BQ16: =AVERAGE(I16:R16) -> 28.9 | ... DD16: =AVERAGE(AV16:BE16) -> #N/A
A18: Yearly Totals | B18: =SUM(B5:B16) -> 242 | C18: =SUM(C5:C16) -> 275 | D18: =SUM(D5:D16) -> 223 | E18: =SUM(E5:E16) -> 327 | F18: =SUM(F5:F16) -> 345 | G18: =SUM(G5:G16) -> 290 | H18: =SUM(H5:H16) -> 428 | I18: =SUM(I5:I16) -> 393 | ... AZ18: =SUM(AZ5:AZ16) -> 0 | BX18: =AVERAGE(AK18:AT18) -> 0 | BY18: =AVERAGE(AL18:AU18) -> 0 | BZ18: =AVERAGE(AM18:AV18) -> 0 | CA18: =AVERAGE(AN18:AW18) -> 0 | CB18: =AVERAGE(AO18:AY18) -> 0 | CC18: =AVERAGE(AP18:AZ18) -> 0

Sheet Millbrook to BLM FT
A1: Balsam Lake Mountain Wild Forest
A2: MILLBROOK (Dry Brook Parking Area To Fire Tower - Millbrook Road)
B3: 1991 | C3: 1992 | D3: 1993 | E3: 1994 | F3: 1995 | G3: 1996 | H3: 1997 | I3: 1998 | J3: 1999 | K3: 2000 | L3: 2001 | M3: 2002 | N3: 2003 | O3: 2004 | P3: 2005 | Q3: 2006 | R3: 2007 | S3: 2008 | T3: 2009 | U3: 2010 | V3: 2011 | W3: 2012 | X3: 2013 | Y3: 2014 | Z3: 2015 | AA3: 2016 | AB3: 2017 | AC3: 2018 | AD3: 2019 | AE3: 2020 | AF3: 2021 | AG3: 2022 | AH3: 2023 | AI3: 2024 | AJ3: 2025 | AK3: 2026 | AL3: 2027 | AM3: 2028 | AN3: 2029 | AO3: 2030 | AP3: 2031 | AQ3: 2032 | AR3: 2033 | AS3: 2034 | AT3: 2035 | AU3: 2036 | AV3: 2037 | AW3: 2038 | AX3: 2039 | AY3: 2040 | AZ3: 2041 | BA3: 10 Year Rolling Averages | BK3: 2001 | BL3: 2002 | BM3: 2003 | BN3: 2004 | BO3: 2005 | BP3: 2006 | BQ3: 2007 | BR3: 2008 | BS3: 2009 | BT3: 2010 | BU3: 2011 | BV3: 2012 | BW3: 2013 | BX3: 2014 | BY3: 2015 | BZ3: 10-YEAR-AVG-2016 | CA3: 10-YEAR-AVG-2017 | CB3: 10-YEAR-AVG-2018 | CC3: 10-YEAR-AVG 2019 | CD3: 10-YEAR-AVG-2020 | CE3: 2021 | CF3: 2022 | CG3: 2023 | CH3: 2024 | CI3: 2025 | CJ3: 2026 | CK3: 2027 | CL3: 2028 | CM3: 2029 | CN3: 2030 | CO3: 2031 | CP3: 2032 | CQ3: 2033 | CR3: 2034 | CS3: 2035 | CT3: 2036 | CU3: 2037 | CV3: 2038 | CW3: 2039 | CX3: 2040 | CY3: 2041 | CZ3: 2042 | DA3: 2043 | DB3: 2044 | DC3: 2045 | DD3: 2046
A5: January | B5: 29 | C5: 25 | D5: 29 | E5: 40 | F5: 96 | G5: 34 | H5: 25 | I5: 77 | J5: 50 | K5: 67 | L5: 72 | M5: 75 | N5: 24 | O5: 68 | P5: 38 | Q5: 45 | R5: 66 | U5: 22 | W5: 54 | X5: 58 | Y5: 71 | Z5: 108 | AA5: 197 | AB5: 168 | AC5: 116 | AD5: 101 | AE5: 166 | AF5: 185 | AG5: =35+32+15+42+8 -> 132 | AH5: =29+45+40+32+52+23 -> 221 | AI5: =SUM(5+6+6+2+3+3+1+2+2+3+5+1+4+1+2+2+2+1+1+1+1+1+3+1+22+1+2+7+2+2+1+1+3+1+1+3+1+1+1+1+2+1+2+2+1+4+1) -> 122 | AJ5: =SUM(2+2+5+1+1+2+2+1+2+1+1+3+1+1+1+3+5+2+1+3+1+2+2+2+1+2+1+2+2+1+2+6+2+1+2+2+2+1+2+3+2+1+5+1+2+2+2+2+3+2+2+1+5+1+5+5+2+5+2+2+1+1+1+2+1+2+3+1) -> 143 | BB5: #N/A | BC5: #N/A | BD5: #N/A | BE5: #N/A | BF5: #N/A | BG5: #N/A | BH5: #N/A | BI5: #N/A | BJ5: =AVERAGE(B5:K5) -> 47.2 | BK5: =AVERAGE(C5:L5) -> 51.5 | BL5: =AVERAGE(D5:M5) -> 56.5 | BM5: =AVERAGE(E5:N5) -> 56 | BN5: =AVERAGE(F5:O5) -> 58.8 | BO5: =AVERAGE(G5:P5) -> 53 | BP5: =AVERAGE(H5:Q5) -> 54.1 | BQ5: =AVERAGE(I5:R5) -> 58.2 | ... DD5: =AVERAGE(AV5:BE5) -> #N/A
A6: February | B6: 66 | C6: 23 | D6: 28 | E6: 25 | F6: 50 | G6: 19 | H6: 35 | I6: 83 | J6: 75 | K6: 48 | L6: 75 | M6: 81 | N6: 22 | O6: 60 | P6: 89 | Q6: 61 | R6: 59 | U6: 36 | W6: 63 | X6: 103 | Y6: 119 | Z6: 99 | AA6: 141 | AB6: 169 | AC6: 141 | AD6: 177 | AE6: 160 | AF6: 106 | AG6: =2+41+39+2+33+35+34+6+13 -> 205 | AH6: =18+41+59+48+1 -> 167 | AI6: =SUM(1+1+1+2+1+1+1+2+2+2+1+2+5+1+2+1+2+1+1+1+2+4+2+4+2+2+1+1+1+1+2+1+1+1+2+1+3+2+2+4+4+2+2+1+1+2+1+2+2+2+2+2+8+5+1+1+8+2+2+1+1+1+2+1+1+1+1+4+5+7+4+1+3+1+2+1+2+1+1+1+1+1+1+2+1+1+1+1+1+2+2+2) -> 178 | AJ6: =SUM(1+2+1+2+3+5+1+1+2+2+2+2+2+2+2+1+2+1+3+3+34+2+2+2+2+1+1+12+2+2+2+2+2+1+1+2+2+1+1+2+1+2+2+2+7+2+2+1+2+2) -> 139 | BA6: #N/A | BB6: #N/A | BC6: #N/A | BD6: #N/A | BE6: #N/A | BF6: #N/A | BG6: #N/A | BH6: #N/A | BI6: #N/A | BJ6: =AVERAGE(B6:K6) -> 45.2 | BK6: =AVERAGE(C6:L6) -> 46.1 | BL6: =AVERAGE(D6:M6) -> 51.9 | BM6: =AVERAGE(E6:N6) -> 51.3 | BN6: =AVERAGE(F6:O6) -> 54.8 | BO6: =AVERAGE(G6:P6) -> 58.7 | BP6: =AVERAGE(H6:Q6) -> 62.9 | BQ6: =AVERAGE(I6:R6) -> 65.3 | ... DD6: =AVERAGE(AV6:BE6) -> #N/A
A7: March | B7: 14 | C7: 35 | D7: 12 | E7: 42 | F7: 51 | G7: 55 | H7: 30 | I7: 28 | J7: 59 | K7: 40 | L7: 56 | M7: 54 | N7: 26 | O7: 39 | P7: 54 | Q7: 57 | R7: 65 | U7: 31 | W7: 45 | X7: 112 | Y7: 69 | Z7: 90 | AA7: 192 | AB7: 96 | AC7: 86 | AD7: 69 | AE7: 182 | AF7: 174 | AG7: =25+18+31+36+19 -> 129 | AH7: =30+43+34+32 -> 139 | AI7: =SUM(2+1+1+1+1+1+2+2+2+1+2+2+4+2+1+2+1+3+1+1+12+1+2+1+2+2+1+1+1+1+1+2+1+1+2+5+2+3+1+2+3+2+3+1+1+2+2+2+1+1+6+7+2+2+1+2+1+1+1+1+7+2+2+1+20+3+1+3+2+1+2+2+1+1+1+1+2+3+2+3+9+1+1+1+5+2+2+3+2+2+1+3+2+2) -> 215 | AJ7: =SUM(1+9+4+2+4+1+2+1+1+1+2+2+1+3+1+1+1+4+1+1+1+5+2+1+4+1+1+1+2+1+1+2+2+1+1+1+2+3+2+2+2+2+2+1+2+1+2+2+2+3+2+1+1+4+7+2+1+1+1+2+1+2+2+1+2+3) -> 131 | BA7: #N/A | BB7: #N/A | BC7: #N/A | BD7: #N/A | BE7: #N/A | BF7: #N/A | BG7: #N/A | BH7: #N/A | BI7: #N/A | BJ7: =AVERAGE(B7:K7) -> 36.6 | BK7: =AVERAGE(C7:L7) -> 40.8 | BL7: =AVERAGE(D7:M7) -> 42.7 | BM7: =AVERAGE(E7:N7) -> 44.1 | BN7: =AVERAGE(F7:O7) -> 43.8 | BO7: =AVERAGE(G7:P7) -> 44.1 | BP7: =AVERAGE(H7:Q7) -> 44.3 | BQ7: =AVERAGE(I7:R7) -> 47.8 | ... DD7: =AVERAGE(AV7:BE7) -> #N/A
A8: April | B8: 15 | C8: 56 | D8: 20 | E8: 36 | F8: 85 | G8: 85 | H8: 28 | I8: 80 | J8: 110 | K8: 55 | L8: 34 | M8: 60 | N8: 46 | O8: 121 | P8: 64 | Q8: 106 | R8: 65 | U8: 66 | W8: 72 | X8: 117 | Y8: 87 | Z8: 105 | AA8: 225 | AB8: 246 | AC8: 138 | AD8: 115 | AE8: 150 | AF8: 200 | AG8: =7+22+46+45+40+37+18 -> 215 | AH8: =16+44+23+41 -> 124 | AI8: =SUM(1+1+1+1+2+1+2+2+2+2+1+2+1+1+2+2+12+1+2+1+2+1+1+1+2+3+3+1+3+4+1+1+1+1+6+2+1+2+1+2+1+1+5+1+2+1+7+1+1+3+1+5+1+2+2+1+1+2+5+2+4+3+2+2+1+2+1+1+2+1) -> 143 | AJ8: =SUM(1+1+1+1+1+1+2+4+1+2+2+2+2+1+1+5+1+1+1+2+1+1+2+1+2+1+1+2+2+1+2+2+1+1+7+2+7+2+1+1+4+1+1+1+3+3+2+1+3+1+3+1+2+2+2+2+1+2+1+6+2+3+1+1+2+2+2+4+2+1+2+2+2+3+2+1+3+1+3+2+2+2+3+2+1+1+2+2+1+1) -> 173 | BA8: #N/A | BB8: #N/A | BC8: #N/A | BD8: #N/A | BE8: #N/A | BF8: #N/A | BG8: #N/A | BH8: #N/A | BI8: #N/A | BJ8: =AVERAGE(B8:K8) -> 57 | BK8: =AVERAGE(C8:L8) -> 58.9 | BL8: =AVERAGE(D8:M8) -> 59.3 | BM8: =AVERAGE(E8:N8) -> 61.9 | BN8: =AVERAGE(F8:O8) -> 70.4 | BO8: =AVERAGE(G8:P8) -> 68.3 | BP8: =AVERAGE(H8:Q8) -> 70.4 | BQ8: =AVERAGE(I8:R8) -> 74.1 | ... DD8: =AVERAGE(AV8:BE8) -> #N/A
A9: May | B9: 168 | C9: 87 | D9: 116 | E9: 115 | F9: 119 | G9: 63 | H9: 109 | I9: 161 | J9: 139 | K9: 115 | L9: 130 | M9: 143 | N9: 54 | O9: 115 | P9: 121 | Q9: 123 | R9: 148 | U9: 61 | W9: 126 | X9: 169 | Y9: 133 | Z9: 227 | AA9: 182 | AB9: 185 | AC9: 210 | AD9: 239 | AE9: 205 | AF9: 227 | AG9: =26+35+61+39+37+35+19 -> 252 | AH9: =10+39+7+43+39+34+49+39+13 -> 273 | AI9: =SUM(2+1+1+3+1+1+2+1+2+1+2+2+1+1+1+2+1+1+2+1+2+1+2+2+4+2+6+1+1+2+2+3+3+1+2+1+4+1+3+1+2+2+2+2+2+2+2+2+2+1+3+1+1+3+6+1+2+1+3+2+1+2+2+1+2+3+2+2+2+1+2+2+2+2+2+2+4+2+1+2+1+3+3+2+1+4+2+2+2+6+1+1+2+4+2+1+2+6+2+2+1+4+3+2+4+5+2+2+6+2+4+3+4+2+3+3+2+2+2+2+3+1+2+2+2+2+5+2+1+2+1+2+2+1) -> 289 | AJ9: =SUM(2+2+3+1+4+1+1+4+10+1+1+1+1+1+3+2+4+3+2+2+1+4+3+6+1+1+1+2+1+2+2+1+2+2+2+1+2+2+2+2+1+3+2+2+4+1+1+2+2+2+1+2+2+4+1+2+1+2+2+2+2+1+3+3+2+2+1+1+20+2+2+1+2+4+3+1+1+2+1+1+2+3+6+3+3+3+2+1+1+1+1+2+9+2+1+4+2+1+2+12+1+2+2+2+2+1+1+1+1+1+1+1+1+2+2+1+2+2+2+2+3) -> 277 | BA9: #N/A | BB9: #N/A | BC9: #N/A | BD9: #N/A | BE9: #N/A | BF9: #N/A | BG9: #N/A | BH9: #N/A | BI9: #N/A | BJ9: =AVERAGE(B9:K9) -> 119.2 | BK9: =AVERAGE(C9:L9) -> 115.4 | BL9: =AVERAGE(D9:M9) -> 121 | BM9: =AVERAGE(E9:N9) -> 114.8 | BN9: =AVERAGE(F9:O9) -> 114.8 | BO9: =AVERAGE(G9:P9) -> 115 | BP9: =AVERAGE(H9:Q9) -> 121 | BQ9: =AVERAGE(I9:R9) -> 124.9 | ... DD9: =AVERAGE(AV9:BE9) -> #N/A
A10: June | B10: 81 | C10: 36 | D10: 62 | E10: 43 | F10: 86 | G10: 106 | H10: 126 | I10: 121 | J10: 135 | K10: 155 | L10: 113 | M10: 177 | N10: 166 | O10: 108 | P10: 106 | Q10: 88 | R10: 153 | U10: 71 | W10: 129 | X10: 120 | Y10: 238 | Z10: 176 | AA10: 226 | AB10: 291 | AC10: 183 | AD10: 285 | AE10: 221 | AF10: 288 | AG10: =56+47+38+55+47+52+20 -> 315 | AH10: =31+36+36+56+36+44+21 -> 260 | AI10: =SUM(2+2+9+4+2+5+2+5+2+2+1+1+1+2+2+1+2+1+2+1+1+7+3+5+3+2+5+2+3+2+2+2+2+2+2+2+4+2+2+1+1+1+1+1+3+2+5+2+2+2+3+1+1+4+2+2+1+2+2+1+5+2+2+19+2+4+2+1+7+2+7+3+2+1+2+3+1+2+1+1+2+2+2+1+2+2+2+3+5+2+1+1+2+2+2+2+2+2+2+2+2+2+1+2+2+2+3+2+2+19+2+1+3+2+2+2+2) -> 303 | AJ10: =SUM(2+2+2+1+3+3+2+1+3+2+2+2+2+1+2+1+3+1+1+2+1+2+2+6+2+2+1+1+4+1+1+1+2+1+2+4+1+2+3+1+1+1+1+1+1+2+1+1+2+1+1+6+2+2+1+2+3+1+3+3+3+1+2+1+3+2+1+2+2+3+1+2+1+2+2+1+1+2+2+2+2+2+2+2+2+1+3+2+2+2+2+1+1+1+2+2+2+1+2+1+1+2+1+2+2+1+8+1+2+2+3+2+7+1+2+2+1+1+2+1+2) -> 231 | BA10: #N/A | BB10: #N/A | BC10: #N/A | BD10: #N/A | BE10: #N/A | BF10: #N/A | BG10: #N/A | BH10: #N/A | BI10: #N/A | BJ10: =AVERAGE(B10:K10) -> 95.1 | BK10: =AVERAGE(C10:L10) -> 98.3 | BL10: =AVERAGE(D10:M10) -> 112.4 | BM10: =AVERAGE(E10:N10) -> 122.8 | BN10: =AVERAGE(F10:O10) -> 129.3 | BO10: =AVERAGE(G10:P10) -> 131.3 | BP10: =AVERAGE(H10:Q10) -> 129.5 | BQ10: =AVERAGE(I10:R10) -> 132.2 | ... DD10: =AVERAGE(AV10:BE10) -> #N/A
A11: July | B11: 91 | C11: 166 | D11: 176 | E11: 231 | F11: 106 | G11: 137 | H11: 178 | I11: 121 | J11: 227 | K11: 295 | L11: 172 | M11: 154 | N11: 165 | O11: 159 | P11: 84 | Q11: 178 | R11: 124 | U11: 143 | W11: 171 | X11: 211 | Y11: 244 | Z11: 256 | AA11: 289 | AB11: 109 | AC11: 224 | AD11: 384 | AE11: 356 | AF11: 291 | AG11: =16+40+39+49+45+38+42+35+59+33+27 -> 423 | AH11: =26+49+48+35+44+43+36+30+62 -> 373 | AI11: =SUM(1+5+6+1+1+2+2+2+1+2+2+1+1+2+2+3+2+2+1+2+2+2+6+2+6+2+2+3+1+2+1+1+2+1+8+1+1+2+1+1+6+2+3+1+1+1+2+2+3+3+2+2+1+2+2+4+4+2+4+3+2+2+2+1+1+2+4+1+2+2+3+2+2+2+1+2+4+2+2+4+2+1+1+1+2+1+1+1+2+14+1+2+3+1+2+2+3+2+2+2+2+1+2+1+2+2+1+2+1+1+1+8+1+5+1+1+2+1+2+2+4+1+2+2+2+4+1+1+2+2+2+2+4+2+2+2+3+2+1+5+3+2+2+2+2+2+3+2+2+8+1+3+1+9+9) -> 363 | AJ11: =SUM(2+2+5+3+2+1+4+3+2+3+3+3+3+2+1+2+3+3+2+2+2+2+4+1+4+2+2+2+6+5+7+3+2+2+1+2+1+1+3+1+3+18+3+1+5+2+1+2+3+2+2+1+1+1+1+1+5+2+1+1+1+2+2+3+3+2+1+5+2+2+2+1+1+2+1+1+2+1+2+7+2+3+2+2+1+1+2+2+2+3+10+1+1+1+1+6+2+4+2+2+1+8+2+2+2+1+2+10+1+2+2+1+1+2+2+4+3+1+1+2+2+7+2+1+2+1+1+2+2+2+2+2+2+2+2+4+1) -> 340 | BA11: #N/A | BB11: #N/A | BC11: #N/A | BD11: #N/A | BE11: #N/A | BF11: #N/A | BG11: #N/A | BH11: #N/A | BI11: #N/A | BJ11: =AVERAGE(B11:K11) -> 172.8 | BK11: =AVERAGE(C11:L11) -> 180.9 | BL11: =AVERAGE(D11:M11) -> 179.7 | BM11: =AVERAGE(E11:N11) -> 178.6 | BN11: =AVERAGE(F11:O11) -> 171.4 | BO11: =AVERAGE(G11:P11) -> 169.2 | BP11: =AVERAGE(H11:Q11) -> 173.3 | BQ11: =AVERAGE(I11:R11) -> 167.9 | ... DD11: =AVERAGE(AV11:BE11) -> #N/A
